5:return {{["x"] = 0, ["y"] = 80, ["param1"] = 15, ["z"] = 0, ["name"] = "unbreakable_map_barrier:barrier"}, {["x"] = 0, ["y"] = 80, ["param1"] = 15, ["z"] = 1, ["name"] = "unbreakable_map_barrier:barrier"}, {["x"] = 0, ["y"] = 80, ["param1"] = 15, ["z"] = 2, ["name"] = "unbreakable_map_barrier:barrier"}, {["x"] = 0, ["y"] = 80, ["param1"] = 15, ["z"] = 3, ["name"] = "unbreakable_map_barrier:barrier"}, {["x"] = 0, ["y"] = 80, ["param1"] = 15, ["z"] = 4, ["name"] = "unbreakable_map_barrier:barrier"}, {["x"] = 0, ["y"] = 80, ["param1"] = 15, ["z"] = 5, ["name"] = "unbreakable_map_barrier:barrier"}, {["x"] = 0, ["y"] = 80, ["param1"] = 15, ["z"] = 6, ["name"] = "unbreakable_map_barrier:barrier"}, {["x"] = 0, ["y"] = 80, ["param1"] = 15, ["z"] = 7, ["name"] = "unbreakable_map_barrier:barrier"}, {["x"] = 0, ["y"] = 80, ["param1"] = 15, ["z"] = 8, ["name"] = "unbreakable_map_barrier:barrier"}, {["x"] = 0, ["y"] = 80, ["param1"] = 15, ["z"] = 9, ["name"] = "unbreakable_map_barrier:barrier"}, {["x"] = 0, ["y"] = 80, ["param1"] = 15, ["z"] = 10, ["name"] = "unbreakable_map_barrier:barrier"}, {["x"] = 0, ["y"] = 80, ["param1"] = 15, ["z"] = 11, ["name"] = "unbreakable_map_barrier:barrier"}, {["x"] = 0, ["y"] = 80, ["param1"] = 15, ["z"] = 12, ["name"] = "unbreakable_map_barrier:barrier"}, {["x"] = 0, ["y"] = 80, ["param1"] = 15, ["z"] = 13, ["name"] = "unbreakable_map_barrier:barrier"}, {["x"] = 0, ["y"] = 80, ["param1"] = 15, ["z"] = 14, ["name"] = "unbreakable_map_barrier:barrier"}, {["x"] = 0, ["y"] = 80, ["param1"] = 15, ["z"] = 15, ["name"] = "unbreakable_map_barrier:barrier"}, {["x"] = 0, ["y"] = 80, ["param1"] = 15, ["z"] = 16, ["name"] = "unbreakable_map_barrier:barrier"}, {["x"] = 0, ["y"] = 80, ["param1"] = 15, ["z"] = 17, ["name"] = "unbreakable_map_barrier:barrier"}, {["x"] = 0, ["y"] = 80, ["param1"] = 15, ["z"] = 18, ["name"] = "unbreakable_map_barrier:barrier"}, {["x"] = 0, ["y"] = 80, ["param1"] = 15, ["z"] = 19, ["name"] = "unbreakable_map_barrier:barrier"}, {["x"] = 0, ["y"] = 80, ["param1"] = 15, ["z"] = 20, ["name"] = "unbreakable_map_barrier:barrier"}, {["x"] = 0, ["y"] = 80, ["param1"] = 15, ["z"] = 21, ["name"] = "unbreakable_map_barrier:barrier"}, {["x"] = 0, ["y"] = 80, ["param1"] = 15, ["z"] = 22, ["name"] = "unbreakable_map_barrier:barrier"}, {["x"] = 0, ["y"] = 80, ["param1"] = 15, ["z"] = 23, ["name"] = "unbreakable_map_barrier:barrier"}, {["x"] = 0, ["y"] = 80, ["param1"] = 15, ["z"] = 24, ["name"] = "unbreakable_map_barrier:barrier"}, {["x"] = 0, ["y"] = 80, ["param1"] = 15, ["z"] = 25, ["name"] = "unbreakable_map_barrier:barrier"}, {["x"] = 0, ["y"] = 80, ["param1"] = 15, ["z"] = 26, ["name"] = "unbreakable_map_barrier:barrier"}, {["x"] = 0, ["y"] = 80, ["param1"] = 15, ["z"] = 27, ["name"] = "unbreakable_map_barrier:barrier"}, {["x"] = 0, ["y"] = 80, ["param1"] = 15, ["z"] = 28, ["name"] = "unbreakable_map_barrier:barrier"}, {["x"] = 0, ["y"] = 80, ["param1"] = 15, ["z"] = 29, ["name"] = "unbreakable_map_barrier:barrier"}, {["x"] = 0, ["y"] = 80, ["param1"] = 15, ["z"] = 30, ["name"] = "unbreakable_map_barrier:barrier"}, {["x"] = 0, ["y"] = 80, ["param1"] = 15, ["z"] = 31, ["name"] = "unbreakable_map_barrier:barrier"}, {["x"] = 0, ["y"] = 80, ["param1"] = 15, ["z"] = 32, ["name"] = "unbreakable_map_barrier:barrier"}, {["x"] = 0, ["y"] = 80, ["param1"] = 15, ["z"] = 33, ["name"] = "unbreakable_map_barrier:barrier"}, {["x"] = 0, ["y"] = 80, ["param1"] = 15, ["z"] = 34, ["name"] = "unbreakable_map_barrier:barrier"}, {["x"] = 0, ["y"] = 80, ["param1"] = 15, ["z"] = 35, ["name"] = "unbreakable_map_barrier:barrier"}, {["x"] = 0, ["y"] = 80, ["param1"] = 15, ["z"] = 36, ["name"] = "unbreakable_map_barrier:barrier"}, {["x"] = 0, ["y"] = 80, ["param1"] = 15, ["z"] = 37, ["name"] = "unbreakable_map_barrier:barrier"}, {["x"] = 0, ["y"] = 80, ["param1"] = 15, ["z"] = 38, ["name"] = "unbreakable_map_barrier:barrier"}, {["x"] = 0, ["y"] = 80, ["param1"] = 15, ["z"] = 39, ["name"] = "unbreakable_map_barrier:barrier"}, {["x"] = 0, ["y"] = 80, ["param1"] = 15, ["z"] = 40, ["name"] = "unbreakable_map_barrier:barrier"}, {["x"] = 0, ["y"] = 80, ["param1"] = 15, ["z"] = 41, ["name"] = "unbreakable_map_barrier:barrier"}, {["x"] = 0, ["y"] = 80, ["param1"] = 15, ["z"] = 42, ["name"] = "unbreakable_map_barrier:barrier"}, {["x"] = 0, ["y"] = 80, ["param1"] = 15, ["z"] = 43, ["name"] = "unbreakable_map_barrier:barrier"}, {["x"] = 0, ["y"] = 80, ["param1"] = 15, ["z"] = 44, ["name"] = "unbreakable_map_barrier:barrier"}, {["x"] = 0, ["y"] = 80, ["param1"] = 15, ["z"] = 45, ["name"] = "unbreakable_map_barrier:barrier"}, {["x"] = 0, ["y"] = 80, ["param1"] = 15, ["z"] = 46, ["name"] = "unbreakable_map_barrier:barrier"}, {["x"] = 0, ["y"] = 80, ["param1"] = 15, ["z"] = 47, ["name"] = "unbreakable_map_barrier:barrier"}, {["x"] = 0, ["y"] = 80, ["param1"] = 15, ["z"] = 48, ["name"] = "unbreakable_map_barrier:barrier"}, {["x"] = 0, ["y"] = 80, ["param1"] = 15, ["z"] = 49, ["name"] = "unbreakable_map_barrier:barrier"}, {["x"] = 0, ["y"] = 80, ["param1"] = 15, ["z"] = 50, ["name"] = "unbreakable_map_barrier:barrier"}, {["x"] = 0, ["y"] = 80, ["param1"] = 15, ["z"] = 51, ["name"] = "unbreakable_map_barrier:barrier"}, {["x"] = 0, ["y"] = 80, ["param1"] = 15, ["z"] = 52, ["name"] = "unbreakable_map_barrier:barrier"}, {["x"] = 0, ["y"] = 80, ["param1"] = 15, ["z"] = 53, ["name"] = "unbreakable_map_barrier:barrier"}, {["x"] = 0, ["y"] = 80, ["param1"] = 15, ["z"] = 54, ["name"] = "unbreakable_map_barrier:barrier"}, {["x"] = 0, ["y"] = 80, ["param1"] = 15, ["z"] = 55, ["name"] = "unbreakable_map_barrier:barrier"}, {["x"] = 0, ["y"] = 80, ["param1"] = 15, ["z"] = 56, ["name"] = "unbreakable_map_barrier:barrier"}, {["x"] = 0, ["y"] = 80, ["param1"] = 15, ["z"] = 57, ["name"] = "unbreakable_map_barrier:barrier"}, {["x"] = 0, ["y"] = 80, ["param1"] = 15, ["z"] = 58, ["name"] = "unbreakable_map_barrier:barrier"}, {["x"] = 0, ["y"] = 80, ["param1"] = 15, ["z"] = 59, ["name"] = "unbreakable_map_barrier:barrier"}, {["x"] = 0, ["y"] = 80, ["param1"] = 15, ["z"] = 60, ["name"] = "unbreakable_map_barrier:barrier"}, {["x"] = 0, ["y"] = 80, ["param1"] = 15, ["z"] = 61, ["name"] = "unbreakable_map_barrier:barrier"}, {["x"] = 0, ["y"] = 80, ["param1"] = 15, ["z"] = 62, ["name"] = "unbreakable_map_barrier:barrier"}, {["x"] = 0, ["y"] = 80, ["param1"] = 15, ["z"] = 63, ["name"] = "unbreakable_map_barrier:barrier"}, {["x"] = 0, ["y"] = 80, ["param1"] = 15, ["z"] = 64, ["name"] = "unbreakable_map_barrier:barrier"}, {["x"] = 0, ["y"] = 80, ["param1"] = 15, ["z"] = 65, ["name"] = "unbreakable_map_barrier:barrier"}, {["x"] = 0, ["y"] = 80, ["param1"] = 15, ["z"] = 66, ["name"] = "unbreakable_map_barrier:barrier"}, {["x"] = 0, ["y"] = 80, ["param1"] = 15, ["z"] = 67, ["name"] = "unbreakable_map_barrier:barrier"}, {["x"] = 0, ["y"] = 80, ["param1"] = 15, ["z"] = 68, ["name"] = "unbreakable_map_barrier:barrier"}, {["x"] = 0, ["y"] = 80, ["param1"] = 15, ["z"] = 69, ["name"] = "unbreakable_map_barrier:barrier"}, {["x"] = 0, ["y"] = 80, ["param1"] = 15, ["z"] = 70, ["name"] = "unbreakable_map_barrier:barrier"}, {["x"] = 0, ["y"] = 80, ["param1"] = 15, ["z"] = 71, ["name"] = "unbreakable_map_barrier:barrier"}, {["x"] = 0, ["y"] = 80, ["param1"] = 15, ["z"] = 72, ["name"] = "unbreakable_map_barrier:barrier"}, {["x"] = 0, ["y"] = 80, ["param1"] = 15, ["z"] = 73, ["name"] = "unbreakable_map_barrier:barrier"}, {["x"] = 0, ["y"] = 80, ["param1"] = 15, ["z"] = 74, ["name"] = "unbreakable_map_barrier:barrier"}, {["x"] = 0, ["y"] = 80, ["param1"] = 15, ["z"] = 75, ["name"] = "unbreakable_map_barrier:barrier"}, {["x"] = 0, ["y"] = 80, ["param1"] = 15, ["z"] = 76, ["name"] = "unbreakable_map_barrier:barrier"}, {["x"] = 0, ["y"] = 80, ["param1"] = 15, ["z"] = 77, ["name"] = "unbreakable_map_barrier:barrier"}, {["x"] = 0, ["y"] = 80, ["param1"] = 15, ["z"] = 78, ["name"] = "unbreakable_map_barrier:barrier"}, {["x"] = 0, ["y"] = 80, ["param1"] = 15, ["z"] = 79, ["name"] = "unbreakable_map_barrier:barrier"}, {["x"] = 0, ["y"] = 80, ["param1"] = 15, ["z"] = 80, ["name"] = "unbreakable_map_barrier:barrier"}, {["x"] = 1, ["y"] = 80, ["param1"] = 15, ["z"] = 0, ["name"] = "unbreakable_map_barrier:barrier"}, {["x"] = 1, ["y"] = 80, ["param1"] = 15, ["z"] = 1, ["name"] = "unbreakable_map_barrier:barrier"}, {["x"] = 1, ["y"] = 80, ["param1"] = 15, ["z"] = 2, ["name"] = "unbreakable_map_barrier:barrier"}, {["x"] = 1, ["y"] = 80, ["param1"] = 15, ["z"] = 3, ["name"] = "unbreakable_map_barrier:barrier"}, {["x"] = 1, ["y"] = 80, ["param1"] = 15, ["z"] = 4, ["name"] = "unbreakable_map_barrier:barrier"}, {["x"] = 1, ["y"] = 80, ["param1"] = 15, ["z"] = 5, ["name"] = "unbreakable_map_barrier:barrier"}, {["x"] = 1, ["y"] = 80, ["param1"] = 15, ["z"] = 6, ["name"] = "unbreakable_map_barrier:barrier"}, {["x"] = 1, ["y"] = 80, ["param1"] = 15, ["z"] = 7, ["name"] = "unbreakable_map_barrier:barrier"}, {["x"] = 1, ["y"] = 80, ["param1"] = 15, ["z"] = 8, ["name"] = "unbreakable_map_barrier:barrier"}, {["x"] = 1, ["y"] = 80, ["param1"] = 15, ["z"] = 9, ["name"] = "unbreakable_map_barrier:barrier"}, {["x"] = 1, ["y"] = 80, ["param1"] = 15, ["z"] = 10, ["name"] = "unbreakable_map_barrier:barrier"}, {["x"] = 1, ["y"] = 80, ["param1"] = 15, ["z"] = 11, ["name"] = "unbreakable_map_barrier:barrier"}, {["x"] = 1, ["y"] = 80, ["param1"] = 15, ["z"] = 12, ["name"] = "unbreakable_map_barrier:barrier"}, {["x"] = 1, ["y"] = 80, ["param1"] = 15, ["z"] = 13, ["name"] = "unbreakable_map_barrier:barrier"}, {["x"] = 1, ["y"] = 80, ["param1"] = 15, ["z"] = 14, ["name"] = "unbreakable_map_barrier:barrier"}, {["x"] = 1, ["y"] = 80, ["param1"] = 15, ["z"] = 15, ["name"] = "unbreakable_map_barrier:barrier"}, {["x"] = 1, ["y"] = 80, ["param1"] = 15, ["z"] = 16, ["name"] = "unbreakable_map_barrier:barrier"}, {["x"] = 1, ["y"] = 80, ["param1"] = 15, ["z"] = 17, ["name"] = "unbreakable_map_barrier:barrier"}, {["x"] = 1, ["y"] = 80, ["param1"] = 15, ["z"] = 18, ["name"] = "unbreakable_map_barrier:barrier"}, {["x"] = 1, ["y"] = 80, ["param1"] = 15, ["z"] = 19, ["name"] = "unbreakable_map_barrier:barrier"}, {["x"] = 1, ["y"] = 80, ["param1"] = 15, ["z"] = 20, ["name"] = "unbreakable_map_barrier:barrier"}, {["x"] = 1, ["y"] = 80, ["param1"] = 15, ["z"] = 21, ["name"] = "unbreakable_map_barrier:barrier"}, {["x"] = 1, ["y"] = 80, ["param1"] = 15, ["z"] = 22, ["name"] = "unbreakable_map_barrier:barrier"}, {["x"] = 1, ["y"] = 80, ["param1"] = 15, ["z"] = 23, ["name"] = "unbreakable_map_barrier:barrier"}, {["x"] = 1, ["y"] = 80, ["param1"] = 15, ["z"] = 24, ["name"] = "unbreakable_map_barrier:barrier"}, {["x"] = 1, ["y"] = 80, ["param1"] = 15, ["z"] = 25, ["name"] = "unbreakable_map_barrier:barrier"}, {["x"] = 1, ["y"] = 80, ["param1"] = 15, ["z"] = 26, ["name"] = "unbreakable_map_barrier:barrier"}, {["x"] = 1, ["y"] = 80, ["param1"] = 15, ["z"] = 27, ["name"] = "unbreakable_map_barrier:barrier"}, {["x"] = 1, ["y"] = 80, ["param1"] = 15, ["z"] = 28, ["name"] = "unbreakable_map_barrier:barrier"}, {["x"] = 1, ["y"] = 80, ["param1"] = 15, ["z"] = 29, ["name"] = "unbreakable_map_barrier:barrier"}, {["x"] = 1, ["y"] = 80, ["param1"] = 15, ["z"] = 30, ["name"] = "unbreakable_map_barrier:barrier"}, {["x"] = 1, ["y"] = 80, ["param1"] = 15, ["z"] = 31, ["name"] = "unbreakable_map_barrier:barrier"}, {["x"] = 1, ["y"] = 80, ["param1"] = 15, ["z"] = 32, ["name"] = "unbreakable_map_barrier:barrier"}, {["x"] = 1, ["y"] = 80, ["param1"] = 15, ["z"] = 33, ["name"] = "unbreakable_map_barrier:barrier"}, {["x"] = 1, ["y"] = 80, ["param1"] = 15, ["z"] = 34, ["name"] = "unbreakable_map_barrier:barrier"}, {["x"] = 1, ["y"] = 80, ["param1"] = 15, ["z"] = 35, ["name"] = "unbreakable_map_barrier:barrier"}, {["x"] = 1, ["y"] = 80, ["param1"] = 15, ["z"] = 36, ["name"] = "unbreakable_map_barrier:barrier"}, {["x"] = 1, ["y"] = 80, ["param1"] = 15, ["z"] = 37, ["name"] = "unbreakable_map_barrier:barrier"}, {["x"] = 1, ["y"] = 80, ["param1"] = 15, ["z"] = 38, ["name"] = "unbreakable_map_barrier:barrier"}, {["x"] = 1, ["y"] = 80, ["param1"] = 15, ["z"] = 39, ["name"] = "unbreakable_map_barrier:barrier"}, {["x"] = 1, ["y"] = 80, ["param1"] = 15, ["z"] = 40, ["name"] = "unbreakable_map_barrier:barrier"}, {["x"] = 1, ["y"] = 80, ["param1"] = 15, ["z"] = 41, ["name"] = "unbreakable_map_barrier:barrier"}, {["x"] = 1, ["y"] = 80, ["param1"] = 15, ["z"] = 42, ["name"] = "unbreakable_map_barrier:barrier"}, {["x"] = 1, ["y"] = 80, ["param1"] = 15, ["z"] = 43, ["name"] = "unbreakable_map_barrier:barrier"}, {["x"] = 1, ["y"] = 80, ["param1"] = 15, ["z"] = 44, ["name"] = "unbreakable_map_barrier:barrier"}, {["x"] = 1, ["y"] = 80, ["param1"] = 15, ["z"] = 45, ["name"] = "unbreakable_map_barrier:barrier"}, {["x"] = 1, ["y"] = 80, ["param1"] = 15, ["z"] = 46, ["name"] = "unbreakable_map_barrier:barrier"}, {["x"] = 1, ["y"] = 80, ["param1"] = 15, ["z"] = 47, ["name"] = "unbreakable_map_barrier:barrier"}, {["x"] = 1, ["y"] = 80, ["param1"] = 15, ["z"] = 48, ["name"] = "unbreakable_map_barrier:barrier"}, {["x"] = 1, ["y"] = 80, ["param1"] = 15, ["z"] = 49, ["name"] = "unbreakable_map_barrier:barrier"}, {["x"] = 1, ["y"] = 80, ["param1"] = 15, ["z"] = 50, ["name"] = "unbreakable_map_barrier:barrier"}, {["x"] = 1, ["y"] = 80, ["param1"] = 15, ["z"] = 51, ["name"] = "unbreakable_map_barrier:barrier"}, {["x"] = 1, ["y"] = 80, ["param1"] = 15, ["z"] = 52, ["name"] = "unbreakable_map_barrier:barrier"}, {["x"] = 1, ["y"] = 80, ["param1"] = 15, ["z"] = 53, ["name"] = "unbreakable_map_barrier:barrier"}, {["x"] = 1, ["y"] = 80, ["param1"] = 15, ["z"] = 54, ["name"] = "unbreakable_map_barrier:barrier"}, {["x"] = 1, ["y"] = 80, ["param1"] = 15, ["z"] = 55, ["name"] = "unbreakable_map_barrier:barrier"}, {["x"] = 1, ["y"] = 80, ["param1"] = 15, ["z"] = 56, ["name"] = "unbreakable_map_barrier:barrier"}, {["x"] = 1, ["y"] = 80, ["param1"] = 15, ["z"] = 57, ["name"] = "unbreakable_map_barrier:barrier"}, {["x"] = 1, ["y"] = 80, ["param1"] = 15, ["z"] = 58, ["name"] = "unbreakable_map_barrier:barrier"}, {["x"] = 1, ["y"] = 80, ["param1"] = 15, ["z"] = 59, ["name"] = "unbreakable_map_barrier:barrier"}, {["x"] = 1, ["y"] = 80, ["param1"] = 15, ["z"] = 60, ["name"] = "unbreakable_map_barrier:barrier"}, {["x"] = 1, ["y"] = 80, ["param1"] = 15, ["z"] = 61, ["name"] = "unbreakable_map_barrier:barrier"}, {["x"] = 1, ["y"] = 80, ["param1"] = 15, ["z"] = 62, ["name"] = "unbreakable_map_barrier:barrier"}, {["x"] = 1, ["y"] = 80, ["param1"] = 15, ["z"] = 63, ["name"] = "unbreakable_map_barrier:barrier"}, {["x"] = 1, ["y"] = 80, ["param1"] = 15, ["z"] = 64, ["name"] = "unbreakable_map_barrier:barrier"}, {["x"] = 1, ["y"] = 80, ["param1"] = 15, ["z"] = 65, ["name"] = "unbreakable_map_barrier:barrier"}, {["x"] = 1, ["y"] = 80, ["param1"] = 15, ["z"] = 66, ["name"] = "unbreakable_map_barrier:barrier"}, {["x"] = 1, ["y"] = 80, ["param1"] = 15, ["z"] = 67, ["name"] = "unbreakable_map_barrier:barrier"}, {["x"] = 1, ["y"] = 80, ["param1"] = 15, ["z"] = 68, ["name"] = "unbreakable_map_barrier:barrier"}, {["x"] = 1, ["y"] = 80, ["param1"] = 15, ["z"] = 69, ["name"] = "unbreakable_map_barrier:barrier"}, {["x"] = 1, ["y"] = 80, ["param1"] = 15, ["z"] = 70, ["name"] = "unbreakable_map_barrier:barrier"}, {["x"] = 1, ["y"] = 80, ["param1"] = 15, ["z"] = 71, ["name"] = "unbreakable_map_barrier:barrier"}, {["x"] = 1, ["y"] = 80, ["param1"] = 15, ["z"] = 72, ["name"] = "unbreakable_map_barrier:barrier"}, {["x"] = 1, ["y"] = 80, ["param1"] = 15, ["z"] = 73, ["name"] = "unbreakable_map_barrier:barrier"}, {["x"] = 1, ["y"] = 80, ["param1"] = 15, ["z"] = 74, ["name"] = "unbreakable_map_barrier:barrier"}, {["x"] = 1, ["y"] = 80, ["param1"] = 15, ["z"] = 75, ["name"] = "unbreakable_map_barrier:barrier"}, {["x"] = 1, ["y"] = 80, ["param1"] = 15, ["z"] = 76, ["name"] = "unbreakable_map_barrier:barrier"}, {["x"] = 1, ["y"] = 80, ["param1"] = 15, ["z"] = 77, ["name"] = "unbreakable_map_barrier:barrier"}, {["x"] = 1, ["y"] = 80, ["param1"] = 15, ["z"] = 78, ["name"] = "unbreakable_map_barrier:barrier"}, {["x"] = 1, ["y"] = 80, ["param1"] = 15, ["z"] = 79, ["name"] = "unbreakable_map_barrier:barrier"}, {["x"] = 1, ["y"] = 80, ["param1"] = 15, ["z"] = 80, ["name"] = "unbreakable_map_barrier:barrier"}, {["x"] = 2, ["y"] = 80, ["param1"] = 15, ["z"] = 0, ["name"] = "unbreakable_map_barrier:barrier"}, {["x"] = 2, ["y"] = 80, ["param1"] = 15, ["z"] = 1, ["name"] = "unbreakable_map_barrier:barrier"}, {["x"] = 2, ["y"] = 80, ["param1"] = 15, ["z"] = 2, ["name"] = "unbreakable_map_barrier:barrier"}, {["x"] = 2, ["y"] = 80, ["param1"] = 15, ["z"] = 3, ["name"] = "unbreakable_map_barrier:barrier"}, {["x"] = 2, ["y"] = 80, ["param1"] = 15, ["z"] = 4, ["name"] = "unbreakable_map_barrier:barrier"}, {["x"] = 2, ["y"] = 80, ["param1"] = 15, ["z"] = 5, ["name"] = "unbreakable_map_barrier:barrier"}, {["x"] = 2, ["y"] = 80, ["param1"] = 15, ["z"] = 6, ["name"] = "unbreakable_map_barrier:barrier"}, {["x"] = 2, ["y"] = 80, ["param1"] = 15, ["z"] = 7, ["name"] = "unbreakable_map_barrier:barrier"}, {["x"] = 2, ["y"] = 80, ["param1"] = 15, ["z"] = 8, ["name"] = "unbreakable_map_barrier:barrier"}, {["x"] = 2, ["y"] = 80, ["param1"] = 15, ["z"] = 9, ["name"] = "unbreakable_map_barrier:barrier"}, {["x"] = 2, ["y"] = 80, ["param1"] = 15, ["z"] = 10, ["name"] = "unbreakable_map_barrier:barrier"}, {["x"] = 2, ["y"] = 80, ["param1"] = 15, ["z"] = 11, ["name"] = "unbreakable_map_barrier:barrier"}, {["x"] = 2, ["y"] = 80, ["param1"] = 15, ["z"] = 12, ["name"] = "unbreakable_map_barrier:barrier"}, {["x"] = 2, ["y"] = 80, ["param1"] = 15, ["z"] = 13, ["name"] = "unbreakable_map_barrier:barrier"}, {["x"] = 2, ["y"] = 80, ["param1"] = 15, ["z"] = 14, ["name"] = "unbreakable_map_barrier:barrier"}, {["x"] = 2, ["y"] = 80, ["param1"] = 15, ["z"] = 15, ["name"] = "unbreakable_map_barrier:barrier"}, {["x"] = 2, ["y"] = 80, ["param1"] = 15, ["z"] = 16, ["name"] = "unbreakable_map_barrier:barrier"}, {["x"] = 2, ["y"] = 80, ["param1"] = 15, ["z"] = 17, ["name"] = "unbreakable_map_barrier:barrier"}, {["x"] = 2, ["y"] = 80, ["param1"] = 15, ["z"] = 18, ["name"] = "unbreakable_map_barrier:barrier"}, {["x"] = 2, ["y"] = 80, ["param1"] = 15, ["z"] = 19, ["name"] = "unbreakable_map_barrier:barrier"}, {["x"] = 2, ["y"] = 80, ["param1"] = 15, ["z"] = 20, ["name"] = "unbreakable_map_barrier:barrier"}, {["x"] = 2, ["y"] = 80, ["param1"] = 15, ["z"] = 21, ["name"] = "unbreakable_map_barrier:barrier"}, {["x"] = 2, ["y"] = 80, ["param1"] = 15, ["z"] = 22, ["name"] = "unbreakable_map_barrier:barrier"}, {["x"] = 2, ["y"] = 80, ["param1"] = 15, ["z"] = 23, ["name"] = "unbreakable_map_barrier:barrier"}, {["x"] = 2, ["y"] = 80, ["param1"] = 15, ["z"] = 24, ["name"] = "unbreakable_map_barrier:barrier"}, {["x"] = 2, ["y"] = 80, ["param1"] = 15, ["z"] = 25, ["name"] = "unbreakable_map_barrier:barrier"}, {["x"] = 2, ["y"] = 80, ["param1"] = 15, ["z"] = 26, ["name"] = "unbreakable_map_barrier:barrier"}, {["x"] = 2, ["y"] = 80, ["param1"] = 15, ["z"] = 27, ["name"] = "unbreakable_map_barrier:barrier"}, {["x"] = 2, ["y"] = 80, ["param1"] = 15, ["z"] = 28, ["name"] = "unbreakable_map_barrier:barrier"}, {["x"] = 2, ["y"] = 80, ["param1"] = 15, ["z"] = 29, ["name"] = "unbreakable_map_barrier:barrier"}, {["x"] = 2, ["y"] = 80, ["param1"] = 15, ["z"] = 30, ["name"] = "unbreakable_map_barrier:barrier"}, {["x"] = 2, ["y"] = 80, ["param1"] = 15, ["z"] = 31, ["name"] = "unbreakable_map_barrier:barrier"}, {["x"] = 2, ["y"] = 80, ["param1"] = 15, ["z"] = 32, ["name"] = "unbreakable_map_barrier:barrier"}, {["x"] = 2, ["y"] = 80, ["param1"] = 15, ["z"] = 33, ["name"] = "unbreakable_map_barrier:barrier"}, {["x"] = 2, ["y"] = 80, ["param1"] = 15, ["z"] = 34, ["name"] = "unbreakable_map_barrier:barrier"}, {["x"] = 2, ["y"] = 80, ["param1"] = 15, ["z"] = 35, ["name"] = "unbreakable_map_barrier:barrier"}, {["x"] = 2, ["y"] = 80, ["param1"] = 15, ["z"] = 36, ["name"] = "unbreakable_map_barrier:barrier"}, {["x"] = 2, ["y"] = 80, ["param1"] = 15, ["z"] = 37, ["name"] = "unbreakable_map_barrier:barrier"}, {["x"] = 2, ["y"] = 80, ["param1"] = 15, ["z"] = 38, ["name"] = "unbreakable_map_barrier:barrier"}, {["x"] = 2, ["y"] = 80, ["param1"] = 15, ["z"] = 39, ["name"] = "unbreakable_map_barrier:barrier"}, {["x"] = 2, ["y"] = 80, ["param1"] = 15, ["z"] = 40, ["name"] = "unbreakable_map_barrier:barrier"}, {["x"] = 2, ["y"] = 80, ["param1"] = 15, ["z"] = 41, ["name"] = "unbreakable_map_barrier:barrier"}, {["x"] = 2, ["y"] = 80, ["param1"] = 15, ["z"] = 42, ["name"] = "unbreakable_map_barrier:barrier"}, {["x"] = 2, ["y"] = 80, ["param1"] = 15, ["z"] = 43, ["name"] = "unbreakable_map_barrier:barrier"}, {["x"] = 2, ["y"] = 80, ["param1"] = 15, ["z"] = 44, ["name"] = "unbreakable_map_barrier:barrier"}, {["x"] = 2, ["y"] = 80, ["param1"] = 15, ["z"] = 45, ["name"] = "unbreakable_map_barrier:barrier"}, {["x"] = 2, ["y"] = 80, ["param1"] = 15, ["z"] = 46, ["name"] = "unbreakable_map_barrier:barrier"}, {["x"] = 2, ["y"] = 80, ["param1"] = 15, ["z"] = 47, ["name"] = "unbreakable_map_barrier:barrier"}, {["x"] = 2, ["y"] = 80, ["param1"] = 15, ["z"] = 48, ["name"] = "unbreakable_map_barrier:barrier"}, {["x"] = 2, ["y"] = 80, ["param1"] = 15, ["z"] = 49, ["name"] = "unbreakable_map_barrier:barrier"}, {["x"] = 2, ["y"] = 80, ["param1"] = 15, ["z"] = 50, ["name"] = "unbreakable_map_barrier:barrier"}, {["x"] = 2, ["y"] = 80, ["param1"] = 15, ["z"] = 51, ["name"] = "unbreakable_map_barrier:barrier"}, {["x"] = 2, ["y"] = 80, ["param1"] = 15, ["z"] = 52, ["name"] = "unbreakable_map_barrier:barrier"}, {["x"] = 2, ["y"] = 80, ["param1"] = 15, ["z"] = 53, ["name"] = "unbreakable_map_barrier:barrier"}, {["x"] = 2, ["y"] = 80, ["param1"] = 15, ["z"] = 54, ["name"] = "unbreakable_map_barrier:barrier"}, {["x"] = 2, ["y"] = 80, ["param1"] = 15, ["z"] = 55, ["name"] = "unbreakable_map_barrier:barrier"}, {["x"] = 2, ["y"] = 80, ["param1"] = 15, ["z"] = 56, ["name"] = "unbreakable_map_barrier:barrier"}, {["x"] = 2, ["y"] = 80, ["param1"] = 15, ["z"] = 57, ["name"] = "unbreakable_map_barrier:barrier"}, {["x"] = 2, ["y"] = 80, ["param1"] = 15, ["z"] = 58, ["name"] = "unbreakable_map_barrier:barrier"}, {["x"] = 2, ["y"] = 80, ["param1"] = 15, ["z"] = 59, ["name"] = "unbreakable_map_barrier:barrier"}, {["x"] = 2, ["y"] = 80, ["param1"] = 15, ["z"] = 60, ["name"] = "unbreakable_map_barrier:barrier"}, {["x"] = 2, ["y"] = 80, ["param1"] = 15, ["z"] = 61, ["name"] = "unbreakable_map_barrier:barrier"}, {["x"] = 2, ["y"] = 80, ["param1"] = 15, ["z"] = 62, ["name"] = "unbreakable_map_barrier:barrier"}, {["x"] = 2, ["y"] = 80, ["param1"] = 15, ["z"] = 63, ["name"] = "unbreakable_map_barrier:barrier"}, {["x"] = 2, ["y"] = 80, ["param1"] = 15, ["z"] = 64, ["name"] = "unbreakable_map_barrier:barrier"}, {["x"] = 2, ["y"] = 80, ["param1"] = 15, ["z"] = 65, ["name"] = "unbreakable_map_barrier:barrier"}, {["x"] = 2, ["y"] = 80, ["param1"] = 15, ["z"] = 66, ["name"] = "unbreakable_map_barrier:barrier"}, {["x"] = 2, ["y"] = 80, ["param1"] = 15, ["z"] = 67, ["name"] = "unbreakable_map_barrier:barrier"}, {["x"] = 2, ["y"] = 80, ["param1"] = 15, ["z"] = 68, ["name"] = "unbreakable_map_barrier:barrier"}, {["x"] = 2, ["y"] = 80, ["param1"] = 15, ["z"] = 69, ["name"] = "unbreakable_map_barrier:barrier"}, {["x"] = 2, ["y"] = 80, ["param1"] = 15, ["z"] = 70, ["name"] = "unbreakable_map_barrier:barrier"}, {["x"] = 2, ["y"] = 80, ["param1"] = 15, ["z"] = 71, ["name"] = "unbreakable_map_barrier:barrier"}, {["x"] = 2, ["y"] = 80, ["param1"] = 15, ["z"] = 72, ["name"] = "unbreakable_map_barrier:barrier"}, {["x"] = 2, ["y"] = 80, ["param1"] = 15, ["z"] = 73, ["name"] = "unbreakable_map_barrier:barrier"}, {["x"] = 2, ["y"] = 80, ["param1"] = 15, ["z"] = 74, ["name"] = "unbreakable_map_barrier:barrier"}, {["x"] = 2, ["y"] = 80, ["param1"] = 15, ["z"] = 75, ["name"] = "unbreakable_map_barrier:barrier"}, {["x"] = 2, ["y"] = 80, ["param1"] = 15, ["z"] = 76, ["name"] = "unbreakable_map_barrier:barrier"}, {["x"] = 2, ["y"] = 80, ["param1"] = 15, ["z"] = 77, ["name"] = "unbreakable_map_barrier:barrier"}, {["x"] = 2, ["y"] = 80, ["param1"] = 15, ["z"] = 78, ["name"] = "unbreakable_map_barrier:barrier"}, {["x"] = 2, ["y"] = 80, ["param1"] = 15, ["z"] = 79, ["name"] = "unbreakable_map_barrier:barrier"}, {["x"] = 2, ["y"] = 80, ["param1"] = 15, ["z"] = 80, ["name"] = "unbreakable_map_barrier:barrier"}, {["x"] = 3, ["y"] = 80, ["param1"] = 15, ["z"] = 0, ["name"] = "unbreakable_map_barrier:barrier"}, {["x"] = 3, ["y"] = 80, ["param1"] = 15, ["z"] = 1, ["name"] = "unbreakable_map_barrier:barrier"}, {["x"] = 3, ["y"] = 80, ["param1"] = 15, ["z"] = 2, ["name"] = "unbreakable_map_barrier:barrier"}, {["x"] = 3, ["y"] = 80, ["param1"] = 15, ["z"] = 3, ["name"] = "unbreakable_map_barrier:barrier"}, {["x"] = 3, ["y"] = 80, ["param1"] = 15, ["z"] = 4, ["name"] = "unbreakable_map_barrier:barrier"}, {["x"] = 3, ["y"] = 80, ["param1"] = 15, ["z"] = 5, ["name"] = "unbreakable_map_barrier:barrier"}, {["x"] = 3, ["y"] = 80, ["param1"] = 15, ["z"] = 6, ["name"] = "unbreakable_map_barrier:barrier"}, {["x"] = 3, ["y"] = 80, ["param1"] = 15, ["z"] = 7, ["name"] = "unbreakable_map_barrier:barrier"}, {["x"] = 3, ["y"] = 80, ["param1"] = 15, ["z"] = 8, ["name"] = "unbreakable_map_barrier:barrier"}, {["x"] = 3, ["y"] = 80, ["param1"] = 15, ["z"] = 9, ["name"] = "unbreakable_map_barrier:barrier"}, {["x"] = 3, ["y"] = 80, ["param1"] = 15, ["z"] = 10, ["name"] = "unbreakable_map_barrier:barrier"}, {["x"] = 3, ["y"] = 80, ["param1"] = 15, ["z"] = 11, ["name"] = "unbreakable_map_barrier:barrier"}, {["x"] = 3, ["y"] = 80, ["param1"] = 15, ["z"] = 12, ["name"] = "unbreakable_map_barrier:barrier"}, {["x"] = 3, ["y"] = 80, ["param1"] = 15, ["z"] = 13, ["name"] = "unbreakable_map_barrier:barrier"}, {["x"] = 3, ["y"] = 80, ["param1"] = 15, ["z"] = 14, ["name"] = "unbreakable_map_barrier:barrier"}, {["x"] = 3, ["y"] = 80, ["param1"] = 15, ["z"] = 15, ["name"] = "unbreakable_map_barrier:barrier"}, {["x"] = 3, ["y"] = 80, ["param1"] = 15, ["z"] = 16, ["name"] = "unbreakable_map_barrier:barrier"}, {["x"] = 3, ["y"] = 80, ["param1"] = 15, ["z"] = 17, ["name"] = "unbreakable_map_barrier:barrier"}, {["x"] = 3, ["y"] = 80, ["param1"] = 15, ["z"] = 18, ["name"] = "unbreakable_map_barrier:barrier"}, {["x"] = 3, ["y"] = 80, ["param1"] = 15, ["z"] = 19, ["name"] = "unbreakable_map_barrier:barrier"}, {["x"] = 3, ["y"] = 80, ["param1"] = 15, ["z"] = 20, ["name"] = "unbreakable_map_barrier:barrier"}, {["x"] = 3, ["y"] = 80, ["param1"] = 15, ["z"] = 21, ["name"] = "unbreakable_map_barrier:barrier"}, {["x"] = 3, ["y"] = 80, ["param1"] = 15, ["z"] = 22, ["name"] = "unbreakable_map_barrier:barrier"}, {["x"] = 3, ["y"] = 80, ["param1"] = 15, ["z"] = 23, ["name"] = "unbreakable_map_barrier:barrier"}, {["x"] = 3, ["y"] = 80, ["param1"] = 15, ["z"] = 24, ["name"] = "unbreakable_map_barrier:barrier"}, {["x"] = 3, ["y"] = 80, ["param1"] = 15, ["z"] = 25, ["name"] = "unbreakable_map_barrier:barrier"}, {["x"] = 3, ["y"] = 80, ["param1"] = 15, ["z"] = 26, ["name"] = "unbreakable_map_barrier:barrier"}, {["x"] = 3, ["y"] = 80, ["param1"] = 15, ["z"] = 27, ["name"] = "unbreakable_map_barrier:barrier"}, {["x"] = 3, ["y"] = 80, ["param1"] = 15, ["z"] = 28, ["name"] = "unbreakable_map_barrier:barrier"}, {["x"] = 3, ["y"] = 80, ["param1"] = 15, ["z"] = 29, ["name"] = "unbreakable_map_barrier:barrier"}, {["x"] = 3, ["y"] = 80, ["param1"] = 15, ["z"] = 30, ["name"] = "unbreakable_map_barrier:barrier"}, {["x"] = 3, ["y"] = 80, ["param1"] = 15, ["z"] = 31, ["name"] = "unbreakable_map_barrier:barrier"}, {["x"] = 3, ["y"] = 80, ["param1"] = 15, ["z"] = 32, ["name"] = "unbreakable_map_barrier:barrier"}, {["x"] = 3, ["y"] = 80, ["param1"] = 15, ["z"] = 33, ["name"] = "unbreakable_map_barrier:barrier"}, {["x"] = 3, ["y"] = 80, ["param1"] = 15, ["z"] = 34, ["name"] = "unbreakable_map_barrier:barrier"}, {["x"] = 3, ["y"] = 80, ["param1"] = 15, ["z"] = 35, ["name"] = "unbreakable_map_barrier:barrier"}, {["x"] = 3, ["y"] = 80, ["param1"] = 15, ["z"] = 36, ["name"] = "unbreakable_map_barrier:barrier"}, {["x"] = 3, ["y"] = 80, ["param1"] = 15, ["z"] = 37, ["name"] = "unbreakable_map_barrier:barrier"}, {["x"] = 3, ["y"] = 80, ["param1"] = 15, ["z"] = 38, ["name"] = "unbreakable_map_barrier:barrier"}, {["x"] = 3, ["y"] = 80, ["param1"] = 15, ["z"] = 39, ["name"] = "unbreakable_map_barrier:barrier"}, {["x"] = 3, ["y"] = 80, ["param1"] = 15, ["z"] = 40, ["name"] = "unbreakable_map_barrier:barrier"}, {["x"] = 3, ["y"] = 80, ["param1"] = 15, ["z"] = 41, ["name"] = "unbreakable_map_barrier:barrier"}, {["x"] = 3, ["y"] = 80, ["param1"] = 15, ["z"] = 42, ["name"] = "unbreakable_map_barrier:barrier"}, {["x"] = 3, ["y"] = 80, ["param1"] = 15, ["z"] = 43, ["name"] = "unbreakable_map_barrier:barrier"}, {["x"] = 3, ["y"] = 80, ["param1"] = 15, ["z"] = 44, ["name"] = "unbreakable_map_barrier:barrier"}, {["x"] = 3, ["y"] = 80, ["param1"] = 15, ["z"] = 45, ["name"] = "unbreakable_map_barrier:barrier"}, {["x"] = 3, ["y"] = 80, ["param1"] = 15, ["z"] = 46, ["name"] = "unbreakable_map_barrier:barrier"}, {["x"] = 3, ["y"] = 80, ["param1"] = 15, ["z"] = 47, ["name"] = "unbreakable_map_barrier:barrier"}, {["x"] = 3, ["y"] = 80, ["param1"] = 15, ["z"] = 48, ["name"] = "unbreakable_map_barrier:barrier"}, {["x"] = 3, ["y"] = 80, ["param1"] = 15, ["z"] = 49, ["name"] = "unbreakable_map_barrier:barrier"}, {["x"] = 3, ["y"] = 80, ["param1"] = 15, ["z"] = 50, ["name"] = "unbreakable_map_barrier:barrier"}, {["x"] = 3, ["y"] = 80, ["param1"] = 15, ["z"] = 51, ["name"] = "unbreakable_map_barrier:barrier"}, {["x"] = 3, ["y"] = 80, ["param1"] = 15, ["z"] = 52, ["name"] = "unbreakable_map_barrier:barrier"}, {["x"] = 3, ["y"] = 80, ["param1"] = 15, ["z"] = 53, ["name"] = "unbreakable_map_barrier:barrier"}, {["x"] = 3, ["y"] = 80, ["param1"] = 15, ["z"] = 54, ["name"] = "unbreakable_map_barrier:barrier"}, {["x"] = 3, ["y"] = 80, ["param1"] = 15, ["z"] = 55, ["name"] = "unbreakable_map_barrier:barrier"}, {["x"] = 3, ["y"] = 80, ["param1"] = 15, ["z"] = 56, ["name"] = "unbreakable_map_barrier:barrier"}, {["x"] = 3, ["y"] = 80, ["param1"] = 15, ["z"] = 57, ["name"] = "unbreakable_map_barrier:barrier"}, {["x"] = 3, ["y"] = 80, ["param1"] = 15, ["z"] = 58, ["name"] = "unbreakable_map_barrier:barrier"}, {["x"] = 3, ["y"] = 80, ["param1"] = 15, ["z"] = 59, ["name"] = "unbreakable_map_barrier:barrier"}, {["x"] = 3, ["y"] = 80, ["param1"] = 15, ["z"] = 60, ["name"] = "unbreakable_map_barrier:barrier"}, {["x"] = 3, ["y"] = 80, ["param1"] = 15, ["z"] = 61, ["name"] = "unbreakable_map_barrier:barrier"}, {["x"] = 3, ["y"] = 80, ["param1"] = 15, ["z"] = 62, ["name"] = "unbreakable_map_barrier:barrier"}, {["x"] = 3, ["y"] = 80, ["param1"] = 15, ["z"] = 63, ["name"] = "unbreakable_map_barrier:barrier"}, {["x"] = 3, ["y"] = 80, ["param1"] = 15, ["z"] = 64, ["name"] = "unbreakable_map_barrier:barrier"}, {["x"] = 3, ["y"] = 80, ["param1"] = 15, ["z"] = 65, ["name"] = "unbreakable_map_barrier:barrier"}, {["x"] = 3, ["y"] = 80, ["param1"] = 15, ["z"] = 66, ["name"] = "unbreakable_map_barrier:barrier"}, {["x"] = 3, ["y"] = 80, ["param1"] = 15, ["z"] = 67, ["name"] = "unbreakable_map_barrier:barrier"}, {["x"] = 3, ["y"] = 80, ["param1"] = 15, ["z"] = 68, ["name"] = "unbreakable_map_barrier:barrier"}, {["x"] = 3, ["y"] = 80, ["param1"] = 15, ["z"] = 69, ["name"] = "unbreakable_map_barrier:barrier"}, {["x"] = 3, ["y"] = 80, ["param1"] = 15, ["z"] = 70, ["name"] = "unbreakable_map_barrier:barrier"}, {["x"] = 3, ["y"] = 80, ["param1"] = 15, ["z"] = 71, ["name"] = "unbreakable_map_barrier:barrier"}, {["x"] = 3, ["y"] = 80, ["param1"] = 15, ["z"] = 72, ["name"] = "unbreakable_map_barrier:barrier"}, {["x"] = 3, ["y"] = 80, ["param1"] = 15, ["z"] = 73, ["name"] = "unbreakable_map_barrier:barrier"}, {["x"] = 3, ["y"] = 80, ["param1"] = 15, ["z"] = 74, ["name"] = "unbreakable_map_barrier:barrier"}, {["x"] = 3, ["y"] = 80, ["param1"] = 15, ["z"] = 75, ["name"] = "unbreakable_map_barrier:barrier"}, {["x"] = 3, ["y"] = 80, ["param1"] = 15, ["z"] = 76, ["name"] = "unbreakable_map_barrier:barrier"}, {["x"] = 3, ["y"] = 80, ["param1"] = 15, ["z"] = 77, ["name"] = "unbreakable_map_barrier:barrier"}, {["x"] = 3, ["y"] = 80, ["param1"] = 15, ["z"] = 78, ["name"] = "unbreakable_map_barrier:barrier"}, {["x"] = 3, ["y"] = 80, ["param1"] = 15, ["z"] = 79, ["name"] = "unbreakable_map_barrier:barrier"}, {["x"] = 3, ["y"] = 80, ["param1"] = 15, ["z"] = 80, ["name"] = "unbreakable_map_barrier:barrier"}, {["x"] = 4, ["y"] = 80, ["param1"] = 15, ["z"] = 0, ["name"] = "unbreakable_map_barrier:barrier"}, {["x"] = 4, ["y"] = 80, ["param1"] = 15, ["z"] = 1, ["name"] = "unbreakable_map_barrier:barrier"}, {["x"] = 4, ["y"] = 80, ["param1"] = 15, ["z"] = 2, ["name"] = "unbreakable_map_barrier:barrier"}, {["x"] = 4, ["y"] = 80, ["param1"] = 15, ["z"] = 3, ["name"] = "unbreakable_map_barrier:barrier"}, {["x"] = 4, ["y"] = 80, ["param1"] = 15, ["z"] = 4, ["name"] = "unbreakable_map_barrier:barrier"}, {["x"] = 4, ["y"] = 80, ["param1"] = 15, ["z"] = 5, ["name"] = "unbreakable_map_barrier:barrier"}, {["x"] = 4, ["y"] = 80, ["param1"] = 15, ["z"] = 6, ["name"] = "unbreakable_map_barrier:barrier"}, {["x"] = 4, ["y"] = 80, ["param1"] = 15, ["z"] = 7, ["name"] = "unbreakable_map_barrier:barrier"}, {["x"] = 4, ["y"] = 80, ["param1"] = 15, ["z"] = 8, ["name"] = "unbreakable_map_barrier:barrier"}, {["x"] = 4, ["y"] = 80, ["param1"] = 15, ["z"] = 9, ["name"] = "unbreakable_map_barrier:barrier"}, {["x"] = 4, ["y"] = 80, ["param1"] = 15, ["z"] = 10, ["name"] = "unbreakable_map_barrier:barrier"}, {["x"] = 4, ["y"] = 80, ["param1"] = 15, ["z"] = 11, ["name"] = "unbreakable_map_barrier:barrier"}, {["x"] = 4, ["y"] = 80, ["param1"] = 15, ["z"] = 12, ["name"] = "unbreakable_map_barrier:barrier"}, {["x"] = 4, ["y"] = 80, ["param1"] = 15, ["z"] = 13, ["name"] = "unbreakable_map_barrier:barrier"}, {["x"] = 4, ["y"] = 80, ["param1"] = 15, ["z"] = 14, ["name"] = "unbreakable_map_barrier:barrier"}, {["x"] = 4, ["y"] = 80, ["param1"] = 15, ["z"] = 15, ["name"] = "unbreakable_map_barrier:barrier"}, {["x"] = 4, ["y"] = 80, ["param1"] = 15, ["z"] = 16, ["name"] = "unbreakable_map_barrier:barrier"}, {["x"] = 4, ["y"] = 80, ["param1"] = 15, ["z"] = 17, ["name"] = "unbreakable_map_barrier:barrier"}, {["x"] = 4, ["y"] = 80, ["param1"] = 15, ["z"] = 18, ["name"] = "unbreakable_map_barrier:barrier"}, {["x"] = 4, ["y"] = 80, ["param1"] = 15, ["z"] = 19, ["name"] = "unbreakable_map_barrier:barrier"}, {["x"] = 4, ["y"] = 80, ["param1"] = 15, ["z"] = 20, ["name"] = "unbreakable_map_barrier:barrier"}, {["x"] = 4, ["y"] = 80, ["param1"] = 15, ["z"] = 21, ["name"] = "unbreakable_map_barrier:barrier"}, {["x"] = 4, ["y"] = 80, ["param1"] = 15, ["z"] = 22, ["name"] = "unbreakable_map_barrier:barrier"}, {["x"] = 4, ["y"] = 80, ["param1"] = 15, ["z"] = 23, ["name"] = "unbreakable_map_barrier:barrier"}, {["x"] = 4, ["y"] = 80, ["param1"] = 15, ["z"] = 24, ["name"] = "unbreakable_map_barrier:barrier"}, {["x"] = 4, ["y"] = 80, ["param1"] = 15, ["z"] = 25, ["name"] = "unbreakable_map_barrier:barrier"}, {["x"] = 4, ["y"] = 80, ["param1"] = 15, ["z"] = 26, ["name"] = "unbreakable_map_barrier:barrier"}, {["x"] = 4, ["y"] = 80, ["param1"] = 15, ["z"] = 27, ["name"] = "unbreakable_map_barrier:barrier"}, {["x"] = 4, ["y"] = 80, ["param1"] = 15, ["z"] = 28, ["name"] = "unbreakable_map_barrier:barrier"}, {["x"] = 4, ["y"] = 80, ["param1"] = 15, ["z"] = 29, ["name"] = "unbreakable_map_barrier:barrier"}, {["x"] = 4, ["y"] = 80, ["param1"] = 15, ["z"] = 30, ["name"] = "unbreakable_map_barrier:barrier"}, {["x"] = 4, ["y"] = 80, ["param1"] = 15, ["z"] = 31, ["name"] = "unbreakable_map_barrier:barrier"}, {["x"] = 4, ["y"] = 80, ["param1"] = 15, ["z"] = 32, ["name"] = "unbreakable_map_barrier:barrier"}, {["x"] = 4, ["y"] = 80, ["param1"] = 15, ["z"] = 33, ["name"] = "unbreakable_map_barrier:barrier"}, {["x"] = 4, ["y"] = 80, ["param1"] = 15, ["z"] = 34, ["name"] = "unbreakable_map_barrier:barrier"}, {["x"] = 4, ["y"] = 80, ["param1"] = 15, ["z"] = 35, ["name"] = "unbreakable_map_barrier:barrier"}, {["x"] = 4, ["y"] = 80, ["param1"] = 15, ["z"] = 36, ["name"] = "unbreakable_map_barrier:barrier"}, {["x"] = 4, ["y"] = 80, ["param1"] = 15, ["z"] = 37, ["name"] = "unbreakable_map_barrier:barrier"}, {["x"] = 4, ["y"] = 80, ["param1"] = 15, ["z"] = 38, ["name"] = "unbreakable_map_barrier:barrier"}, {["x"] = 4, ["y"] = 80, ["param1"] = 15, ["z"] = 39, ["name"] = "unbreakable_map_barrier:barrier"}, {["x"] = 4, ["y"] = 80, ["param1"] = 15, ["z"] = 40, ["name"] = "unbreakable_map_barrier:barrier"}, {["x"] = 4, ["y"] = 80, ["param1"] = 15, ["z"] = 41, ["name"] = "unbreakable_map_barrier:barrier"}, {["x"] = 4, ["y"] = 80, ["param1"] = 15, ["z"] = 42, ["name"] = "unbreakable_map_barrier:barrier"}, {["x"] = 4, ["y"] = 80, ["param1"] = 15, ["z"] = 43, ["name"] = "unbreakable_map_barrier:barrier"}, {["x"] = 4, ["y"] = 80, ["param1"] = 15, ["z"] = 44, ["name"] = "unbreakable_map_barrier:barrier"}, {["x"] = 4, ["y"] = 80, ["param1"] = 15, ["z"] = 45, ["name"] = "unbreakable_map_barrier:barrier"}, {["x"] = 4, ["y"] = 80, ["param1"] = 15, ["z"] = 46, ["name"] = "unbreakable_map_barrier:barrier"}, {["x"] = 4, ["y"] = 80, ["param1"] = 15, ["z"] = 47, ["name"] = "unbreakable_map_barrier:barrier"}, {["x"] = 4, ["y"] = 80, ["param1"] = 15, ["z"] = 48, ["name"] = "unbreakable_map_barrier:barrier"}, {["x"] = 4, ["y"] = 80, ["param1"] = 15, ["z"] = 49, ["name"] = "unbreakable_map_barrier:barrier"}, {["x"] = 4, ["y"] = 80, ["param1"] = 15, ["z"] = 50, ["name"] = "unbreakable_map_barrier:barrier"}, {["x"] = 4, ["y"] = 80, ["param1"] = 15, ["z"] = 51, ["name"] = "unbreakable_map_barrier:barrier"}, {["x"] = 4, ["y"] = 80, ["param1"] = 15, ["z"] = 52, ["name"] = "unbreakable_map_barrier:barrier"}, {["x"] = 4, ["y"] = 80, ["param1"] = 15, ["z"] = 53, ["name"] = "unbreakable_map_barrier:barrier"}, {["x"] = 4, ["y"] = 80, ["param1"] = 15, ["z"] = 54, ["name"] = "unbreakable_map_barrier:barrier"}, {["x"] = 4, ["y"] = 80, ["param1"] = 15, ["z"] = 55, ["name"] = "unbreakable_map_barrier:barrier"}, {["x"] = 4, ["y"] = 80, ["param1"] = 15, ["z"] = 56, ["name"] = "unbreakable_map_barrier:barrier"}, {["x"] = 4, ["y"] = 80, ["param1"] = 15, ["z"] = 57, ["name"] = "unbreakable_map_barrier:barrier"}, {["x"] = 4, ["y"] = 80, ["param1"] = 15, ["z"] = 58, ["name"] = "unbreakable_map_barrier:barrier"}, {["x"] = 4, ["y"] = 80, ["param1"] = 15, ["z"] = 59, ["name"] = "unbreakable_map_barrier:barrier"}, {["x"] = 4, ["y"] = 80, ["param1"] = 15, ["z"] = 60, ["name"] = "unbreakable_map_barrier:barrier"}, {["x"] = 4, ["y"] = 80, ["param1"] = 15, ["z"] = 61, ["name"] = "unbreakable_map_barrier:barrier"}, {["x"] = 4, ["y"] = 80, ["param1"] = 15, ["z"] = 62, ["name"] = "unbreakable_map_barrier:barrier"}, {["x"] = 4, ["y"] = 80, ["param1"] = 15, ["z"] = 63, ["name"] = "unbreakable_map_barrier:barrier"}, {["x"] = 4, ["y"] = 80, ["param1"] = 15, ["z"] = 64, ["name"] = "unbreakable_map_barrier:barrier"}, {["x"] = 4, ["y"] = 80, ["param1"] = 15, ["z"] = 65, ["name"] = "unbreakable_map_barrier:barrier"}, {["x"] = 4, ["y"] = 80, ["param1"] = 15, ["z"] = 66, ["name"] = "unbreakable_map_barrier:barrier"}, {["x"] = 4, ["y"] = 80, ["param1"] = 15, ["z"] = 67, ["name"] = "unbreakable_map_barrier:barrier"}, {["x"] = 4, ["y"] = 80, ["param1"] = 15, ["z"] = 68, ["name"] = "unbreakable_map_barrier:barrier"}, {["x"] = 4, ["y"] = 80, ["param1"] = 15, ["z"] = 69, ["name"] = "unbreakable_map_barrier:barrier"}, {["x"] = 4, ["y"] = 80, ["param1"] = 15, ["z"] = 70, ["name"] = "unbreakable_map_barrier:barrier"}, {["x"] = 4, ["y"] = 80, ["param1"] = 15, ["z"] = 71, ["name"] = "unbreakable_map_barrier:barrier"}, {["x"] = 4, ["y"] = 80, ["param1"] = 15, ["z"] = 72, ["name"] = "unbreakable_map_barrier:barrier"}, {["x"] = 4, ["y"] = 80, ["param1"] = 15, ["z"] = 73, ["name"] = "unbreakable_map_barrier:barrier"}, {["x"] = 4, ["y"] = 80, ["param1"] = 15, ["z"] = 74, ["name"] = "unbreakable_map_barrier:barrier"}, {["x"] = 4, ["y"] = 80, ["param1"] = 15, ["z"] = 75, ["name"] = "unbreakable_map_barrier:barrier"}, {["x"] = 4, ["y"] = 80, ["param1"] = 15, ["z"] = 76, ["name"] = "unbreakable_map_barrier:barrier"}, {["x"] = 4, ["y"] = 80, ["param1"] = 15, ["z"] = 77, ["name"] = "unbreakable_map_barrier:barrier"}, {["x"] = 4, ["y"] = 80, ["param1"] = 15, ["z"] = 78, ["name"] = "unbreakable_map_barrier:barrier"}, {["x"] = 4, ["y"] = 80, ["param1"] = 15, ["z"] = 79, ["name"] = "unbreakable_map_barrier:barrier"}, {["x"] = 4, ["y"] = 80, ["param1"] = 15, ["z"] = 80, ["name"] = "unbreakable_map_barrier:barrier"}, {["x"] = 5, ["y"] = 80, ["param1"] = 15, ["z"] = 0, ["name"] = "unbreakable_map_barrier:barrier"}, {["x"] = 5, ["y"] = 80, ["param1"] = 15, ["z"] = 1, ["name"] = "unbreakable_map_barrier:barrier"}, {["x"] = 5, ["y"] = 80, ["param1"] = 15, ["z"] = 2, ["name"] = "unbreakable_map_barrier:barrier"}, {["x"] = 5, ["y"] = 80, ["param1"] = 15, ["z"] = 3, ["name"] = "unbreakable_map_barrier:barrier"}, {["x"] = 5, ["y"] = 80, ["param1"] = 15, ["z"] = 4, ["name"] = "unbreakable_map_barrier:barrier"}, {["x"] = 5, ["y"] = 80, ["param1"] = 15, ["z"] = 5, ["name"] = "unbreakable_map_barrier:barrier"}, {["x"] = 5, ["y"] = 80, ["param1"] = 15, ["z"] = 6, ["name"] = "unbreakable_map_barrier:barrier"}, {["x"] = 5, ["y"] = 80, ["param1"] = 15, ["z"] = 7, ["name"] = "unbreakable_map_barrier:barrier"}, {["x"] = 5, ["y"] = 80, ["param1"] = 15, ["z"] = 8, ["name"] = "unbreakable_map_barrier:barrier"}, {["x"] = 5, ["y"] = 80, ["param1"] = 15, ["z"] = 9, ["name"] = "unbreakable_map_barrier:barrier"}, {["x"] = 5, ["y"] = 80, ["param1"] = 15, ["z"] = 10, ["name"] = "unbreakable_map_barrier:barrier"}, {["x"] = 5, ["y"] = 80, ["param1"] = 15, ["z"] = 11, ["name"] = "unbreakable_map_barrier:barrier"}, {["x"] = 5, ["y"] = 80, ["param1"] = 15, ["z"] = 12, ["name"] = "unbreakable_map_barrier:barrier"}, {["x"] = 5, ["y"] = 80, ["param1"] = 15, ["z"] = 13, ["name"] = "unbreakable_map_barrier:barrier"}, {["x"] = 5, ["y"] = 80, ["param1"] = 15, ["z"] = 14, ["name"] = "unbreakable_map_barrier:barrier"}, {["x"] = 5, ["y"] = 80, ["param1"] = 15, ["z"] = 15, ["name"] = "unbreakable_map_barrier:barrier"}, {["x"] = 5, ["y"] = 80, ["param1"] = 15, ["z"] = 16, ["name"] = "unbreakable_map_barrier:barrier"}, {["x"] = 5, ["y"] = 80, ["param1"] = 15, ["z"] = 17, ["name"] = "unbreakable_map_barrier:barrier"}, {["x"] = 5, ["y"] = 80, ["param1"] = 15, ["z"] = 18, ["name"] = "unbreakable_map_barrier:barrier"}, {["x"] = 5, ["y"] = 80, ["param1"] = 15, ["z"] = 19, ["name"] = "unbreakable_map_barrier:barrier"}, {["x"] = 5, ["y"] = 80, ["param1"] = 15, ["z"] = 20, ["name"] = "unbreakable_map_barrier:barrier"}, {["x"] = 5, ["y"] = 80, ["param1"] = 15, ["z"] = 21, ["name"] = "unbreakable_map_barrier:barrier"}, {["x"] = 5, ["y"] = 80, ["param1"] = 15, ["z"] = 22, ["name"] = "unbreakable_map_barrier:barrier"}, {["x"] = 5, ["y"] = 80, ["param1"] = 15, ["z"] = 23, ["name"] = "unbreakable_map_barrier:barrier"}, {["x"] = 5, ["y"] = 80, ["param1"] = 15, ["z"] = 24, ["name"] = "unbreakable_map_barrier:barrier"}, {["x"] = 5, ["y"] = 80, ["param1"] = 15, ["z"] = 25, ["name"] = "unbreakable_map_barrier:barrier"}, {["x"] = 5, ["y"] = 80, ["param1"] = 15, ["z"] = 26, ["name"] = "unbreakable_map_barrier:barrier"}, {["x"] = 5, ["y"] = 80, ["param1"] = 15, ["z"] = 27, ["name"] = "unbreakable_map_barrier:barrier"}, {["x"] = 5, ["y"] = 80, ["param1"] = 15, ["z"] = 28, ["name"] = "unbreakable_map_barrier:barrier"}, {["x"] = 5, ["y"] = 80, ["param1"] = 15, ["z"] = 29, ["name"] = "unbreakable_map_barrier:barrier"}, {["x"] = 5, ["y"] = 80, ["param1"] = 15, ["z"] = 30, ["name"] = "unbreakable_map_barrier:barrier"}, {["x"] = 5, ["y"] = 80, ["param1"] = 15, ["z"] = 31, ["name"] = "unbreakable_map_barrier:barrier"}, {["x"] = 5, ["y"] = 80, ["param1"] = 15, ["z"] = 32, ["name"] = "unbreakable_map_barrier:barrier"}, {["x"] = 5, ["y"] = 80, ["param1"] = 15, ["z"] = 33, ["name"] = "unbreakable_map_barrier:barrier"}, {["x"] = 5, ["y"] = 80, ["param1"] = 15, ["z"] = 34, ["name"] = "unbreakable_map_barrier:barrier"}, {["x"] = 5, ["y"] = 80, ["param1"] = 15, ["z"] = 35, ["name"] = "unbreakable_map_barrier:barrier"}, {["x"] = 5, ["y"] = 80, ["param1"] = 15, ["z"] = 36, ["name"] = "unbreakable_map_barrier:barrier"}, {["x"] = 5, ["y"] = 80, ["param1"] = 15, ["z"] = 37, ["name"] = "unbreakable_map_barrier:barrier"}, {["x"] = 5, ["y"] = 80, ["param1"] = 15, ["z"] = 38, ["name"] = "unbreakable_map_barrier:barrier"}, {["x"] = 5, ["y"] = 80, ["param1"] = 15, ["z"] = 39, ["name"] = "unbreakable_map_barrier:barrier"}, {["x"] = 5, ["y"] = 80, ["param1"] = 15, ["z"] = 40, ["name"] = "unbreakable_map_barrier:barrier"}, {["x"] = 5, ["y"] = 80, ["param1"] = 15, ["z"] = 41, ["name"] = "unbreakable_map_barrier:barrier"}, {["x"] = 5, ["y"] = 80, ["param1"] = 15, ["z"] = 42, ["name"] = "unbreakable_map_barrier:barrier"}, {["x"] = 5, ["y"] = 80, ["param1"] = 15, ["z"] = 43, ["name"] = "unbreakable_map_barrier:barrier"}, {["x"] = 5, ["y"] = 80, ["param1"] = 15, ["z"] = 44, ["name"] = "unbreakable_map_barrier:barrier"}, {["x"] = 5, ["y"] = 80, ["param1"] = 15, ["z"] = 45, ["name"] = "unbreakable_map_barrier:barrier"}, {["x"] = 5, ["y"] = 80, ["param1"] = 15, ["z"] = 46, ["name"] = "unbreakable_map_barrier:barrier"}, {["x"] = 5, ["y"] = 80, ["param1"] = 15, ["z"] = 47, ["name"] = "unbreakable_map_barrier:barrier"}, {["x"] = 5, ["y"] = 80, ["param1"] = 15, ["z"] = 48, ["name"] = "unbreakable_map_barrier:barrier"}, {["x"] = 5, ["y"] = 80, ["param1"] = 15, ["z"] = 49, ["name"] = "unbreakable_map_barrier:barrier"}, {["x"] = 5, ["y"] = 80, ["param1"] = 15, ["z"] = 50, ["name"] = "unbreakable_map_barrier:barrier"}, {["x"] = 5, ["y"] = 80, ["param1"] = 15, ["z"] = 51, ["name"] = "unbreakable_map_barrier:barrier"}, {["x"] = 5, ["y"] = 80, ["param1"] = 15, ["z"] = 52, ["name"] = "unbreakable_map_barrier:barrier"}, {["x"] = 5, ["y"] = 80, ["param1"] = 15, ["z"] = 53, ["name"] = "unbreakable_map_barrier:barrier"}, {["x"] = 5, ["y"] = 80, ["param1"] = 15, ["z"] = 54, ["name"] = "unbreakable_map_barrier:barrier"}, {["x"] = 5, ["y"] = 80, ["param1"] = 15, ["z"] = 55, ["name"] = "unbreakable_map_barrier:barrier"}, {["x"] = 5, ["y"] = 80, ["param1"] = 15, ["z"] = 56, ["name"] = "unbreakable_map_barrier:barrier"}, {["x"] = 5, ["y"] = 80, ["param1"] = 15, ["z"] = 57, ["name"] = "unbreakable_map_barrier:barrier"}, {["x"] = 5, ["y"] = 80, ["param1"] = 15, ["z"] = 58, ["name"] = "unbreakable_map_barrier:barrier"}, {["x"] = 5, ["y"] = 80, ["param1"] = 15, ["z"] = 59, ["name"] = "unbreakable_map_barrier:barrier"}, {["x"] = 5, ["y"] = 80, ["param1"] = 15, ["z"] = 60, ["name"] = "unbreakable_map_barrier:barrier"}, {["x"] = 5, ["y"] = 80, ["param1"] = 15, ["z"] = 61, ["name"] = "unbreakable_map_barrier:barrier"}, {["x"] = 5, ["y"] = 80, ["param1"] = 15, ["z"] = 62, ["name"] = "unbreakable_map_barrier:barrier"}, {["x"] = 5, ["y"] = 80, ["param1"] = 15, ["z"] = 63, ["name"] = "unbreakable_map_barrier:barrier"}, {["x"] = 5, ["y"] = 80, ["param1"] = 15, ["z"] = 64, ["name"] = "unbreakable_map_barrier:barrier"}, {["x"] = 5, ["y"] = 80, ["param1"] = 15, ["z"] = 65, ["name"] = "unbreakable_map_barrier:barrier"}, {["x"] = 5, ["y"] = 80, ["param1"] = 15, ["z"] = 66, ["name"] = "unbreakable_map_barrier:barrier"}, {["x"] = 5, ["y"] = 80, ["param1"] = 15, ["z"] = 67, ["name"] = "unbreakable_map_barrier:barrier"}, {["x"] = 5, ["y"] = 80, ["param1"] = 15, ["z"] = 68, ["name"] = "unbreakable_map_barrier:barrier"}, {["x"] = 5, ["y"] = 80, ["param1"] = 15, ["z"] = 69, ["name"] = "unbreakable_map_barrier:barrier"}, {["x"] = 5, ["y"] = 80, ["param1"] = 15, ["z"] = 70, ["name"] = "unbreakable_map_barrier:barrier"}, {["x"] = 5, ["y"] = 80, ["param1"] = 15, ["z"] = 71, ["name"] = "unbreakable_map_barrier:barrier"}, {["x"] = 5, ["y"] = 80, ["param1"] = 15, ["z"] = 72, ["name"] = "unbreakable_map_barrier:barrier"}, {["x"] = 5, ["y"] = 80, ["param1"] = 15, ["z"] = 73, ["name"] = "unbreakable_map_barrier:barrier"}, {["x"] = 5, ["y"] = 80, ["param1"] = 15, ["z"] = 74, ["name"] = "unbreakable_map_barrier:barrier"}, {["x"] = 5, ["y"] = 80, ["param1"] = 15, ["z"] = 75, ["name"] = "unbreakable_map_barrier:barrier"}, {["x"] = 5, ["y"] = 80, ["param1"] = 15, ["z"] = 76, ["name"] = "unbreakable_map_barrier:barrier"}, {["x"] = 5, ["y"] = 80, ["param1"] = 15, ["z"] = 77, ["name"] = "unbreakable_map_barrier:barrier"}, {["x"] = 5, ["y"] = 80, ["param1"] = 15, ["z"] = 78, ["name"] = "unbreakable_map_barrier:barrier"}, {["x"] = 5, ["y"] = 80, ["param1"] = 15, ["z"] = 79, ["name"] = "unbreakable_map_barrier:barrier"}, {["x"] = 5, ["y"] = 80, ["param1"] = 15, ["z"] = 80, ["name"] = "unbreakable_map_barrier:barrier"}, {["x"] = 6, ["y"] = 80, ["param1"] = 15, ["z"] = 0, ["name"] = "unbreakable_map_barrier:barrier"}, {["x"] = 6, ["y"] = 80, ["param1"] = 15, ["z"] = 1, ["name"] = "unbreakable_map_barrier:barrier"}, {["x"] = 6, ["y"] = 80, ["param1"] = 15, ["z"] = 2, ["name"] = "unbreakable_map_barrier:barrier"}, {["x"] = 6, ["y"] = 80, ["param1"] = 15, ["z"] = 3, ["name"] = "unbreakable_map_barrier:barrier"}, {["x"] = 6, ["y"] = 80, ["param1"] = 15, ["z"] = 4, ["name"] = "unbreakable_map_barrier:barrier"}, {["x"] = 6, ["y"] = 80, ["param1"] = 15, ["z"] = 5, ["name"] = "unbreakable_map_barrier:barrier"}, {["x"] = 6, ["y"] = 80, ["param1"] = 15, ["z"] = 6, ["name"] = "unbreakable_map_barrier:barrier"}, {["x"] = 6, ["y"] = 80, ["param1"] = 15, ["z"] = 7, ["name"] = "unbreakable_map_barrier:barrier"}, {["x"] = 6, ["y"] = 80, ["param1"] = 15, ["z"] = 8, ["name"] = "unbreakable_map_barrier:barrier"}, {["x"] = 6, ["y"] = 80, ["param1"] = 15, ["z"] = 9, ["name"] = "unbreakable_map_barrier:barrier"}, {["x"] = 6, ["y"] = 80, ["param1"] = 15, ["z"] = 10, ["name"] = "unbreakable_map_barrier:barrier"}, {["x"] = 6, ["y"] = 80, ["param1"] = 15, ["z"] = 11, ["name"] = "unbreakable_map_barrier:barrier"}, {["x"] = 6, ["y"] = 80, ["param1"] = 15, ["z"] = 12, ["name"] = "unbreakable_map_barrier:barrier"}, {["x"] = 6, ["y"] = 80, ["param1"] = 15, ["z"] = 13, ["name"] = "unbreakable_map_barrier:barrier"}, {["x"] = 6, ["y"] = 80, ["param1"] = 15, ["z"] = 14, ["name"] = "unbreakable_map_barrier:barrier"}, {["x"] = 6, ["y"] = 80, ["param1"] = 15, ["z"] = 15, ["name"] = "unbreakable_map_barrier:barrier"}, {["x"] = 6, ["y"] = 80, ["param1"] = 15, ["z"] = 16, ["name"] = "unbreakable_map_barrier:barrier"}, {["x"] = 6, ["y"] = 80, ["param1"] = 15, ["z"] = 17, ["name"] = "unbreakable_map_barrier:barrier"}, {["x"] = 6, ["y"] = 80, ["param1"] = 15, ["z"] = 18, ["name"] = "unbreakable_map_barrier:barrier"}, {["x"] = 6, ["y"] = 80, ["param1"] = 15, ["z"] = 19, ["name"] = "unbreakable_map_barrier:barrier"}, {["x"] = 6, ["y"] = 80, ["param1"] = 15, ["z"] = 20, ["name"] = "unbreakable_map_barrier:barrier"}, {["x"] = 6, ["y"] = 80, ["param1"] = 15, ["z"] = 21, ["name"] = "unbreakable_map_barrier:barrier"}, {["x"] = 6, ["y"] = 80, ["param1"] = 15, ["z"] = 22, ["name"] = "unbreakable_map_barrier:barrier"}, {["x"] = 6, ["y"] = 80, ["param1"] = 15, ["z"] = 23, ["name"] = "unbreakable_map_barrier:barrier"}, {["x"] = 6, ["y"] = 80, ["param1"] = 15, ["z"] = 24, ["name"] = "unbreakable_map_barrier:barrier"}, {["x"] = 6, ["y"] = 80, ["param1"] = 15, ["z"] = 25, ["name"] = "unbreakable_map_barrier:barrier"}, {["x"] = 6, ["y"] = 80, ["param1"] = 15, ["z"] = 26, ["name"] = "unbreakable_map_barrier:barrier"}, {["x"] = 6, ["y"] = 80, ["param1"] = 15, ["z"] = 27, ["name"] = "unbreakable_map_barrier:barrier"}, {["x"] = 6, ["y"] = 80, ["param1"] = 15, ["z"] = 28, ["name"] = "unbreakable_map_barrier:barrier"}, {["x"] = 6, ["y"] = 80, ["param1"] = 15, ["z"] = 29, ["name"] = "unbreakable_map_barrier:barrier"}, {["x"] = 6, ["y"] = 80, ["param1"] = 15, ["z"] = 30, ["name"] = "unbreakable_map_barrier:barrier"}, {["x"] = 6, ["y"] = 80, ["param1"] = 15, ["z"] = 31, ["name"] = "unbreakable_map_barrier:barrier"}, {["x"] = 6, ["y"] = 80, ["param1"] = 15, ["z"] = 32, ["name"] = "unbreakable_map_barrier:barrier"}, {["x"] = 6, ["y"] = 80, ["param1"] = 15, ["z"] = 33, ["name"] = "unbreakable_map_barrier:barrier"}, {["x"] = 6, ["y"] = 80, ["param1"] = 15, ["z"] = 34, ["name"] = "unbreakable_map_barrier:barrier"}, {["x"] = 6, ["y"] = 80, ["param1"] = 15, ["z"] = 35, ["name"] = "unbreakable_map_barrier:barrier"}, {["x"] = 6, ["y"] = 80, ["param1"] = 15, ["z"] = 36, ["name"] = "unbreakable_map_barrier:barrier"}, {["x"] = 6, ["y"] = 80, ["param1"] = 15, ["z"] = 37, ["name"] = "unbreakable_map_barrier:barrier"}, {["x"] = 6, ["y"] = 80, ["param1"] = 15, ["z"] = 38, ["name"] = "unbreakable_map_barrier:barrier"}, {["x"] = 6, ["y"] = 80, ["param1"] = 15, ["z"] = 39, ["name"] = "unbreakable_map_barrier:barrier"}, {["x"] = 6, ["y"] = 80, ["param1"] = 15, ["z"] = 40, ["name"] = "unbreakable_map_barrier:barrier"}, {["x"] = 6, ["y"] = 80, ["param1"] = 15, ["z"] = 41, ["name"] = "unbreakable_map_barrier:barrier"}, {["x"] = 6, ["y"] = 80, ["param1"] = 15, ["z"] = 42, ["name"] = "unbreakable_map_barrier:barrier"}, {["x"] = 6, ["y"] = 80, ["param1"] = 15, ["z"] = 43, ["name"] = "unbreakable_map_barrier:barrier"}, {["x"] = 6, ["y"] = 80, ["param1"] = 15, ["z"] = 44, ["name"] = "unbreakable_map_barrier:barrier"}, {["x"] = 6, ["y"] = 80, ["param1"] = 15, ["z"] = 45, ["name"] = "unbreakable_map_barrier:barrier"}, {["x"] = 6, ["y"] = 80, ["param1"] = 15, ["z"] = 46, ["name"] = "unbreakable_map_barrier:barrier"}, {["x"] = 6, ["y"] = 80, ["param1"] = 15, ["z"] = 47, ["name"] = "unbreakable_map_barrier:barrier"}, {["x"] = 6, ["y"] = 80, ["param1"] = 15, ["z"] = 48, ["name"] = "unbreakable_map_barrier:barrier"}, {["x"] = 6, ["y"] = 80, ["param1"] = 15, ["z"] = 49, ["name"] = "unbreakable_map_barrier:barrier"}, {["x"] = 6, ["y"] = 80, ["param1"] = 15, ["z"] = 50, ["name"] = "unbreakable_map_barrier:barrier"}, {["x"] = 6, ["y"] = 80, ["param1"] = 15, ["z"] = 51, ["name"] = "unbreakable_map_barrier:barrier"}, {["x"] = 6, ["y"] = 80, ["param1"] = 15, ["z"] = 52, ["name"] = "unbreakable_map_barrier:barrier"}, {["x"] = 6, ["y"] = 80, ["param1"] = 15, ["z"] = 53, ["name"] = "unbreakable_map_barrier:barrier"}, {["x"] = 6, ["y"] = 80, ["param1"] = 15, ["z"] = 54, ["name"] = "unbreakable_map_barrier:barrier"}, {["x"] = 6, ["y"] = 80, ["param1"] = 15, ["z"] = 55, ["name"] = "unbreakable_map_barrier:barrier"}, {["x"] = 6, ["y"] = 80, ["param1"] = 15, ["z"] = 56, ["name"] = "unbreakable_map_barrier:barrier"}, {["x"] = 6, ["y"] = 80, ["param1"] = 15, ["z"] = 57, ["name"] = "unbreakable_map_barrier:barrier"}, {["x"] = 6, ["y"] = 80, ["param1"] = 15, ["z"] = 58, ["name"] = "unbreakable_map_barrier:barrier"}, {["x"] = 6, ["y"] = 80, ["param1"] = 15, ["z"] = 59, ["name"] = "unbreakable_map_barrier:barrier"}, {["x"] = 6, ["y"] = 80, ["param1"] = 15, ["z"] = 60, ["name"] = "unbreakable_map_barrier:barrier"}, {["x"] = 6, ["y"] = 80, ["param1"] = 15, ["z"] = 61, ["name"] = "unbreakable_map_barrier:barrier"}, {["x"] = 6, ["y"] = 80, ["param1"] = 15, ["z"] = 62, ["name"] = "unbreakable_map_barrier:barrier"}, {["x"] = 6, ["y"] = 80, ["param1"] = 15, ["z"] = 63, ["name"] = "unbreakable_map_barrier:barrier"}, {["x"] = 6, ["y"] = 80, ["param1"] = 15, ["z"] = 64, ["name"] = "unbreakable_map_barrier:barrier"}, {["x"] = 6, ["y"] = 80, ["param1"] = 15, ["z"] = 65, ["name"] = "unbreakable_map_barrier:barrier"}, {["x"] = 6, ["y"] = 80, ["param1"] = 15, ["z"] = 66, ["name"] = "unbreakable_map_barrier:barrier"}, {["x"] = 6, ["y"] = 80, ["param1"] = 15, ["z"] = 67, ["name"] = "unbreakable_map_barrier:barrier"}, {["x"] = 6, ["y"] = 80, ["param1"] = 15, ["z"] = 68, ["name"] = "unbreakable_map_barrier:barrier"}, {["x"] = 6, ["y"] = 80, ["param1"] = 15, ["z"] = 69, ["name"] = "unbreakable_map_barrier:barrier"}, {["x"] = 6, ["y"] = 80, ["param1"] = 15, ["z"] = 70, ["name"] = "unbreakable_map_barrier:barrier"}, {["x"] = 6, ["y"] = 80, ["param1"] = 15, ["z"] = 71, ["name"] = "unbreakable_map_barrier:barrier"}, {["x"] = 6, ["y"] = 80, ["param1"] = 15, ["z"] = 72, ["name"] = "unbreakable_map_barrier:barrier"}, {["x"] = 6, ["y"] = 80, ["param1"] = 15, ["z"] = 73, ["name"] = "unbreakable_map_barrier:barrier"}, {["x"] = 6, ["y"] = 80, ["param1"] = 15, ["z"] = 74, ["name"] = "unbreakable_map_barrier:barrier"}, {["x"] = 6, ["y"] = 80, ["param1"] = 15, ["z"] = 75, ["name"] = "unbreakable_map_barrier:barrier"}, {["x"] = 6, ["y"] = 80, ["param1"] = 15, ["z"] = 76, ["name"] = "unbreakable_map_barrier:barrier"}, {["x"] = 6, ["y"] = 80, ["param1"] = 15, ["z"] = 77, ["name"] = "unbreakable_map_barrier:barrier"}, {["x"] = 6, ["y"] = 80, ["param1"] = 15, ["z"] = 78, ["name"] = "unbreakable_map_barrier:barrier"}, {["x"] = 6, ["y"] = 80, ["param1"] = 15, ["z"] = 79, ["name"] = "unbreakable_map_barrier:barrier"}, {["x"] = 6, ["y"] = 80, ["param1"] = 15, ["z"] = 80, ["name"] = "unbreakable_map_barrier:barrier"}, {["x"] = 7, ["y"] = 0, ["param1"] = 15, ["z"] = 18, ["name"] = "default:tinblock"}, {["x"] = 7, ["y"] = 0, ["param1"] = 15, ["z"] = 19, ["name"] = "default:tinblock"}, {["x"] = 7, ["y"] = 0, ["param1"] = 15, ["z"] = 20, ["name"] = "default:tinblock"}, {["x"] = 7, ["y"] = 0, ["param1"] = 15, ["z"] = 21, ["name"] = "default:tinblock"}, {["x"] = 7, ["y"] = 1, ["param1"] = 15, ["z"] = 18, ["name"] = "default:tinblock"}, {["x"] = 7, ["y"] = 1, ["param1"] = 15, ["z"] = 19, ["name"] = "default:tinblock"}, {["x"] = 7, ["y"] = 1, ["param1"] = 15, ["z"] = 20, ["name"] = "default:tinblock"}, {["x"] = 7, ["y"] = 1, ["param1"] = 15, ["z"] = 21, ["name"] = "default:tinblock"}, {["x"] = 7, ["y"] = 2, ["param1"] = 15, ["z"] = 18, ["name"] = "default:tinblock"}, {["x"] = 7, ["y"] = 2, ["param1"] = 15, ["z"] = 19, ["name"] = "default:tinblock"}, {["x"] = 7, ["y"] = 2, ["param1"] = 15, ["z"] = 20, ["name"] = "default:tinblock"}, {["x"] = 7, ["y"] = 2, ["param1"] = 15, ["z"] = 21, ["name"] = "default:tinblock"}, {["x"] = 7, ["y"] = 3, ["param1"] = 15, ["z"] = 18, ["name"] = "default:tinblock"}, {["x"] = 7, ["y"] = 3, ["param1"] = 15, ["z"] = 19, ["name"] = "default:tinblock"}, {["x"] = 7, ["y"] = 3, ["param1"] = 15, ["z"] = 20, ["name"] = "default:tinblock"}, {["x"] = 7, ["y"] = 3, ["param1"] = 15, ["z"] = 21, ["name"] = "default:tinblock"}, {["x"] = 7, ["y"] = 4, ["param1"] = 15, ["z"] = 18, ["name"] = "default:tinblock"}, {["x"] = 7, ["y"] = 4, ["param1"] = 15, ["z"] = 19, ["name"] = "default:tinblock"}, {["x"] = 7, ["y"] = 4, ["param1"] = 15, ["z"] = 20, ["name"] = "default:tinblock"}, {["x"] = 7, ["y"] = 4, ["param1"] = 15, ["z"] = 21, ["name"] = "default:tinblock"}, {["x"] = 7, ["y"] = 5, ["param1"] = 15, ["z"] = 18, ["name"] = "default:tinblock"}, {["x"] = 7, ["y"] = 5, ["param1"] = 15, ["z"] = 19, ["name"] = "default:tinblock"}, {["x"] = 7, ["y"] = 5, ["param1"] = 15, ["z"] = 20, ["name"] = "default:tinblock"}, {["x"] = 7, ["y"] = 5, ["param1"] = 15, ["z"] = 21, ["name"] = "default:tinblock"}, {["x"] = 7, ["y"] = 6, ["param1"] = 15, ["z"] = 18, ["name"] = "default:tinblock"}, {["x"] = 7, ["y"] = 6, ["param1"] = 15, ["z"] = 19, ["name"] = "default:tinblock"}, {["x"] = 7, ["y"] = 6, ["param1"] = 15, ["z"] = 20, ["name"] = "default:tinblock"}, {["x"] = 7, ["y"] = 6, ["param1"] = 15, ["z"] = 21, ["name"] = "default:tinblock"}, {["x"] = 7, ["y"] = 7, ["param1"] = 15, ["z"] = 18, ["name"] = "default:tinblock"}, {["x"] = 7, ["y"] = 7, ["param1"] = 15, ["z"] = 19, ["name"] = "default:tinblock"}, {["x"] = 7, ["y"] = 7, ["param1"] = 15, ["z"] = 20, ["name"] = "default:tinblock"}, {["x"] = 7, ["y"] = 7, ["param1"] = 15, ["z"] = 21, ["name"] = "default:tinblock"}, {["x"] = 7, ["y"] = 8, ["param1"] = 15, ["z"] = 18, ["name"] = "default:tinblock"}, {["x"] = 7, ["y"] = 8, ["param1"] = 15, ["z"] = 19, ["name"] = "default:tinblock"}, {["x"] = 7, ["y"] = 8, ["param1"] = 15, ["z"] = 20, ["name"] = "default:tinblock"}, {["x"] = 7, ["y"] = 8, ["param1"] = 15, ["z"] = 21, ["name"] = "default:tinblock"}, {["x"] = 7, ["y"] = 9, ["param1"] = 15, ["z"] = 18, ["name"] = "default:tinblock"}, {["x"] = 7, ["y"] = 10, ["param1"] = 15, ["z"] = 18, ["name"] = "default:tinblock"}, {["x"] = 7, ["y"] = 11, ["param1"] = 15, ["z"] = 18, ["name"] = "default:tinblock"}, {["x"] = 7, ["y"] = 80, ["param1"] = 15, ["z"] = 0, ["name"] = "unbreakable_map_barrier:barrier"}, {["x"] = 7, ["y"] = 80, ["param1"] = 15, ["z"] = 1, ["name"] = "unbreakable_map_barrier:barrier"}, {["x"] = 7, ["y"] = 80, ["param1"] = 15, ["z"] = 2, ["name"] = "unbreakable_map_barrier:barrier"}, {["x"] = 7, ["y"] = 80, ["param1"] = 15, ["z"] = 3, ["name"] = "unbreakable_map_barrier:barrier"}, {["x"] = 7, ["y"] = 80, ["param1"] = 15, ["z"] = 4, ["name"] = "unbreakable_map_barrier:barrier"}, {["x"] = 7, ["y"] = 80, ["param1"] = 15, ["z"] = 5, ["name"] = "unbreakable_map_barrier:barrier"}, {["x"] = 7, ["y"] = 80, ["param1"] = 15, ["z"] = 6, ["name"] = "unbreakable_map_barrier:barrier"}, {["x"] = 7, ["y"] = 80, ["param1"] = 15, ["z"] = 7, ["name"] = "unbreakable_map_barrier:barrier"}, {["x"] = 7, ["y"] = 80, ["param1"] = 15, ["z"] = 8, ["name"] = "unbreakable_map_barrier:barrier"}, {["x"] = 7, ["y"] = 80, ["param1"] = 15, ["z"] = 9, ["name"] = "unbreakable_map_barrier:barrier"}, {["x"] = 7, ["y"] = 80, ["param1"] = 15, ["z"] = 10, ["name"] = "unbreakable_map_barrier:barrier"}, {["x"] = 7, ["y"] = 80, ["param1"] = 15, ["z"] = 11, ["name"] = "unbreakable_map_barrier:barrier"}, {["x"] = 7, ["y"] = 80, ["param1"] = 15, ["z"] = 12, ["name"] = "unbreakable_map_barrier:barrier"}, {["x"] = 7, ["y"] = 80, ["param1"] = 15, ["z"] = 13, ["name"] = "unbreakable_map_barrier:barrier"}, {["x"] = 7, ["y"] = 80, ["param1"] = 15, ["z"] = 14, ["name"] = "unbreakable_map_barrier:barrier"}, {["x"] = 7, ["y"] = 80, ["param1"] = 15, ["z"] = 15, ["name"] = "unbreakable_map_barrier:barrier"}, {["x"] = 7, ["y"] = 80, ["param1"] = 15, ["z"] = 16, ["name"] = "unbreakable_map_barrier:barrier"}, {["x"] = 7, ["y"] = 80, ["param1"] = 15, ["z"] = 17, ["name"] = "unbreakable_map_barrier:barrier"}, {["x"] = 7, ["y"] = 80, ["param1"] = 15, ["z"] = 18, ["name"] = "unbreakable_map_barrier:barrier"}, {["x"] = 7, ["y"] = 80, ["param1"] = 15, ["z"] = 19, ["name"] = "unbreakable_map_barrier:barrier"}, {["x"] = 7, ["y"] = 80, ["param1"] = 15, ["z"] = 20, ["name"] = "unbreakable_map_barrier:barrier"}, {["x"] = 7, ["y"] = 80, ["param1"] = 15, ["z"] = 21, ["name"] = "unbreakable_map_barrier:barrier"}, {["x"] = 7, ["y"] = 80, ["param1"] = 15, ["z"] = 22, ["name"] = "unbreakable_map_barrier:barrier"}, {["x"] = 7, ["y"] = 80, ["param1"] = 15, ["z"] = 23, ["name"] = "unbreakable_map_barrier:barrier"}, {["x"] = 7, ["y"] = 80, ["param1"] = 15, ["z"] = 24, ["name"] = "unbreakable_map_barrier:barrier"}, {["x"] = 7, ["y"] = 80, ["param1"] = 15, ["z"] = 25, ["name"] = "unbreakable_map_barrier:barrier"}, {["x"] = 7, ["y"] = 80, ["param1"] = 15, ["z"] = 26, ["name"] = "unbreakable_map_barrier:barrier"}, {["x"] = 7, ["y"] = 80, ["param1"] = 15, ["z"] = 27, ["name"] = "unbreakable_map_barrier:barrier"}, {["x"] = 7, ["y"] = 80, ["param1"] = 15, ["z"] = 28, ["name"] = "unbreakable_map_barrier:barrier"}, {["x"] = 7, ["y"] = 80, ["param1"] = 15, ["z"] = 29, ["name"] = "unbreakable_map_barrier:barrier"}, {["x"] = 7, ["y"] = 80, ["param1"] = 15, ["z"] = 30, ["name"] = "unbreakable_map_barrier:barrier"}, {["x"] = 7, ["y"] = 80, ["param1"] = 15, ["z"] = 31, ["name"] = "unbreakable_map_barrier:barrier"}, {["x"] = 7, ["y"] = 80, ["param1"] = 15, ["z"] = 32, ["name"] = "unbreakable_map_barrier:barrier"}, {["x"] = 7, ["y"] = 80, ["param1"] = 15, ["z"] = 33, ["name"] = "unbreakable_map_barrier:barrier"}, {["x"] = 7, ["y"] = 80, ["param1"] = 15, ["z"] = 34, ["name"] = "unbreakable_map_barrier:barrier"}, {["x"] = 7, ["y"] = 80, ["param1"] = 15, ["z"] = 35, ["name"] = "unbreakable_map_barrier:barrier"}, {["x"] = 7, ["y"] = 80, ["param1"] = 15, ["z"] = 36, ["name"] = "unbreakable_map_barrier:barrier"}, {["x"] = 7, ["y"] = 80, ["param1"] = 15, ["z"] = 37, ["name"] = "unbreakable_map_barrier:barrier"}, {["x"] = 7, ["y"] = 80, ["param1"] = 15, ["z"] = 38, ["name"] = "unbreakable_map_barrier:barrier"}, {["x"] = 7, ["y"] = 80, ["param1"] = 15, ["z"] = 39, ["name"] = "unbreakable_map_barrier:barrier"}, {["x"] = 7, ["y"] = 80, ["param1"] = 15, ["z"] = 40, ["name"] = "unbreakable_map_barrier:barrier"}, {["x"] = 7, ["y"] = 80, ["param1"] = 15, ["z"] = 41, ["name"] = "unbreakable_map_barrier:barrier"}, {["x"] = 7, ["y"] = 80, ["param1"] = 15, ["z"] = 42, ["name"] = "unbreakable_map_barrier:barrier"}, {["x"] = 7, ["y"] = 80, ["param1"] = 15, ["z"] = 43, ["name"] = "unbreakable_map_barrier:barrier"}, {["x"] = 7, ["y"] = 80, ["param1"] = 15, ["z"] = 44, ["name"] = "unbreakable_map_barrier:barrier"}, {["x"] = 7, ["y"] = 80, ["param1"] = 15, ["z"] = 45, ["name"] = "unbreakable_map_barrier:barrier"}, {["x"] = 7, ["y"] = 80, ["param1"] = 15, ["z"] = 46, ["name"] = "unbreakable_map_barrier:barrier"}, {["x"] = 7, ["y"] = 80, ["param1"] = 15, ["z"] = 47, ["name"] = "unbreakable_map_barrier:barrier"}, {["x"] = 7, ["y"] = 80, ["param1"] = 15, ["z"] = 48, ["name"] = "unbreakable_map_barrier:barrier"}, {["x"] = 7, ["y"] = 80, ["param1"] = 15, ["z"] = 49, ["name"] = "unbreakable_map_barrier:barrier"}, {["x"] = 7, ["y"] = 80, ["param1"] = 15, ["z"] = 50, ["name"] = "unbreakable_map_barrier:barrier"}, {["x"] = 7, ["y"] = 80, ["param1"] = 15, ["z"] = 51, ["name"] = "unbreakable_map_barrier:barrier"}, {["x"] = 7, ["y"] = 80, ["param1"] = 15, ["z"] = 52, ["name"] = "unbreakable_map_barrier:barrier"}, {["x"] = 7, ["y"] = 80, ["param1"] = 15, ["z"] = 53, ["name"] = "unbreakable_map_barrier:barrier"}, {["x"] = 7, ["y"] = 80, ["param1"] = 15, ["z"] = 54, ["name"] = "unbreakable_map_barrier:barrier"}, {["x"] = 7, ["y"] = 80, ["param1"] = 15, ["z"] = 55, ["name"] = "unbreakable_map_barrier:barrier"}, {["x"] = 7, ["y"] = 80, ["param1"] = 15, ["z"] = 56, ["name"] = "unbreakable_map_barrier:barrier"}, {["x"] = 7, ["y"] = 80, ["param1"] = 15, ["z"] = 57, ["name"] = "unbreakable_map_barrier:barrier"}, {["x"] = 7, ["y"] = 80, ["param1"] = 15, ["z"] = 58, ["name"] = "unbreakable_map_barrier:barrier"}, {["x"] = 7, ["y"] = 80, ["param1"] = 15, ["z"] = 59, ["name"] = "unbreakable_map_barrier:barrier"}, {["x"] = 7, ["y"] = 80, ["param1"] = 15, ["z"] = 60, ["name"] = "unbreakable_map_barrier:barrier"}, {["x"] = 7, ["y"] = 80, ["param1"] = 15, ["z"] = 61, ["name"] = "unbreakable_map_barrier:barrier"}, {["x"] = 7, ["y"] = 80, ["param1"] = 15, ["z"] = 62, ["name"] = "unbreakable_map_barrier:barrier"}, {["x"] = 7, ["y"] = 80, ["param1"] = 15, ["z"] = 63, ["name"] = "unbreakable_map_barrier:barrier"}, {["x"] = 7, ["y"] = 80, ["param1"] = 15, ["z"] = 64, ["name"] = "unbreakable_map_barrier:barrier"}, {["x"] = 7, ["y"] = 80, ["param1"] = 15, ["z"] = 65, ["name"] = "unbreakable_map_barrier:barrier"}, {["x"] = 7, ["y"] = 80, ["param1"] = 15, ["z"] = 66, ["name"] = "unbreakable_map_barrier:barrier"}, {["x"] = 7, ["y"] = 80, ["param1"] = 15, ["z"] = 67, ["name"] = "unbreakable_map_barrier:barrier"}, {["x"] = 7, ["y"] = 80, ["param1"] = 15, ["z"] = 68, ["name"] = "unbreakable_map_barrier:barrier"}, {["x"] = 7, ["y"] = 80, ["param1"] = 15, ["z"] = 69, ["name"] = "unbreakable_map_barrier:barrier"}, {["x"] = 7, ["y"] = 80, ["param1"] = 15, ["z"] = 70, ["name"] = "unbreakable_map_barrier:barrier"}, {["x"] = 7, ["y"] = 80, ["param1"] = 15, ["z"] = 71, ["name"] = "unbreakable_map_barrier:barrier"}, {["x"] = 7, ["y"] = 80, ["param1"] = 15, ["z"] = 72, ["name"] = "unbreakable_map_barrier:barrier"}, {["x"] = 7, ["y"] = 80, ["param1"] = 15, ["z"] = 73, ["name"] = "unbreakable_map_barrier:barrier"}, {["x"] = 7, ["y"] = 80, ["param1"] = 15, ["z"] = 74, ["name"] = "unbreakable_map_barrier:barrier"}, {["x"] = 7, ["y"] = 80, ["param1"] = 15, ["z"] = 75, ["name"] = "unbreakable_map_barrier:barrier"}, {["x"] = 7, ["y"] = 80, ["param1"] = 15, ["z"] = 76, ["name"] = "unbreakable_map_barrier:barrier"}, {["x"] = 7, ["y"] = 80, ["param1"] = 15, ["z"] = 77, ["name"] = "unbreakable_map_barrier:barrier"}, {["x"] = 7, ["y"] = 80, ["param1"] = 15, ["z"] = 78, ["name"] = "unbreakable_map_barrier:barrier"}, {["x"] = 7, ["y"] = 80, ["param1"] = 15, ["z"] = 79, ["name"] = "unbreakable_map_barrier:barrier"}, {["x"] = 7, ["y"] = 80, ["param1"] = 15, ["z"] = 80, ["name"] = "unbreakable_map_barrier:barrier"}, {["x"] = 8, ["y"] = 0, ["param1"] = 15, ["z"] = 15, ["name"] = "default:tinblock"}, {["x"] = 8, ["y"] = 0, ["param1"] = 15, ["z"] = 16, ["name"] = "default:tinblock"}, {["x"] = 8, ["y"] = 0, ["param1"] = 15, ["z"] = 17, ["name"] = "default:tinblock"}, {["x"] = 8, ["y"] = 0, ["param1"] = 15, ["z"] = 18, ["name"] = "default:tinblock"}, {["x"] = 8, ["y"] = 0, ["param1"] = 15, ["z"] = 19, ["name"] = "default:tinblock"}, {["x"] = 8, ["y"] = 0, ["param1"] = 15, ["z"] = 20, ["name"] = "default:tinblock"}, {["x"] = 8, ["y"] = 0, ["param1"] = 15, ["z"] = 21, ["name"] = "default:tinblock"}, {["x"] = 8, ["y"] = 0, ["param1"] = 15, ["z"] = 22, ["name"] = "default:tinblock"}, {["x"] = 8, ["y"] = 0, ["param1"] = 15, ["z"] = 23, ["name"] = "default:tinblock"}, {["x"] = 8, ["y"] = 1, ["param1"] = 15, ["z"] = 15, ["name"] = "default:tinblock"}, {["x"] = 8, ["y"] = 1, ["param1"] = 15, ["z"] = 16, ["name"] = "default:tinblock"}, {["x"] = 8, ["y"] = 1, ["param1"] = 15, ["z"] = 17, ["name"] = "default:tinblock"}, {["x"] = 8, ["y"] = 1, ["param1"] = 15, ["z"] = 18, ["name"] = "default:tinblock"}, {["x"] = 8, ["y"] = 1, ["param1"] = 15, ["z"] = 19, ["name"] = "default:tinblock"}, {["x"] = 8, ["y"] = 1, ["param1"] = 15, ["z"] = 20, ["name"] = "default:tinblock"}, {["x"] = 8, ["y"] = 1, ["param1"] = 15, ["z"] = 21, ["name"] = "default:tinblock"}, {["x"] = 8, ["y"] = 1, ["param1"] = 15, ["z"] = 22, ["name"] = "default:tinblock"}, {["x"] = 8, ["y"] = 1, ["param1"] = 15, ["z"] = 23, ["name"] = "default:tinblock"}, {["x"] = 8, ["y"] = 2, ["param1"] = 15, ["z"] = 15, ["name"] = "default:tinblock"}, {["x"] = 8, ["y"] = 2, ["param1"] = 15, ["z"] = 16, ["name"] = "default:tinblock"}, {["x"] = 8, ["y"] = 2, ["param1"] = 15, ["z"] = 17, ["name"] = "default:tinblock"}, {["x"] = 8, ["y"] = 2, ["param1"] = 15, ["z"] = 18, ["name"] = "default:tinblock"}, {["x"] = 8, ["y"] = 2, ["param1"] = 15, ["z"] = 19, ["name"] = "default:tinblock"}, {["x"] = 8, ["y"] = 2, ["param1"] = 15, ["z"] = 20, ["name"] = "default:tinblock"}, {["x"] = 8, ["y"] = 2, ["param1"] = 15, ["z"] = 21, ["name"] = "default:tinblock"}, {["x"] = 8, ["y"] = 2, ["param1"] = 15, ["z"] = 22, ["name"] = "default:tinblock"}, {["x"] = 8, ["y"] = 2, ["param1"] = 15, ["z"] = 23, ["name"] = "default:tinblock"}, {["x"] = 8, ["y"] = 3, ["param1"] = 15, ["z"] = 15, ["name"] = "default:tinblock"}, {["x"] = 8, ["y"] = 3, ["param1"] = 15, ["z"] = 16, ["name"] = "default:tinblock"}, {["x"] = 8, ["y"] = 3, ["param1"] = 15, ["z"] = 17, ["name"] = "default:tinblock"}, {["x"] = 8, ["y"] = 3, ["param1"] = 15, ["z"] = 18, ["name"] = "default:tinblock"}, {["x"] = 8, ["y"] = 3, ["param1"] = 15, ["z"] = 19, ["name"] = "default:tinblock"}, {["x"] = 8, ["y"] = 3, ["param1"] = 15, ["z"] = 20, ["name"] = "default:tinblock"}, {["x"] = 8, ["y"] = 3, ["param1"] = 15, ["z"] = 21, ["name"] = "default:tinblock"}, {["x"] = 8, ["y"] = 3, ["param1"] = 15, ["z"] = 22, ["name"] = "default:tinblock"}, {["x"] = 8, ["y"] = 3, ["param1"] = 15, ["z"] = 23, ["name"] = "default:tinblock"}, {["x"] = 8, ["y"] = 4, ["param1"] = 15, ["z"] = 15, ["name"] = "default:tinblock"}, {["x"] = 8, ["y"] = 4, ["param1"] = 15, ["z"] = 16, ["name"] = "default:tinblock"}, {["x"] = 8, ["y"] = 4, ["param1"] = 15, ["z"] = 17, ["name"] = "default:tinblock"}, {["x"] = 8, ["y"] = 4, ["param1"] = 15, ["z"] = 18, ["name"] = "default:tinblock"}, {["x"] = 8, ["y"] = 4, ["param1"] = 15, ["z"] = 19, ["name"] = "default:tinblock"}, {["x"] = 8, ["y"] = 4, ["param1"] = 15, ["z"] = 20, ["name"] = "default:tinblock"}, {["x"] = 8, ["y"] = 4, ["param1"] = 15, ["z"] = 21, ["name"] = "default:tinblock"}, {["x"] = 8, ["y"] = 4, ["param1"] = 15, ["z"] = 22, ["name"] = "default:tinblock"}, {["x"] = 8, ["y"] = 4, ["param1"] = 15, ["z"] = 23, ["name"] = "default:tinblock"}, {["x"] = 8, ["y"] = 5, ["param1"] = 15, ["z"] = 15, ["name"] = "default:tinblock"}, {["x"] = 8, ["y"] = 5, ["param1"] = 15, ["z"] = 16, ["name"] = "default:tinblock"}, {["x"] = 8, ["y"] = 5, ["param1"] = 15, ["z"] = 17, ["name"] = "default:tinblock"}, {["x"] = 8, ["y"] = 5, ["param1"] = 15, ["z"] = 18, ["name"] = "default:tinblock"}, {["x"] = 8, ["y"] = 5, ["param1"] = 15, ["z"] = 19, ["name"] = "default:tinblock"}, {["x"] = 8, ["y"] = 5, ["param1"] = 15, ["z"] = 20, ["name"] = "default:tinblock"}, {["x"] = 8, ["y"] = 5, ["param1"] = 15, ["z"] = 21, ["name"] = "default:tinblock"}, {["x"] = 8, ["y"] = 5, ["param1"] = 15, ["z"] = 22, ["name"] = "default:tinblock"}, {["x"] = 8, ["y"] = 5, ["param1"] = 15, ["z"] = 23, ["name"] = "default:tinblock"}, {["x"] = 8, ["y"] = 6, ["param1"] = 15, ["z"] = 15, ["name"] = "default:tinblock"}, {["x"] = 8, ["y"] = 6, ["param1"] = 15, ["z"] = 16, ["name"] = "default:tinblock"}, {["x"] = 8, ["y"] = 6, ["param1"] = 15, ["z"] = 17, ["name"] = "default:tinblock"}, {["x"] = 8, ["y"] = 6, ["param1"] = 15, ["z"] = 18, ["name"] = "default:tinblock"}, {["x"] = 8, ["y"] = 6, ["param1"] = 15, ["z"] = 19, ["name"] = "default:tinblock"}, {["x"] = 8, ["y"] = 6, ["param1"] = 15, ["z"] = 20, ["name"] = "default:tinblock"}, {["x"] = 8, ["y"] = 6, ["param1"] = 15, ["z"] = 21, ["name"] = "default:tinblock"}, {["x"] = 8, ["y"] = 6, ["param1"] = 15, ["z"] = 22, ["name"] = "default:tinblock"}, {["x"] = 8, ["y"] = 6, ["param1"] = 15, ["z"] = 23, ["name"] = "default:tinblock"}, {["x"] = 8, ["y"] = 7, ["param1"] = 15, ["z"] = 15, ["name"] = "default:tinblock"}, {["x"] = 8, ["y"] = 7, ["param1"] = 15, ["z"] = 16, ["name"] = "default:tinblock"}, {["x"] = 8, ["y"] = 7, ["param1"] = 15, ["z"] = 17, ["name"] = "default:tinblock"}, {["x"] = 8, ["y"] = 7, ["param1"] = 15, ["z"] = 18, ["name"] = "default:tinblock"}, {["x"] = 8, ["y"] = 7, ["param1"] = 15, ["z"] = 19, ["name"] = "default:tinblock"}, {["x"] = 8, ["y"] = 7, ["param1"] = 15, ["z"] = 20, ["name"] = "default:tinblock"}, {["x"] = 8, ["y"] = 7, ["param1"] = 15, ["z"] = 21, ["name"] = "default:tinblock"}, {["x"] = 8, ["y"] = 7, ["param1"] = 15, ["z"] = 22, ["name"] = "default:tinblock"}, {["x"] = 8, ["y"] = 7, ["param1"] = 15, ["z"] = 23, ["name"] = "default:tinblock"}, {["x"] = 8, ["y"] = 8, ["param1"] = 15, ["z"] = 16, ["name"] = "default:tinblock"}, {["x"] = 8, ["y"] = 8, ["param1"] = 15, ["z"] = 17, ["name"] = "default:tinblock"}, {["x"] = 8, ["y"] = 8, ["param1"] = 15, ["z"] = 18, ["name"] = "default:tinblock"}, {["x"] = 8, ["y"] = 8, ["param1"] = 15, ["z"] = 19, ["name"] = "default:tinblock"}, {["x"] = 8, ["y"] = 8, ["param1"] = 15, ["z"] = 20, ["name"] = "default:tinblock"}, {["x"] = 8, ["y"] = 8, ["param1"] = 15, ["z"] = 21, ["name"] = "default:tinblock"}, {["x"] = 8, ["y"] = 8, ["param1"] = 15, ["z"] = 22, ["name"] = "default:tinblock"}, {["x"] = 8, ["y"] = 8, ["param1"] = 15, ["z"] = 23, ["name"] = "default:tinblock"}, {["x"] = 8, ["y"] = 9, ["param1"] = 15, ["z"] = 16, ["name"] = "default:tinblock"}, {["x"] = 8, ["y"] = 9, ["param1"] = 15, ["z"] = 20, ["name"] = "default:tinblock"}, {["x"] = 8, ["y"] = 10, ["param1"] = 15, ["z"] = 16, ["name"] = "default:tinblock"}, {["x"] = 8, ["y"] = 11, ["param1"] = 15, ["z"] = 16, ["name"] = "default:tinblock"}, {["x"] = 8, ["y"] = 80, ["param1"] = 15, ["z"] = 0, ["name"] = "unbreakable_map_barrier:barrier"}, {["x"] = 8, ["y"] = 80, ["param1"] = 15, ["z"] = 1, ["name"] = "unbreakable_map_barrier:barrier"}, {["x"] = 8, ["y"] = 80, ["param1"] = 15, ["z"] = 2, ["name"] = "unbreakable_map_barrier:barrier"}, {["x"] = 8, ["y"] = 80, ["param1"] = 15, ["z"] = 3, ["name"] = "unbreakable_map_barrier:barrier"}, {["x"] = 8, ["y"] = 80, ["param1"] = 15, ["z"] = 4, ["name"] = "unbreakable_map_barrier:barrier"}, {["x"] = 8, ["y"] = 80, ["param1"] = 15, ["z"] = 5, ["name"] = "unbreakable_map_barrier:barrier"}, {["x"] = 8, ["y"] = 80, ["param1"] = 15, ["z"] = 6, ["name"] = "unbreakable_map_barrier:barrier"}, {["x"] = 8, ["y"] = 80, ["param1"] = 15, ["z"] = 7, ["name"] = "unbreakable_map_barrier:barrier"}, {["x"] = 8, ["y"] = 80, ["param1"] = 15, ["z"] = 8, ["name"] = "unbreakable_map_barrier:barrier"}, {["x"] = 8, ["y"] = 80, ["param1"] = 15, ["z"] = 9, ["name"] = "unbreakable_map_barrier:barrier"}, {["x"] = 8, ["y"] = 80, ["param1"] = 15, ["z"] = 10, ["name"] = "unbreakable_map_barrier:barrier"}, {["x"] = 8, ["y"] = 80, ["param1"] = 15, ["z"] = 11, ["name"] = "unbreakable_map_barrier:barrier"}, {["x"] = 8, ["y"] = 80, ["param1"] = 15, ["z"] = 12, ["name"] = "unbreakable_map_barrier:barrier"}, {["x"] = 8, ["y"] = 80, ["param1"] = 15, ["z"] = 13, ["name"] = "unbreakable_map_barrier:barrier"}, {["x"] = 8, ["y"] = 80, ["param1"] = 15, ["z"] = 14, ["name"] = "unbreakable_map_barrier:barrier"}, {["x"] = 8, ["y"] = 80, ["param1"] = 15, ["z"] = 15, ["name"] = "unbreakable_map_barrier:barrier"}, {["x"] = 8, ["y"] = 80, ["param1"] = 15, ["z"] = 16, ["name"] = "unbreakable_map_barrier:barrier"}, {["x"] = 8, ["y"] = 80, ["param1"] = 15, ["z"] = 17, ["name"] = "unbreakable_map_barrier:barrier"}, {["x"] = 8, ["y"] = 80, ["param1"] = 15, ["z"] = 18, ["name"] = "unbreakable_map_barrier:barrier"}, {["x"] = 8, ["y"] = 80, ["param1"] = 15, ["z"] = 19, ["name"] = "unbreakable_map_barrier:barrier"}, {["x"] = 8, ["y"] = 80, ["param1"] = 15, ["z"] = 20, ["name"] = "unbreakable_map_barrier:barrier"}, {["x"] = 8, ["y"] = 80, ["param1"] = 15, ["z"] = 21, ["name"] = "unbreakable_map_barrier:barrier"}, {["x"] = 8, ["y"] = 80, ["param1"] = 15, ["z"] = 22, ["name"] = "unbreakable_map_barrier:barrier"}, {["x"] = 8, ["y"] = 80, ["param1"] = 15, ["z"] = 23, ["name"] = "unbreakable_map_barrier:barrier"}, {["x"] = 8, ["y"] = 80, ["param1"] = 15, ["z"] = 24, ["name"] = "unbreakable_map_barrier:barrier"}, {["x"] = 8, ["y"] = 80, ["param1"] = 15, ["z"] = 25, ["name"] = "unbreakable_map_barrier:barrier"}, {["x"] = 8, ["y"] = 80, ["param1"] = 15, ["z"] = 26, ["name"] = "unbreakable_map_barrier:barrier"}, {["x"] = 8, ["y"] = 80, ["param1"] = 15, ["z"] = 27, ["name"] = "unbreakable_map_barrier:barrier"}, {["x"] = 8, ["y"] = 80, ["param1"] = 15, ["z"] = 28, ["name"] = "unbreakable_map_barrier:barrier"}, {["x"] = 8, ["y"] = 80, ["param1"] = 15, ["z"] = 29, ["name"] = "unbreakable_map_barrier:barrier"}, {["x"] = 8, ["y"] = 80, ["param1"] = 15, ["z"] = 30, ["name"] = "unbreakable_map_barrier:barrier"}, {["x"] = 8, ["y"] = 80, ["param1"] = 15, ["z"] = 31, ["name"] = "unbreakable_map_barrier:barrier"}, {["x"] = 8, ["y"] = 80, ["param1"] = 15, ["z"] = 32, ["name"] = "unbreakable_map_barrier:barrier"}, {["x"] = 8, ["y"] = 80, ["param1"] = 15, ["z"] = 33, ["name"] = "unbreakable_map_barrier:barrier"}, {["x"] = 8, ["y"] = 80, ["param1"] = 15, ["z"] = 34, ["name"] = "unbreakable_map_barrier:barrier"}, {["x"] = 8, ["y"] = 80, ["param1"] = 15, ["z"] = 35, ["name"] = "unbreakable_map_barrier:barrier"}, {["x"] = 8, ["y"] = 80, ["param1"] = 15, ["z"] = 36, ["name"] = "unbreakable_map_barrier:barrier"}, {["x"] = 8, ["y"] = 80, ["param1"] = 15, ["z"] = 37, ["name"] = "unbreakable_map_barrier:barrier"}, {["x"] = 8, ["y"] = 80, ["param1"] = 15, ["z"] = 38, ["name"] = "unbreakable_map_barrier:barrier"}, {["x"] = 8, ["y"] = 80, ["param1"] = 15, ["z"] = 39, ["name"] = "unbreakable_map_barrier:barrier"}, {["x"] = 8, ["y"] = 80, ["param1"] = 15, ["z"] = 40, ["name"] = "unbreakable_map_barrier:barrier"}, {["x"] = 8, ["y"] = 80, ["param1"] = 15, ["z"] = 41, ["name"] = "unbreakable_map_barrier:barrier"}, {["x"] = 8, ["y"] = 80, ["param1"] = 15, ["z"] = 42, ["name"] = "unbreakable_map_barrier:barrier"}, {["x"] = 8, ["y"] = 80, ["param1"] = 15, ["z"] = 43, ["name"] = "unbreakable_map_barrier:barrier"}, {["x"] = 8, ["y"] = 80, ["param1"] = 15, ["z"] = 44, ["name"] = "unbreakable_map_barrier:barrier"}, {["x"] = 8, ["y"] = 80, ["param1"] = 15, ["z"] = 45, ["name"] = "unbreakable_map_barrier:barrier"}, {["x"] = 8, ["y"] = 80, ["param1"] = 15, ["z"] = 46, ["name"] = "unbreakable_map_barrier:barrier"}, {["x"] = 8, ["y"] = 80, ["param1"] = 15, ["z"] = 47, ["name"] = "unbreakable_map_barrier:barrier"}, {["x"] = 8, ["y"] = 80, ["param1"] = 15, ["z"] = 48, ["name"] = "unbreakable_map_barrier:barrier"}, {["x"] = 8, ["y"] = 80, ["param1"] = 15, ["z"] = 49, ["name"] = "unbreakable_map_barrier:barrier"}, {["x"] = 8, ["y"] = 80, ["param1"] = 15, ["z"] = 50, ["name"] = "unbreakable_map_barrier:barrier"}, {["x"] = 8, ["y"] = 80, ["param1"] = 15, ["z"] = 51, ["name"] = "unbreakable_map_barrier:barrier"}, {["x"] = 8, ["y"] = 80, ["param1"] = 15, ["z"] = 52, ["name"] = "unbreakable_map_barrier:barrier"}, {["x"] = 8, ["y"] = 80, ["param1"] = 15, ["z"] = 53, ["name"] = "unbreakable_map_barrier:barrier"}, {["x"] = 8, ["y"] = 80, ["param1"] = 15, ["z"] = 54, ["name"] = "unbreakable_map_barrier:barrier"}, {["x"] = 8, ["y"] = 80, ["param1"] = 15, ["z"] = 55, ["name"] = "unbreakable_map_barrier:barrier"}, {["x"] = 8, ["y"] = 80, ["param1"] = 15, ["z"] = 56, ["name"] = "unbreakable_map_barrier:barrier"}, {["x"] = 8, ["y"] = 80, ["param1"] = 15, ["z"] = 57, ["name"] = "unbreakable_map_barrier:barrier"}, {["x"] = 8, ["y"] = 80, ["param1"] = 15, ["z"] = 58, ["name"] = "unbreakable_map_barrier:barrier"}, {["x"] = 8, ["y"] = 80, ["param1"] = 15, ["z"] = 59, ["name"] = "unbreakable_map_barrier:barrier"}, {["x"] = 8, ["y"] = 80, ["param1"] = 15, ["z"] = 60, ["name"] = "unbreakable_map_barrier:barrier"}, {["x"] = 8, ["y"] = 80, ["param1"] = 15, ["z"] = 61, ["name"] = "unbreakable_map_barrier:barrier"}, {["x"] = 8, ["y"] = 80, ["param1"] = 15, ["z"] = 62, ["name"] = "unbreakable_map_barrier:barrier"}, {["x"] = 8, ["y"] = 80, ["param1"] = 15, ["z"] = 63, ["name"] = "unbreakable_map_barrier:barrier"}, {["x"] = 8, ["y"] = 80, ["param1"] = 15, ["z"] = 64, ["name"] = "unbreakable_map_barrier:barrier"}, {["x"] = 8, ["y"] = 80, ["param1"] = 15, ["z"] = 65, ["name"] = "unbreakable_map_barrier:barrier"}, {["x"] = 8, ["y"] = 80, ["param1"] = 15, ["z"] = 66, ["name"] = "unbreakable_map_barrier:barrier"}, {["x"] = 8, ["y"] = 80, ["param1"] = 15, ["z"] = 67, ["name"] = "unbreakable_map_barrier:barrier"}, {["x"] = 8, ["y"] = 80, ["param1"] = 15, ["z"] = 68, ["name"] = "unbreakable_map_barrier:barrier"}, {["x"] = 8, ["y"] = 80, ["param1"] = 15, ["z"] = 69, ["name"] = "unbreakable_map_barrier:barrier"}, {["x"] = 8, ["y"] = 80, ["param1"] = 15, ["z"] = 70, ["name"] = "unbreakable_map_barrier:barrier"}, {["x"] = 8, ["y"] = 80, ["param1"] = 15, ["z"] = 71, ["name"] = "unbreakable_map_barrier:barrier"}, {["x"] = 8, ["y"] = 80, ["param1"] = 15, ["z"] = 72, ["name"] = "unbreakable_map_barrier:barrier"}, {["x"] = 8, ["y"] = 80, ["param1"] = 15, ["z"] = 73, ["name"] = "unbreakable_map_barrier:barrier"}, {["x"] = 8, ["y"] = 80, ["param1"] = 15, ["z"] = 74, ["name"] = "unbreakable_map_barrier:barrier"}, {["x"] = 8, ["y"] = 80, ["param1"] = 15, ["z"] = 75, ["name"] = "unbreakable_map_barrier:barrier"}, {["x"] = 8, ["y"] = 80, ["param1"] = 15, ["z"] = 76, ["name"] = "unbreakable_map_barrier:barrier"}, {["x"] = 8, ["y"] = 80, ["param1"] = 15, ["z"] = 77, ["name"] = "unbreakable_map_barrier:barrier"}, {["x"] = 8, ["y"] = 80, ["param1"] = 15, ["z"] = 78, ["name"] = "unbreakable_map_barrier:barrier"}, {["x"] = 8, ["y"] = 80, ["param1"] = 15, ["z"] = 79, ["name"] = "unbreakable_map_barrier:barrier"}, {["x"] = 8, ["y"] = 80, ["param1"] = 15, ["z"] = 80, ["name"] = "unbreakable_map_barrier:barrier"}, {["x"] = 9, ["y"] = 0, ["param1"] = 15, ["z"] = 13, ["name"] = "default:tinblock"}, {["x"] = 9, ["y"] = 0, ["param1"] = 15, ["z"] = 14, ["name"] = "default:tinblock"}, {["x"] = 9, ["y"] = 0, ["param1"] = 15, ["z"] = 15, ["name"] = "default:tinblock"}, {["x"] = 9, ["y"] = 0, ["param1"] = 15, ["z"] = 16, ["name"] = "default:tinblock"}, {["x"] = 9, ["y"] = 0, ["param1"] = 15, ["z"] = 17, ["name"] = "default:tinblock"}, {["x"] = 9, ["y"] = 0, ["param1"] = 15, ["z"] = 18, ["name"] = "default:tinblock"}, {["x"] = 9, ["y"] = 0, ["param1"] = 15, ["z"] = 19, ["name"] = "default:tinblock"}, {["x"] = 9, ["y"] = 0, ["param1"] = 15, ["z"] = 20, ["name"] = "default:tinblock"}, {["x"] = 9, ["y"] = 0, ["param1"] = 15, ["z"] = 21, ["name"] = "default:tinblock"}, {["x"] = 9, ["y"] = 0, ["param1"] = 15, ["z"] = 22, ["name"] = "default:tinblock"}, {["x"] = 9, ["y"] = 0, ["param1"] = 15, ["z"] = 23, ["name"] = "default:tinblock"}, {["x"] = 9, ["y"] = 0, ["param1"] = 15, ["z"] = 24, ["name"] = "default:tinblock"}, {["x"] = 9, ["y"] = 0, ["param1"] = 15, ["z"] = 25, ["name"] = "default:tinblock"}, {["x"] = 9, ["y"] = 1, ["param1"] = 15, ["z"] = 13, ["name"] = "default:tinblock"}, {["x"] = 9, ["y"] = 1, ["param1"] = 15, ["z"] = 14, ["name"] = "default:tinblock"}, {["x"] = 9, ["y"] = 1, ["param1"] = 15, ["z"] = 15, ["name"] = "default:tinblock"}, {["x"] = 9, ["y"] = 1, ["param1"] = 15, ["z"] = 16, ["name"] = "default:tinblock"}, {["x"] = 9, ["y"] = 1, ["param1"] = 15, ["z"] = 17, ["name"] = "default:tinblock"}, {["x"] = 9, ["y"] = 1, ["param1"] = 15, ["z"] = 18, ["name"] = "default:tinblock"}, {["x"] = 9, ["y"] = 1, ["param1"] = 15, ["z"] = 19, ["name"] = "default:tinblock"}, {["x"] = 9, ["y"] = 1, ["param1"] = 15, ["z"] = 20, ["name"] = "default:tinblock"}, {["x"] = 9, ["y"] = 1, ["param1"] = 15, ["z"] = 21, ["name"] = "default:tinblock"}, {["x"] = 9, ["y"] = 1, ["param1"] = 15, ["z"] = 22, ["name"] = "default:tinblock"}, {["x"] = 9, ["y"] = 1, ["param1"] = 15, ["z"] = 23, ["name"] = "default:tinblock"}, {["x"] = 9, ["y"] = 1, ["param1"] = 15, ["z"] = 24, ["name"] = "default:tinblock"}, {["x"] = 9, ["y"] = 1, ["param1"] = 15, ["z"] = 25, ["name"] = "default:tinblock"}, {["x"] = 9, ["y"] = 2, ["param1"] = 15, ["z"] = 13, ["name"] = "default:tinblock"}, {["x"] = 9, ["y"] = 2, ["param1"] = 15, ["z"] = 14, ["name"] = "default:tinblock"}, {["x"] = 9, ["y"] = 2, ["param1"] = 15, ["z"] = 15, ["name"] = "default:tinblock"}, {["x"] = 9, ["y"] = 2, ["param1"] = 15, ["z"] = 16, ["name"] = "default:tinblock"}, {["x"] = 9, ["y"] = 2, ["param1"] = 15, ["z"] = 17, ["name"] = "default:tinblock"}, {["x"] = 9, ["y"] = 2, ["param1"] = 15, ["z"] = 18, ["name"] = "default:tinblock"}, {["x"] = 9, ["y"] = 2, ["param1"] = 15, ["z"] = 19, ["name"] = "default:tinblock"}, {["x"] = 9, ["y"] = 2, ["param1"] = 15, ["z"] = 20, ["name"] = "default:tinblock"}, {["x"] = 9, ["y"] = 2, ["param1"] = 15, ["z"] = 21, ["name"] = "default:tinblock"}, {["x"] = 9, ["y"] = 2, ["param1"] = 15, ["z"] = 22, ["name"] = "default:tinblock"}, {["x"] = 9, ["y"] = 2, ["param1"] = 15, ["z"] = 23, ["name"] = "default:tinblock"}, {["x"] = 9, ["y"] = 2, ["param1"] = 15, ["z"] = 24, ["name"] = "default:tinblock"}, {["x"] = 9, ["y"] = 2, ["param1"] = 15, ["z"] = 25, ["name"] = "default:tinblock"}, {["x"] = 9, ["y"] = 3, ["param1"] = 15, ["z"] = 13, ["name"] = "default:tinblock"}, {["x"] = 9, ["y"] = 3, ["param1"] = 15, ["z"] = 14, ["name"] = "default:tinblock"}, {["x"] = 9, ["y"] = 3, ["param1"] = 15, ["z"] = 15, ["name"] = "default:tinblock"}, {["x"] = 9, ["y"] = 3, ["param1"] = 15, ["z"] = 16, ["name"] = "default:tinblock"}, {["x"] = 9, ["y"] = 3, ["param1"] = 15, ["z"] = 17, ["name"] = "default:tinblock"}, {["x"] = 9, ["y"] = 3, ["param1"] = 15, ["z"] = 18, ["name"] = "default:tinblock"}, {["x"] = 9, ["y"] = 3, ["param1"] = 15, ["z"] = 19, ["name"] = "default:tinblock"}, {["x"] = 9, ["y"] = 3, ["param1"] = 15, ["z"] = 20, ["name"] = "default:tinblock"}, {["x"] = 9, ["y"] = 3, ["param1"] = 15, ["z"] = 21, ["name"] = "default:tinblock"}, {["x"] = 9, ["y"] = 3, ["param1"] = 15, ["z"] = 22, ["name"] = "default:tinblock"}, {["x"] = 9, ["y"] = 3, ["param1"] = 15, ["z"] = 23, ["name"] = "default:tinblock"}, {["x"] = 9, ["y"] = 3, ["param1"] = 15, ["z"] = 24, ["name"] = "default:tinblock"}, {["x"] = 9, ["y"] = 3, ["param1"] = 15, ["z"] = 25, ["name"] = "default:tinblock"}, {["x"] = 9, ["y"] = 4, ["param1"] = 15, ["z"] = 13, ["name"] = "default:tinblock"}, {["x"] = 9, ["y"] = 4, ["param1"] = 15, ["z"] = 14, ["name"] = "default:tinblock"}, {["x"] = 9, ["y"] = 4, ["param1"] = 15, ["z"] = 15, ["name"] = "default:tinblock"}, {["x"] = 9, ["y"] = 4, ["param1"] = 15, ["z"] = 16, ["name"] = "default:tinblock"}, {["x"] = 9, ["y"] = 4, ["param1"] = 15, ["z"] = 17, ["name"] = "default:tinblock"}, {["x"] = 9, ["y"] = 4, ["param1"] = 15, ["z"] = 18, ["name"] = "default:tinblock"}, {["x"] = 9, ["y"] = 4, ["param1"] = 15, ["z"] = 19, ["name"] = "default:tinblock"}, {["x"] = 9, ["y"] = 4, ["param1"] = 15, ["z"] = 20, ["name"] = "default:tinblock"}, {["x"] = 9, ["y"] = 4, ["param1"] = 15, ["z"] = 21, ["name"] = "default:tinblock"}, {["x"] = 9, ["y"] = 4, ["param1"] = 15, ["z"] = 22, ["name"] = "default:tinblock"}, {["x"] = 9, ["y"] = 4, ["param1"] = 15, ["z"] = 23, ["name"] = "default:tinblock"}, {["x"] = 9, ["y"] = 4, ["param1"] = 15, ["z"] = 24, ["name"] = "default:tinblock"}, {["x"] = 9, ["y"] = 4, ["param1"] = 15, ["z"] = 25, ["name"] = "default:tinblock"}, {["x"] = 9, ["y"] = 5, ["param1"] = 15, ["z"] = 14, ["name"] = "default:tinblock"}, {["x"] = 9, ["y"] = 5, ["param1"] = 15, ["z"] = 15, ["name"] = "default:tinblock"}, {["x"] = 9, ["y"] = 5, ["param1"] = 15, ["z"] = 16, ["name"] = "default:tinblock"}, {["x"] = 9, ["y"] = 5, ["param1"] = 15, ["z"] = 17, ["name"] = "default:tinblock"}, {["x"] = 9, ["y"] = 5, ["param1"] = 15, ["z"] = 18, ["name"] = "default:tinblock"}, {["x"] = 9, ["y"] = 5, ["param1"] = 15, ["z"] = 19, ["name"] = "default:tinblock"}, {["x"] = 9, ["y"] = 5, ["param1"] = 15, ["z"] = 20, ["name"] = "default:tinblock"}, {["x"] = 9, ["y"] = 5, ["param1"] = 15, ["z"] = 21, ["name"] = "default:tinblock"}, {["x"] = 9, ["y"] = 5, ["param1"] = 15, ["z"] = 22, ["name"] = "default:tinblock"}, {["x"] = 9, ["y"] = 5, ["param1"] = 15, ["z"] = 23, ["name"] = "default:tinblock"}, {["x"] = 9, ["y"] = 5, ["param1"] = 15, ["z"] = 24, ["name"] = "default:tinblock"}, {["x"] = 9, ["y"] = 5, ["param1"] = 15, ["z"] = 25, ["name"] = "default:tinblock"}, {["x"] = 9, ["y"] = 6, ["param1"] = 15, ["z"] = 14, ["name"] = "default:tinblock"}, {["x"] = 9, ["y"] = 6, ["param1"] = 15, ["z"] = 15, ["name"] = "default:tinblock"}, {["x"] = 9, ["y"] = 6, ["param1"] = 15, ["z"] = 16, ["name"] = "default:tinblock"}, {["x"] = 9, ["y"] = 6, ["param1"] = 15, ["z"] = 17, ["name"] = "default:tinblock"}, {["x"] = 9, ["y"] = 6, ["param1"] = 15, ["z"] = 18, ["name"] = "default:tinblock"}, {["x"] = 9, ["y"] = 6, ["param1"] = 15, ["z"] = 19, ["name"] = "default:tinblock"}, {["x"] = 9, ["y"] = 6, ["param1"] = 15, ["z"] = 20, ["name"] = "default:tinblock"}, {["x"] = 9, ["y"] = 6, ["param1"] = 15, ["z"] = 21, ["name"] = "default:tinblock"}, {["x"] = 9, ["y"] = 6, ["param1"] = 15, ["z"] = 22, ["name"] = "default:tinblock"}, {["x"] = 9, ["y"] = 6, ["param1"] = 15, ["z"] = 23, ["name"] = "default:tinblock"}, {["x"] = 9, ["y"] = 6, ["param1"] = 15, ["z"] = 24, ["name"] = "default:tinblock"}, {["x"] = 9, ["y"] = 6, ["param1"] = 15, ["z"] = 25, ["name"] = "default:tinblock"}, {["x"] = 9, ["y"] = 7, ["param1"] = 15, ["z"] = 14, ["name"] = "default:tinblock"}, {["x"] = 9, ["y"] = 7, ["param1"] = 15, ["z"] = 15, ["name"] = "default:tinblock"}, {["x"] = 9, ["y"] = 7, ["param1"] = 15, ["z"] = 16, ["name"] = "default:tinblock"}, {["x"] = 9, ["y"] = 7, ["param1"] = 15, ["z"] = 17, ["name"] = "default:tinblock"}, {["x"] = 9, ["y"] = 7, ["param1"] = 15, ["z"] = 18, ["name"] = "default:tinblock"}, {["x"] = 9, ["y"] = 7, ["param1"] = 15, ["z"] = 19, ["name"] = "default:tinblock"}, {["x"] = 9, ["y"] = 7, ["param1"] = 15, ["z"] = 20, ["name"] = "default:tinblock"}, {["x"] = 9, ["y"] = 7, ["param1"] = 15, ["z"] = 21, ["name"] = "default:tinblock"}, {["x"] = 9, ["y"] = 7, ["param1"] = 15, ["z"] = 22, ["name"] = "default:tinblock"}, {["x"] = 9, ["y"] = 7, ["param1"] = 15, ["z"] = 23, ["name"] = "default:tinblock"}, {["x"] = 9, ["y"] = 7, ["param1"] = 15, ["z"] = 24, ["name"] = "default:tinblock"}, {["x"] = 9, ["y"] = 7, ["param1"] = 15, ["z"] = 25, ["name"] = "default:tinblock"}, {["x"] = 9, ["y"] = 8, ["param1"] = 15, ["z"] = 14, ["name"] = "default:tinblock"}, {["x"] = 9, ["y"] = 8, ["param1"] = 15, ["z"] = 15, ["name"] = "default:tinblock"}, {["x"] = 9, ["y"] = 8, ["param1"] = 15, ["z"] = 16, ["name"] = "default:tinblock"}, {["x"] = 9, ["y"] = 8, ["param1"] = 15, ["z"] = 17, ["name"] = "default:tinblock"}, {["x"] = 9, ["y"] = 8, ["param1"] = 15, ["z"] = 18, ["name"] = "default:tinblock"}, {["x"] = 9, ["y"] = 8, ["param1"] = 15, ["z"] = 19, ["name"] = "default:tinblock"}, {["x"] = 9, ["y"] = 8, ["param1"] = 15, ["z"] = 20, ["name"] = "default:tinblock"}, {["x"] = 9, ["y"] = 8, ["param1"] = 15, ["z"] = 21, ["name"] = "default:tinblock"}, {["x"] = 9, ["y"] = 8, ["param1"] = 15, ["z"] = 22, ["name"] = "default:tinblock"}, {["x"] = 9, ["y"] = 8, ["param1"] = 15, ["z"] = 23, ["name"] = "default:tinblock"}, {["x"] = 9, ["y"] = 8, ["param1"] = 15, ["z"] = 24, ["name"] = "default:tinblock"}, {["x"] = 9, ["y"] = 8, ["param1"] = 15, ["z"] = 25, ["name"] = "default:tinblock"}, {["x"] = 9, ["y"] = 9, ["param1"] = 15, ["z"] = 14, ["name"] = "default:tinblock"}, {["x"] = 9, ["y"] = 9, ["param1"] = 15, ["z"] = 25, ["name"] = "default:tinblock"}, {["x"] = 9, ["y"] = 10, ["param1"] = 15, ["z"] = 14, ["name"] = "default:tinblock"}, {["x"] = 9, ["y"] = 11, ["param1"] = 15, ["z"] = 14, ["name"] = "default:tinblock"}, {["x"] = 9, ["y"] = 80, ["param1"] = 15, ["z"] = 0, ["name"] = "unbreakable_map_barrier:barrier"}, {["x"] = 9, ["y"] = 80, ["param1"] = 15, ["z"] = 1, ["name"] = "unbreakable_map_barrier:barrier"}, {["x"] = 9, ["y"] = 80, ["param1"] = 15, ["z"] = 2, ["name"] = "unbreakable_map_barrier:barrier"}, {["x"] = 9, ["y"] = 80, ["param1"] = 15, ["z"] = 3, ["name"] = "unbreakable_map_barrier:barrier"}, {["x"] = 9, ["y"] = 80, ["param1"] = 15, ["z"] = 4, ["name"] = "unbreakable_map_barrier:barrier"}, {["x"] = 9, ["y"] = 80, ["param1"] = 15, ["z"] = 5, ["name"] = "unbreakable_map_barrier:barrier"}, {["x"] = 9, ["y"] = 80, ["param1"] = 15, ["z"] = 6, ["name"] = "unbreakable_map_barrier:barrier"}, {["x"] = 9, ["y"] = 80, ["param1"] = 15, ["z"] = 7, ["name"] = "unbreakable_map_barrier:barrier"}, {["x"] = 9, ["y"] = 80, ["param1"] = 15, ["z"] = 8, ["name"] = "unbreakable_map_barrier:barrier"}, {["x"] = 9, ["y"] = 80, ["param1"] = 15, ["z"] = 9, ["name"] = "unbreakable_map_barrier:barrier"}, {["x"] = 9, ["y"] = 80, ["param1"] = 15, ["z"] = 10, ["name"] = "unbreakable_map_barrier:barrier"}, {["x"] = 9, ["y"] = 80, ["param1"] = 15, ["z"] = 11, ["name"] = "unbreakable_map_barrier:barrier"}, {["x"] = 9, ["y"] = 80, ["param1"] = 15, ["z"] = 12, ["name"] = "unbreakable_map_barrier:barrier"}, {["x"] = 9, ["y"] = 80, ["param1"] = 15, ["z"] = 13, ["name"] = "unbreakable_map_barrier:barrier"}, {["x"] = 9, ["y"] = 80, ["param1"] = 15, ["z"] = 14, ["name"] = "unbreakable_map_barrier:barrier"}, {["x"] = 9, ["y"] = 80, ["param1"] = 15, ["z"] = 15, ["name"] = "unbreakable_map_barrier:barrier"}, {["x"] = 9, ["y"] = 80, ["param1"] = 15, ["z"] = 16, ["name"] = "unbreakable_map_barrier:barrier"}, {["x"] = 9, ["y"] = 80, ["param1"] = 15, ["z"] = 17, ["name"] = "unbreakable_map_barrier:barrier"}, {["x"] = 9, ["y"] = 80, ["param1"] = 15, ["z"] = 18, ["name"] = "unbreakable_map_barrier:barrier"}, {["x"] = 9, ["y"] = 80, ["param1"] = 15, ["z"] = 19, ["name"] = "unbreakable_map_barrier:barrier"}, {["x"] = 9, ["y"] = 80, ["param1"] = 15, ["z"] = 20, ["name"] = "unbreakable_map_barrier:barrier"}, {["x"] = 9, ["y"] = 80, ["param1"] = 15, ["z"] = 21, ["name"] = "unbreakable_map_barrier:barrier"}, {["x"] = 9, ["y"] = 80, ["param1"] = 15, ["z"] = 22, ["name"] = "unbreakable_map_barrier:barrier"}, {["x"] = 9, ["y"] = 80, ["param1"] = 15, ["z"] = 23, ["name"] = "unbreakable_map_barrier:barrier"}, {["x"] = 9, ["y"] = 80, ["param1"] = 15, ["z"] = 24, ["name"] = "unbreakable_map_barrier:barrier"}, {["x"] = 9, ["y"] = 80, ["param1"] = 15, ["z"] = 25, ["name"] = "unbreakable_map_barrier:barrier"}, {["x"] = 9, ["y"] = 80, ["param1"] = 15, ["z"] = 26, ["name"] = "unbreakable_map_barrier:barrier"}, {["x"] = 9, ["y"] = 80, ["param1"] = 15, ["z"] = 27, ["name"] = "unbreakable_map_barrier:barrier"}, {["x"] = 9, ["y"] = 80, ["param1"] = 15, ["z"] = 28, ["name"] = "unbreakable_map_barrier:barrier"}, {["x"] = 9, ["y"] = 80, ["param1"] = 15, ["z"] = 29, ["name"] = "unbreakable_map_barrier:barrier"}, {["x"] = 9, ["y"] = 80, ["param1"] = 15, ["z"] = 30, ["name"] = "unbreakable_map_barrier:barrier"}, {["x"] = 9, ["y"] = 80, ["param1"] = 15, ["z"] = 31, ["name"] = "unbreakable_map_barrier:barrier"}, {["x"] = 9, ["y"] = 80, ["param1"] = 15, ["z"] = 32, ["name"] = "unbreakable_map_barrier:barrier"}, {["x"] = 9, ["y"] = 80, ["param1"] = 15, ["z"] = 33, ["name"] = "unbreakable_map_barrier:barrier"}, {["x"] = 9, ["y"] = 80, ["param1"] = 15, ["z"] = 34, ["name"] = "unbreakable_map_barrier:barrier"}, {["x"] = 9, ["y"] = 80, ["param1"] = 15, ["z"] = 35, ["name"] = "unbreakable_map_barrier:barrier"}, {["x"] = 9, ["y"] = 80, ["param1"] = 15, ["z"] = 36, ["name"] = "unbreakable_map_barrier:barrier"}, {["x"] = 9, ["y"] = 80, ["param1"] = 15, ["z"] = 37, ["name"] = "unbreakable_map_barrier:barrier"}, {["x"] = 9, ["y"] = 80, ["param1"] = 15, ["z"] = 38, ["name"] = "unbreakable_map_barrier:barrier"}, {["x"] = 9, ["y"] = 80, ["param1"] = 15, ["z"] = 39, ["name"] = "unbreakable_map_barrier:barrier"}, {["x"] = 9, ["y"] = 80, ["param1"] = 15, ["z"] = 40, ["name"] = "unbreakable_map_barrier:barrier"}, {["x"] = 9, ["y"] = 80, ["param1"] = 15, ["z"] = 41, ["name"] = "unbreakable_map_barrier:barrier"}, {["x"] = 9, ["y"] = 80, ["param1"] = 15, ["z"] = 42, ["name"] = "unbreakable_map_barrier:barrier"}, {["x"] = 9, ["y"] = 80, ["param1"] = 15, ["z"] = 43, ["name"] = "unbreakable_map_barrier:barrier"}, {["x"] = 9, ["y"] = 80, ["param1"] = 15, ["z"] = 44, ["name"] = "unbreakable_map_barrier:barrier"}, {["x"] = 9, ["y"] = 80, ["param1"] = 15, ["z"] = 45, ["name"] = "unbreakable_map_barrier:barrier"}, {["x"] = 9, ["y"] = 80, ["param1"] = 15, ["z"] = 46, ["name"] = "unbreakable_map_barrier:barrier"}, {["x"] = 9, ["y"] = 80, ["param1"] = 15, ["z"] = 47, ["name"] = "unbreakable_map_barrier:barrier"}, {["x"] = 9, ["y"] = 80, ["param1"] = 15, ["z"] = 48, ["name"] = "unbreakable_map_barrier:barrier"}, {["x"] = 9, ["y"] = 80, ["param1"] = 15, ["z"] = 49, ["name"] = "unbreakable_map_barrier:barrier"}, {["x"] = 9, ["y"] = 80, ["param1"] = 15, ["z"] = 50, ["name"] = "unbreakable_map_barrier:barrier"}, {["x"] = 9, ["y"] = 80, ["param1"] = 15, ["z"] = 51, ["name"] = "unbreakable_map_barrier:barrier"}, {["x"] = 9, ["y"] = 80, ["param1"] = 15, ["z"] = 52, ["name"] = "unbreakable_map_barrier:barrier"}, {["x"] = 9, ["y"] = 80, ["param1"] = 15, ["z"] = 53, ["name"] = "unbreakable_map_barrier:barrier"}, {["x"] = 9, ["y"] = 80, ["param1"] = 15, ["z"] = 54, ["name"] = "unbreakable_map_barrier:barrier"}, {["x"] = 9, ["y"] = 80, ["param1"] = 15, ["z"] = 55, ["name"] = "unbreakable_map_barrier:barrier"}, {["x"] = 9, ["y"] = 80, ["param1"] = 15, ["z"] = 56, ["name"] = "unbreakable_map_barrier:barrier"}, {["x"] = 9, ["y"] = 80, ["param1"] = 15, ["z"] = 57, ["name"] = "unbreakable_map_barrier:barrier"}, {["x"] = 9, ["y"] = 80, ["param1"] = 15, ["z"] = 58, ["name"] = "unbreakable_map_barrier:barrier"}, {["x"] = 9, ["y"] = 80, ["param1"] = 15, ["z"] = 59, ["name"] = "unbreakable_map_barrier:barrier"}, {["x"] = 9, ["y"] = 80, ["param1"] = 15, ["z"] = 60, ["name"] = "unbreakable_map_barrier:barrier"}, {["x"] = 9, ["y"] = 80, ["param1"] = 15, ["z"] = 61, ["name"] = "unbreakable_map_barrier:barrier"}, {["x"] = 9, ["y"] = 80, ["param1"] = 15, ["z"] = 62, ["name"] = "unbreakable_map_barrier:barrier"}, {["x"] = 9, ["y"] = 80, ["param1"] = 15, ["z"] = 63, ["name"] = "unbreakable_map_barrier:barrier"}, {["x"] = 9, ["y"] = 80, ["param1"] = 15, ["z"] = 64, ["name"] = "unbreakable_map_barrier:barrier"}, {["x"] = 9, ["y"] = 80, ["param1"] = 15, ["z"] = 65, ["name"] = "unbreakable_map_barrier:barrier"}, {["x"] = 9, ["y"] = 80, ["param1"] = 15, ["z"] = 66, ["name"] = "unbreakable_map_barrier:barrier"}, {["x"] = 9, ["y"] = 80, ["param1"] = 15, ["z"] = 67, ["name"] = "unbreakable_map_barrier:barrier"}, {["x"] = 9, ["y"] = 80, ["param1"] = 15, ["z"] = 68, ["name"] = "unbreakable_map_barrier:barrier"}, {["x"] = 9, ["y"] = 80, ["param1"] = 15, ["z"] = 69, ["name"] = "unbreakable_map_barrier:barrier"},