5:return {{["x"] = 0, ["y"] = 0, ["param1"] = 15, ["z"] = 0, ["name"] = "unbreakable_map_barrier:barrier"}, {["x"] = 0, ["y"] = 1, ["param1"] = 15, ["z"] = 0, ["name"] = "unbreakable_map_barrier:barrier"}, {["x"] = 0, ["y"] = 2, ["param1"] = 15, ["z"] = 0, ["name"] = "unbreakable_map_barrier:barrier"}, {["x"] = 0, ["y"] = 3, ["param1"] = 15, ["z"] = 0, ["name"] = "unbreakable_map_barrier:barrier"}, {["x"] = 0, ["y"] = 4, ["param1"] = 15, ["z"] = 0, ["name"] = "unbreakable_map_barrier:barrier"}, {["x"] = 0, ["y"] = 5, ["param1"] = 15, ["z"] = 0, ["name"] = "unbreakable_map_barrier:barrier"}, {["x"] = 0, ["y"] = 6, ["param1"] = 15, ["z"] = 0, ["name"] = "unbreakable_map_barrier:barrier"}, {["x"] = 0, ["y"] = 7, ["param1"] = 15, ["z"] = 0, ["name"] = "unbreakable_map_barrier:barrier"}, {["x"] = 0, ["y"] = 8, ["param1"] = 15, ["z"] = 0, ["name"] = "unbreakable_map_barrier:barrier"}, {["x"] = 0, ["y"] = 9, ["param1"] = 15, ["z"] = 0, ["name"] = "unbreakable_map_barrier:barrier"}, {["x"] = 0, ["y"] = 10, ["param1"] = 15, ["z"] = 0, ["name"] = "unbreakable_map_barrier:barrier"}, {["x"] = 0, ["y"] = 11, ["param1"] = 15, ["z"] = 0, ["name"] = "unbreakable_map_barrier:barrier"}, {["x"] = 0, ["y"] = 12, ["param1"] = 15, ["z"] = 0, ["name"] = "unbreakable_map_barrier:barrier"}, {["x"] = 0, ["y"] = 13, ["param1"] = 15, ["z"] = 0, ["name"] = "unbreakable_map_barrier:barrier"}, {["x"] = 0, ["y"] = 14, ["param1"] = 15, ["z"] = 0, ["name"] = "unbreakable_map_barrier:barrier"}, {["x"] = 0, ["y"] = 15, ["param1"] = 15, ["z"] = 0, ["name"] = "unbreakable_map_barrier:barrier"}, {["x"] = 0, ["y"] = 16, ["param1"] = 15, ["z"] = 0, ["name"] = "unbreakable_map_barrier:barrier"}, {["x"] = 0, ["y"] = 17, ["param1"] = 15, ["z"] = 0, ["name"] = "unbreakable_map_barrier:barrier"}, {["x"] = 0, ["y"] = 18, ["param1"] = 15, ["z"] = 0, ["name"] = "unbreakable_map_barrier:barrier"}, {["x"] = 0, ["y"] = 19, ["param1"] = 15, ["z"] = 0, ["name"] = "unbreakable_map_barrier:barrier"}, {["x"] = 0, ["y"] = 20, ["param1"] = 15, ["z"] = 0, ["name"] = "unbreakable_map_barrier:barrier"}, {["x"] = 0, ["y"] = 21, ["param1"] = 15, ["z"] = 0, ["name"] = "unbreakable_map_barrier:barrier"}, {["x"] = 0, ["y"] = 22, ["param1"] = 15, ["z"] = 0, ["name"] = "unbreakable_map_barrier:barrier"}, {["x"] = 0, ["y"] = 23, ["param1"] = 15, ["z"] = 0, ["name"] = "unbreakable_map_barrier:barrier"}, {["x"] = 0, ["y"] = 24, ["param1"] = 15, ["z"] = 0, ["name"] = "unbreakable_map_barrier:barrier"}, {["x"] = 0, ["y"] = 25, ["param1"] = 15, ["z"] = 0, ["name"] = "unbreakable_map_barrier:barrier"}, {["x"] = 0, ["y"] = 26, ["param1"] = 15, ["z"] = 0, ["name"] = "unbreakable_map_barrier:barrier"}, {["x"] = 0, ["y"] = 27, ["param1"] = 15, ["z"] = 0, ["name"] = "unbreakable_map_barrier:barrier"}, {["x"] = 0, ["y"] = 28, ["param1"] = 15, ["z"] = 0, ["name"] = "unbreakable_map_barrier:barrier"}, {["x"] = 0, ["y"] = 29, ["param1"] = 15, ["z"] = 0, ["name"] = "unbreakable_map_barrier:barrier"}, {["x"] = 0, ["y"] = 30, ["param1"] = 15, ["z"] = 0, ["name"] = "unbreakable_map_barrier:barrier"}, {["x"] = 0, ["y"] = 31, ["param1"] = 15, ["z"] = 0, ["name"] = "unbreakable_map_barrier:barrier"}, {["x"] = 0, ["y"] = 32, ["param1"] = 15, ["z"] = 0, ["name"] = "unbreakable_map_barrier:barrier"}, {["x"] = 0, ["y"] = 33, ["param1"] = 15, ["z"] = 0, ["name"] = "unbreakable_map_barrier:barrier"}, {["x"] = 0, ["y"] = 34, ["param1"] = 15, ["z"] = 0, ["name"] = "unbreakable_map_barrier:barrier"}, {["x"] = 0, ["y"] = 35, ["param1"] = 15, ["z"] = 0, ["name"] = "unbreakable_map_barrier:barrier"}, {["x"] = 0, ["y"] = 36, ["param1"] = 15, ["z"] = 0, ["name"] = "unbreakable_map_barrier:barrier"}, {["x"] = 0, ["y"] = 37, ["param1"] = 15, ["z"] = 0, ["name"] = "unbreakable_map_barrier:barrier"}, {["x"] = 0, ["y"] = 38, ["param1"] = 15, ["z"] = 0, ["name"] = "unbreakable_map_barrier:barrier"}, {["x"] = 0, ["y"] = 39, ["param1"] = 15, ["z"] = 0, ["name"] = "unbreakable_map_barrier:barrier"}, {["x"] = 0, ["y"] = 40, ["param1"] = 15, ["z"] = 0, ["name"] = "unbreakable_map_barrier:barrier"}, {["x"] = 0, ["y"] = 41, ["param1"] = 15, ["z"] = 0, ["name"] = "unbreakable_map_barrier:barrier"}, {["x"] = 0, ["y"] = 42, ["param1"] = 15, ["z"] = 0, ["name"] = "unbreakable_map_barrier:barrier"}, {["x"] = 0, ["y"] = 43, ["param1"] = 15, ["z"] = 0, ["name"] = "unbreakable_map_barrier:barrier"}, {["x"] = 0, ["y"] = 44, ["param1"] = 15, ["z"] = 0, ["name"] = "unbreakable_map_barrier:barrier"}, {["x"] = 0, ["y"] = 45, ["param1"] = 15, ["z"] = 0, ["name"] = "unbreakable_map_barrier:barrier"}, {["x"] = 0, ["y"] = 46, ["param1"] = 15, ["z"] = 0, ["name"] = "unbreakable_map_barrier:barrier"}, {["x"] = 0, ["y"] = 47, ["param1"] = 15, ["z"] = 0, ["name"] = "unbreakable_map_barrier:barrier"}, {["x"] = 0, ["y"] = 48, ["param1"] = 15, ["z"] = 0, ["name"] = "unbreakable_map_barrier:barrier"}, {["x"] = 0, ["y"] = 49, ["param1"] = 15, ["z"] = 0, ["name"] = "unbreakable_map_barrier:barrier"}, {["x"] = 0, ["y"] = 50, ["param1"] = 15, ["z"] = 0, ["name"] = "unbreakable_map_barrier:barrier"}, {["x"] = 0, ["y"] = 51, ["param1"] = 15, ["z"] = 0, ["name"] = "unbreakable_map_barrier:barrier"}, {["x"] = 0, ["y"] = 52, ["param1"] = 15, ["z"] = 0, ["name"] = "unbreakable_map_barrier:barrier"}, {["x"] = 0, ["y"] = 53, ["param1"] = 15, ["z"] = 0, ["name"] = "unbreakable_map_barrier:barrier"}, {["x"] = 0, ["y"] = 54, ["param1"] = 15, ["z"] = 0, ["name"] = "unbreakable_map_barrier:barrier"}, {["x"] = 0, ["y"] = 55, ["param1"] = 15, ["z"] = 0, ["name"] = "unbreakable_map_barrier:barrier"}, {["x"] = 0, ["y"] = 56, ["param1"] = 15, ["z"] = 0, ["name"] = "unbreakable_map_barrier:barrier"}, {["x"] = 0, ["y"] = 57, ["param1"] = 15, ["z"] = 0, ["name"] = "unbreakable_map_barrier:barrier"}, {["x"] = 0, ["y"] = 58, ["param1"] = 15, ["z"] = 0, ["name"] = "unbreakable_map_barrier:barrier"}, {["x"] = 0, ["y"] = 59, ["param1"] = 15, ["z"] = 0, ["name"] = "unbreakable_map_barrier:barrier"}, {["x"] = 0, ["y"] = 60, ["param1"] = 15, ["z"] = 0, ["name"] = "unbreakable_map_barrier:barrier"}, {["x"] = 0, ["y"] = 61, ["param1"] = 15, ["z"] = 0, ["name"] = "unbreakable_map_barrier:barrier"}, {["x"] = 0, ["y"] = 62, ["param1"] = 15, ["z"] = 0, ["name"] = "unbreakable_map_barrier:barrier"}, {["x"] = 0, ["y"] = 63, ["param1"] = 15, ["z"] = 0, ["name"] = "unbreakable_map_barrier:barrier"}, {["x"] = 0, ["y"] = 64, ["param1"] = 15, ["z"] = 0, ["name"] = "unbreakable_map_barrier:barrier"}, {["x"] = 0, ["y"] = 65, ["param1"] = 15, ["z"] = 0, ["name"] = "unbreakable_map_barrier:barrier"}, {["x"] = 0, ["y"] = 66, ["param1"] = 15, ["z"] = 0, ["name"] = "unbreakable_map_barrier:barrier"}, {["x"] = 0, ["y"] = 67, ["param1"] = 15, ["z"] = 0, ["name"] = "unbreakable_map_barrier:barrier"}, {["x"] = 0, ["y"] = 68, ["param1"] = 15, ["z"] = 0, ["name"] = "unbreakable_map_barrier:barrier"}, {["x"] = 0, ["y"] = 69, ["param1"] = 15, ["z"] = 0, ["name"] = "unbreakable_map_barrier:barrier"}, {["x"] = 0, ["y"] = 70, ["param1"] = 15, ["z"] = 0, ["name"] = "unbreakable_map_barrier:barrier"}, {["x"] = 0, ["y"] = 71, ["param1"] = 15, ["z"] = 0, ["name"] = "unbreakable_map_barrier:barrier"}, {["x"] = 0, ["y"] = 72, ["param1"] = 15, ["z"] = 0, ["name"] = "unbreakable_map_barrier:barrier"}, {["x"] = 0, ["y"] = 73, ["param1"] = 15, ["z"] = 0, ["name"] = "unbreakable_map_barrier:barrier"}, {["x"] = 0, ["y"] = 74, ["param1"] = 15, ["z"] = 0, ["name"] = "unbreakable_map_barrier:barrier"}, {["x"] = 0, ["y"] = 75, ["param1"] = 15, ["z"] = 0, ["name"] = "unbreakable_map_barrier:barrier"}, {["x"] = 0, ["y"] = 76, ["param1"] = 15, ["z"] = 0, ["name"] = "unbreakable_map_barrier:barrier"}, {["x"] = 0, ["y"] = 77, ["param1"] = 15, ["z"] = 0, ["name"] = "unbreakable_map_barrier:barrier"}, {["x"] = 0, ["y"] = 78, ["param1"] = 15, ["z"] = 0, ["name"] = "unbreakable_map_barrier:barrier"}, {["x"] = 0, ["y"] = 79, ["param1"] = 15, ["z"] = 0, ["name"] = "unbreakable_map_barrier:barrier"}, {["x"] = 0, ["y"] = 80, ["param1"] = 15, ["z"] = 0, ["name"] = "unbreakable_map_barrier:barrier"}, {["x"] = 0, ["y"] = 80, ["param1"] = 15, ["z"] = 1, ["name"] = "unbreakable_map_barrier:barrier"}, {["x"] = 0, ["y"] = 80, ["param1"] = 15, ["z"] = 2, ["name"] = "unbreakable_map_barrier:barrier"}, {["x"] = 0, ["y"] = 80, ["param1"] = 15, ["z"] = 3, ["name"] = "unbreakable_map_barrier:barrier"}, {["x"] = 0, ["y"] = 80, ["param1"] = 15, ["z"] = 4, ["name"] = "unbreakable_map_barrier:barrier"}, {["x"] = 0, ["y"] = 80, ["param1"] = 15, ["z"] = 5, ["name"] = "unbreakable_map_barrier:barrier"}, {["x"] = 0, ["y"] = 80, ["param1"] = 15, ["z"] = 6, ["name"] = "unbreakable_map_barrier:barrier"}, {["x"] = 0, ["y"] = 80, ["param1"] = 15, ["z"] = 7, ["name"] = "unbreakable_map_barrier:barrier"}, {["x"] = 0, ["y"] = 80, ["param1"] = 15, ["z"] = 8, ["name"] = "unbreakable_map_barrier:barrier"}, {["x"] = 0, ["y"] = 80, ["param1"] = 15, ["z"] = 9, ["name"] = "unbreakable_map_barrier:barrier"}, {["x"] = 0, ["y"] = 80, ["param1"] = 15, ["z"] = 10, ["name"] = "unbreakable_map_barrier:barrier"}, {["x"] = 0, ["y"] = 80, ["param1"] = 15, ["z"] = 11, ["name"] = "unbreakable_map_barrier:barrier"}, {["x"] = 0, ["y"] = 80, ["param1"] = 15, ["z"] = 12, ["name"] = "unbreakable_map_barrier:barrier"}, {["x"] = 0, ["y"] = 80, ["param1"] = 15, ["z"] = 13, ["name"] = "unbreakable_map_barrier:barrier"}, {["x"] = 0, ["y"] = 80, ["param1"] = 15, ["z"] = 14, ["name"] = "unbreakable_map_barrier:barrier"}, {["x"] = 0, ["y"] = 80, ["param1"] = 15, ["z"] = 15, ["name"] = "unbreakable_map_barrier:barrier"}, {["x"] = 0, ["y"] = 80, ["param1"] = 15, ["z"] = 16, ["name"] = "unbreakable_map_barrier:barrier"}, {["x"] = 0, ["y"] = 80, ["param1"] = 15, ["z"] = 17, ["name"] = "unbreakable_map_barrier:barrier"}, {["x"] = 0, ["y"] = 80, ["param1"] = 15, ["z"] = 18, ["name"] = "unbreakable_map_barrier:barrier"}, {["x"] = 0, ["y"] = 80, ["param1"] = 15, ["z"] = 19, ["name"] = "unbreakable_map_barrier:barrier"}, {["x"] = 0, ["y"] = 80, ["param1"] = 15, ["z"] = 20, ["name"] = "unbreakable_map_barrier:barrier"}, {["x"] = 0, ["y"] = 80, ["param1"] = 15, ["z"] = 21, ["name"] = "unbreakable_map_barrier:barrier"}, {["x"] = 0, ["y"] = 80, ["param1"] = 15, ["z"] = 22, ["name"] = "unbreakable_map_barrier:barrier"}, {["x"] = 0, ["y"] = 80, ["param1"] = 15, ["z"] = 23, ["name"] = "unbreakable_map_barrier:barrier"}, {["x"] = 0, ["y"] = 80, ["param1"] = 15, ["z"] = 24, ["name"] = "unbreakable_map_barrier:barrier"}, {["x"] = 0, ["y"] = 80, ["param1"] = 15, ["z"] = 25, ["name"] = "unbreakable_map_barrier:barrier"}, {["x"] = 0, ["y"] = 80, ["param1"] = 15, ["z"] = 26, ["name"] = "unbreakable_map_barrier:barrier"}, {["x"] = 0, ["y"] = 80, ["param1"] = 15, ["z"] = 27, ["name"] = "unbreakable_map_barrier:barrier"}, {["x"] = 0, ["y"] = 80, ["param1"] = 15, ["z"] = 28, ["name"] = "unbreakable_map_barrier:barrier"}, {["x"] = 0, ["y"] = 80, ["param1"] = 15, ["z"] = 29, ["name"] = "unbreakable_map_barrier:barrier"}, {["x"] = 0, ["y"] = 80, ["param1"] = 15, ["z"] = 30, ["name"] = "unbreakable_map_barrier:barrier"}, {["x"] = 0, ["y"] = 80, ["param1"] = 15, ["z"] = 31, ["name"] = "unbreakable_map_barrier:barrier"}, {["x"] = 0, ["y"] = 80, ["param1"] = 15, ["z"] = 32, ["name"] = "unbreakable_map_barrier:barrier"}, {["x"] = 0, ["y"] = 80, ["param1"] = 15, ["z"] = 33, ["name"] = "unbreakable_map_barrier:barrier"}, {["x"] = 0, ["y"] = 80, ["param1"] = 15, ["z"] = 34, ["name"] = "unbreakable_map_barrier:barrier"}, {["x"] = 0, ["y"] = 80, ["param1"] = 15, ["z"] = 35, ["name"] = "unbreakable_map_barrier:barrier"}, {["x"] = 0, ["y"] = 80, ["param1"] = 15, ["z"] = 36, ["name"] = "unbreakable_map_barrier:barrier"}, {["x"] = 0, ["y"] = 80, ["param1"] = 15, ["z"] = 37, ["name"] = "unbreakable_map_barrier:barrier"}, {["x"] = 0, ["y"] = 80, ["param1"] = 15, ["z"] = 38, ["name"] = "unbreakable_map_barrier:barrier"}, {["x"] = 0, ["y"] = 80, ["param1"] = 15, ["z"] = 39, ["name"] = "unbreakable_map_barrier:barrier"}, {["x"] = 0, ["y"] = 80, ["param1"] = 15, ["z"] = 40, ["name"] = "unbreakable_map_barrier:barrier"}, {["x"] = 0, ["y"] = 80, ["param1"] = 15, ["z"] = 41, ["name"] = "unbreakable_map_barrier:barrier"}, {["x"] = 0, ["y"] = 80, ["param1"] = 15, ["z"] = 42, ["name"] = "unbreakable_map_barrier:barrier"}, {["x"] = 0, ["y"] = 80, ["param1"] = 15, ["z"] = 43, ["name"] = "unbreakable_map_barrier:barrier"}, {["x"] = 0, ["y"] = 80, ["param1"] = 15, ["z"] = 44, ["name"] = "unbreakable_map_barrier:barrier"}, {["x"] = 0, ["y"] = 80, ["param1"] = 15, ["z"] = 45, ["name"] = "unbreakable_map_barrier:barrier"}, {["x"] = 0, ["y"] = 80, ["param1"] = 15, ["z"] = 46, ["name"] = "unbreakable_map_barrier:barrier"}, {["x"] = 0, ["y"] = 80, ["param1"] = 15, ["z"] = 47, ["name"] = "unbreakable_map_barrier:barrier"}, {["x"] = 0, ["y"] = 80, ["param1"] = 15, ["z"] = 48, ["name"] = "unbreakable_map_barrier:barrier"}, {["x"] = 0, ["y"] = 80, ["param1"] = 15, ["z"] = 49, ["name"] = "unbreakable_map_barrier:barrier"}, {["x"] = 0, ["y"] = 80, ["param1"] = 15, ["z"] = 50, ["name"] = "unbreakable_map_barrier:barrier"}, {["x"] = 0, ["y"] = 80, ["param1"] = 15, ["z"] = 51, ["name"] = "unbreakable_map_barrier:barrier"}, {["x"] = 0, ["y"] = 80, ["param1"] = 15, ["z"] = 52, ["name"] = "unbreakable_map_barrier:barrier"}, {["x"] = 0, ["y"] = 80, ["param1"] = 15, ["z"] = 53, ["name"] = "unbreakable_map_barrier:barrier"}, {["x"] = 0, ["y"] = 80, ["param1"] = 15, ["z"] = 54, ["name"] = "unbreakable_map_barrier:barrier"}, {["x"] = 0, ["y"] = 80, ["param1"] = 15, ["z"] = 55, ["name"] = "unbreakable_map_barrier:barrier"}, {["x"] = 0, ["y"] = 80, ["param1"] = 15, ["z"] = 56, ["name"] = "unbreakable_map_barrier:barrier"}, {["x"] = 0, ["y"] = 80, ["param1"] = 15, ["z"] = 57, ["name"] = "unbreakable_map_barrier:barrier"}, {["x"] = 0, ["y"] = 80, ["param1"] = 15, ["z"] = 58, ["name"] = "unbreakable_map_barrier:barrier"}, {["x"] = 0, ["y"] = 80, ["param1"] = 15, ["z"] = 59, ["name"] = "unbreakable_map_barrier:barrier"}, {["x"] = 0, ["y"] = 80, ["param1"] = 15, ["z"] = 60, ["name"] = "unbreakable_map_barrier:barrier"}, {["x"] = 0, ["y"] = 80, ["param1"] = 15, ["z"] = 61, ["name"] = "unbreakable_map_barrier:barrier"}, {["x"] = 0, ["y"] = 80, ["param1"] = 15, ["z"] = 62, ["name"] = "unbreakable_map_barrier:barrier"}, {["x"] = 0, ["y"] = 80, ["param1"] = 15, ["z"] = 63, ["name"] = "unbreakable_map_barrier:barrier"}, {["x"] = 0, ["y"] = 80, ["param1"] = 15, ["z"] = 64, ["name"] = "unbreakable_map_barrier:barrier"}, {["x"] = 0, ["y"] = 80, ["param1"] = 15, ["z"] = 65, ["name"] = "unbreakable_map_barrier:barrier"}, {["x"] = 0, ["y"] = 80, ["param1"] = 15, ["z"] = 66, ["name"] = "unbreakable_map_barrier:barrier"}, {["x"] = 0, ["y"] = 80, ["param1"] = 15, ["z"] = 67, ["name"] = "unbreakable_map_barrier:barrier"}, {["x"] = 0, ["y"] = 80, ["param1"] = 15, ["z"] = 68, ["name"] = "unbreakable_map_barrier:barrier"}, {["x"] = 0, ["y"] = 80, ["param1"] = 15, ["z"] = 69, ["name"] = "unbreakable_map_barrier:barrier"}, {["x"] = 0, ["y"] = 80, ["param1"] = 15, ["z"] = 70, ["name"] = "unbreakable_map_barrier:barrier"}, {["x"] = 0, ["y"] = 80, ["param1"] = 15, ["z"] = 71, ["name"] = "unbreakable_map_barrier:barrier"}, {["x"] = 0, ["y"] = 80, ["param1"] = 15, ["z"] = 72, ["name"] = "unbreakable_map_barrier:barrier"}, {["x"] = 0, ["y"] = 80, ["param1"] = 15, ["z"] = 73, ["name"] = "unbreakable_map_barrier:barrier"}, {["x"] = 0, ["y"] = 80, ["param1"] = 15, ["z"] = 74, ["name"] = "unbreakable_map_barrier:barrier"}, {["x"] = 0, ["y"] = 80, ["param1"] = 15, ["z"] = 75, ["name"] = "unbreakable_map_barrier:barrier"}, {["x"] = 0, ["y"] = 80, ["param1"] = 15, ["z"] = 76, ["name"] = "unbreakable_map_barrier:barrier"}, {["x"] = 0, ["y"] = 80, ["param1"] = 15, ["z"] = 77, ["name"] = "unbreakable_map_barrier:barrier"}, {["x"] = 0, ["y"] = 80, ["param1"] = 15, ["z"] = 78, ["name"] = "unbreakable_map_barrier:barrier"}, {["x"] = 0, ["y"] = 80, ["param1"] = 15, ["z"] = 79, ["name"] = "unbreakable_map_barrier:barrier"}, {["x"] = 0, ["y"] = 80, ["param1"] = 15, ["z"] = 80, ["name"] = "unbreakable_map_barrier:barrier"}, {["x"] = 1, ["y"] = 0, ["param1"] = 15, ["z"] = 0, ["name"] = "unbreakable_map_barrier:barrier"}, {["x"] = 1, ["y"] = 1, ["param1"] = 15, ["z"] = 0, ["name"] = "unbreakable_map_barrier:barrier"}, {["x"] = 1, ["y"] = 2, ["param1"] = 15, ["z"] = 0, ["name"] = "unbreakable_map_barrier:barrier"}, {["x"] = 1, ["y"] = 3, ["param1"] = 15, ["z"] = 0, ["name"] = "unbreakable_map_barrier:barrier"}, {["x"] = 1, ["y"] = 4, ["param1"] = 15, ["z"] = 0, ["name"] = "unbreakable_map_barrier:barrier"}, {["x"] = 1, ["y"] = 5, ["param1"] = 15, ["z"] = 0, ["name"] = "unbreakable_map_barrier:barrier"}, {["x"] = 1, ["y"] = 6, ["param1"] = 15, ["z"] = 0, ["name"] = "unbreakable_map_barrier:barrier"}, {["x"] = 1, ["y"] = 7, ["param1"] = 15, ["z"] = 0, ["name"] = "unbreakable_map_barrier:barrier"}, {["x"] = 1, ["y"] = 8, ["param1"] = 15, ["z"] = 0, ["name"] = "unbreakable_map_barrier:barrier"}, {["x"] = 1, ["y"] = 9, ["param1"] = 15, ["z"] = 0, ["name"] = "unbreakable_map_barrier:barrier"}, {["x"] = 1, ["y"] = 10, ["param1"] = 15, ["z"] = 0, ["name"] = "unbreakable_map_barrier:barrier"}, {["x"] = 1, ["y"] = 11, ["param1"] = 15, ["z"] = 0, ["name"] = "unbreakable_map_barrier:barrier"}, {["x"] = 1, ["y"] = 12, ["param1"] = 15, ["z"] = 0, ["name"] = "unbreakable_map_barrier:barrier"}, {["x"] = 1, ["y"] = 13, ["param1"] = 15, ["z"] = 0, ["name"] = "unbreakable_map_barrier:barrier"}, {["x"] = 1, ["y"] = 14, ["param1"] = 15, ["z"] = 0, ["name"] = "unbreakable_map_barrier:barrier"}, {["x"] = 1, ["y"] = 15, ["param1"] = 15, ["z"] = 0, ["name"] = "unbreakable_map_barrier:barrier"}, {["x"] = 1, ["y"] = 16, ["param1"] = 15, ["z"] = 0, ["name"] = "unbreakable_map_barrier:barrier"}, {["x"] = 1, ["y"] = 17, ["param1"] = 15, ["z"] = 0, ["name"] = "unbreakable_map_barrier:barrier"}, {["x"] = 1, ["y"] = 18, ["param1"] = 15, ["z"] = 0, ["name"] = "unbreakable_map_barrier:barrier"}, {["x"] = 1, ["y"] = 19, ["param1"] = 15, ["z"] = 0, ["name"] = "unbreakable_map_barrier:barrier"}, {["x"] = 1, ["y"] = 20, ["param1"] = 15, ["z"] = 0, ["name"] = "unbreakable_map_barrier:barrier"}, {["x"] = 1, ["y"] = 21, ["param1"] = 15, ["z"] = 0, ["name"] = "unbreakable_map_barrier:barrier"}, {["x"] = 1, ["y"] = 22, ["param1"] = 15, ["z"] = 0, ["name"] = "unbreakable_map_barrier:barrier"}, {["x"] = 1, ["y"] = 23, ["param1"] = 15, ["z"] = 0, ["name"] = "unbreakable_map_barrier:barrier"}, {["x"] = 1, ["y"] = 24, ["param1"] = 15, ["z"] = 0, ["name"] = "unbreakable_map_barrier:barrier"}, {["x"] = 1, ["y"] = 25, ["param1"] = 15, ["z"] = 0, ["name"] = "unbreakable_map_barrier:barrier"}, {["x"] = 1, ["y"] = 26, ["param1"] = 15, ["z"] = 0, ["name"] = "unbreakable_map_barrier:barrier"}, {["x"] = 1, ["y"] = 27, ["param1"] = 15, ["z"] = 0, ["name"] = "unbreakable_map_barrier:barrier"}, {["x"] = 1, ["y"] = 28, ["param1"] = 15, ["z"] = 0, ["name"] = "unbreakable_map_barrier:barrier"}, {["x"] = 1, ["y"] = 29, ["param1"] = 15, ["z"] = 0, ["name"] = "unbreakable_map_barrier:barrier"}, {["x"] = 1, ["y"] = 30, ["param1"] = 15, ["z"] = 0, ["name"] = "unbreakable_map_barrier:barrier"}, {["x"] = 1, ["y"] = 31, ["param1"] = 15, ["z"] = 0, ["name"] = "unbreakable_map_barrier:barrier"}, {["x"] = 1, ["y"] = 32, ["param1"] = 15, ["z"] = 0, ["name"] = "unbreakable_map_barrier:barrier"}, {["x"] = 1, ["y"] = 33, ["param1"] = 15, ["z"] = 0, ["name"] = "unbreakable_map_barrier:barrier"}, {["x"] = 1, ["y"] = 34, ["param1"] = 15, ["z"] = 0, ["name"] = "unbreakable_map_barrier:barrier"}, {["x"] = 1, ["y"] = 35, ["param1"] = 15, ["z"] = 0, ["name"] = "unbreakable_map_barrier:barrier"}, {["x"] = 1, ["y"] = 36, ["param1"] = 15, ["z"] = 0, ["name"] = "unbreakable_map_barrier:barrier"}, {["x"] = 1, ["y"] = 37, ["param1"] = 15, ["z"] = 0, ["name"] = "unbreakable_map_barrier:barrier"}, {["x"] = 1, ["y"] = 38, ["param1"] = 15, ["z"] = 0, ["name"] = "unbreakable_map_barrier:barrier"}, {["x"] = 1, ["y"] = 39, ["param1"] = 15, ["z"] = 0, ["name"] = "unbreakable_map_barrier:barrier"}, {["x"] = 1, ["y"] = 40, ["param1"] = 15, ["z"] = 0, ["name"] = "unbreakable_map_barrier:barrier"}, {["x"] = 1, ["y"] = 41, ["param1"] = 15, ["z"] = 0, ["name"] = "unbreakable_map_barrier:barrier"}, {["x"] = 1, ["y"] = 42, ["param1"] = 15, ["z"] = 0, ["name"] = "unbreakable_map_barrier:barrier"}, {["x"] = 1, ["y"] = 43, ["param1"] = 15, ["z"] = 0, ["name"] = "unbreakable_map_barrier:barrier"}, {["x"] = 1, ["y"] = 44, ["param1"] = 15, ["z"] = 0, ["name"] = "unbreakable_map_barrier:barrier"}, {["x"] = 1, ["y"] = 45, ["param1"] = 15, ["z"] = 0, ["name"] = "unbreakable_map_barrier:barrier"}, {["x"] = 1, ["y"] = 46, ["param1"] = 15, ["z"] = 0, ["name"] = "unbreakable_map_barrier:barrier"}, {["x"] = 1, ["y"] = 47, ["param1"] = 15, ["z"] = 0, ["name"] = "unbreakable_map_barrier:barrier"}, {["x"] = 1, ["y"] = 48, ["param1"] = 15, ["z"] = 0, ["name"] = "unbreakable_map_barrier:barrier"}, {["x"] = 1, ["y"] = 49, ["param1"] = 15, ["z"] = 0, ["name"] = "unbreakable_map_barrier:barrier"}, {["x"] = 1, ["y"] = 50, ["param1"] = 15, ["z"] = 0, ["name"] = "unbreakable_map_barrier:barrier"}, {["x"] = 1, ["y"] = 51, ["param1"] = 15, ["z"] = 0, ["name"] = "unbreakable_map_barrier:barrier"}, {["x"] = 1, ["y"] = 52, ["param1"] = 15, ["z"] = 0, ["name"] = "unbreakable_map_barrier:barrier"}, {["x"] = 1, ["y"] = 53, ["param1"] = 15, ["z"] = 0, ["name"] = "unbreakable_map_barrier:barrier"}, {["x"] = 1, ["y"] = 54, ["param1"] = 15, ["z"] = 0, ["name"] = "unbreakable_map_barrier:barrier"}, {["x"] = 1, ["y"] = 55, ["param1"] = 15, ["z"] = 0, ["name"] = "unbreakable_map_barrier:barrier"}, {["x"] = 1, ["y"] = 56, ["param1"] = 15, ["z"] = 0, ["name"] = "unbreakable_map_barrier:barrier"}, {["x"] = 1, ["y"] = 57, ["param1"] = 15, ["z"] = 0, ["name"] = "unbreakable_map_barrier:barrier"}, {["x"] = 1, ["y"] = 58, ["param1"] = 15, ["z"] = 0, ["name"] = "unbreakable_map_barrier:barrier"}, {["x"] = 1, ["y"] = 59, ["param1"] = 15, ["z"] = 0, ["name"] = "unbreakable_map_barrier:barrier"}, {["x"] = 1, ["y"] = 60, ["param1"] = 15, ["z"] = 0, ["name"] = "unbreakable_map_barrier:barrier"}, {["x"] = 1, ["y"] = 61, ["param1"] = 15, ["z"] = 0, ["name"] = "unbreakable_map_barrier:barrier"}, {["x"] = 1, ["y"] = 62, ["param1"] = 15, ["z"] = 0, ["name"] = "unbreakable_map_barrier:barrier"}, {["x"] = 1, ["y"] = 63, ["param1"] = 15, ["z"] = 0, ["name"] = "unbreakable_map_barrier:barrier"}, {["x"] = 1, ["y"] = 64, ["param1"] = 15, ["z"] = 0, ["name"] = "unbreakable_map_barrier:barrier"}, {["x"] = 1, ["y"] = 65, ["param1"] = 15, ["z"] = 0, ["name"] = "unbreakable_map_barrier:barrier"}, {["x"] = 1, ["y"] = 66, ["param1"] = 15, ["z"] = 0, ["name"] = "unbreakable_map_barrier:barrier"}, {["x"] = 1, ["y"] = 67, ["param1"] = 15, ["z"] = 0, ["name"] = "unbreakable_map_barrier:barrier"}, {["x"] = 1, ["y"] = 68, ["param1"] = 15, ["z"] = 0, ["name"] = "unbreakable_map_barrier:barrier"}, {["x"] = 1, ["y"] = 69, ["param1"] = 15, ["z"] = 0, ["name"] = "unbreakable_map_barrier:barrier"}, {["x"] = 1, ["y"] = 70, ["param1"] = 15, ["z"] = 0, ["name"] = "unbreakable_map_barrier:barrier"}, {["x"] = 1, ["y"] = 71, ["param1"] = 15, ["z"] = 0, ["name"] = "unbreakable_map_barrier:barrier"}, {["x"] = 1, ["y"] = 72, ["param1"] = 15, ["z"] = 0, ["name"] = "unbreakable_map_barrier:barrier"}, {["x"] = 1, ["y"] = 73, ["param1"] = 15, ["z"] = 0, ["name"] = "unbreakable_map_barrier:barrier"}, {["x"] = 1, ["y"] = 74, ["param1"] = 15, ["z"] = 0, ["name"] = "unbreakable_map_barrier:barrier"}, {["x"] = 1, ["y"] = 75, ["param1"] = 15, ["z"] = 0, ["name"] = "unbreakable_map_barrier:barrier"}, {["x"] = 1, ["y"] = 76, ["param1"] = 15, ["z"] = 0, ["name"] = "unbreakable_map_barrier:barrier"}, {["x"] = 1, ["y"] = 77, ["param1"] = 15, ["z"] = 0, ["name"] = "unbreakable_map_barrier:barrier"}, {["x"] = 1, ["y"] = 78, ["param1"] = 15, ["z"] = 0, ["name"] = "unbreakable_map_barrier:barrier"}, {["x"] = 1, ["y"] = 79, ["param1"] = 15, ["z"] = 0, ["name"] = "unbreakable_map_barrier:barrier"}, {["x"] = 1, ["y"] = 80, ["param1"] = 15, ["z"] = 0, ["name"] = "unbreakable_map_barrier:barrier"}, {["x"] = 1, ["y"] = 80, ["param1"] = 15, ["z"] = 1, ["name"] = "unbreakable_map_barrier:barrier"}, {["x"] = 1, ["y"] = 80, ["param1"] = 15, ["z"] = 2, ["name"] = "unbreakable_map_barrier:barrier"}, {["x"] = 1, ["y"] = 80, ["param1"] = 15, ["z"] = 3, ["name"] = "unbreakable_map_barrier:barrier"}, {["x"] = 1, ["y"] = 80, ["param1"] = 15, ["z"] = 4, ["name"] = "unbreakable_map_barrier:barrier"}, {["x"] = 1, ["y"] = 80, ["param1"] = 15, ["z"] = 5, ["name"] = "unbreakable_map_barrier:barrier"}, {["x"] = 1, ["y"] = 80, ["param1"] = 15, ["z"] = 6, ["name"] = "unbreakable_map_barrier:barrier"}, {["x"] = 1, ["y"] = 80, ["param1"] = 15, ["z"] = 7, ["name"] = "unbreakable_map_barrier:barrier"}, {["x"] = 1, ["y"] = 80, ["param1"] = 15, ["z"] = 8, ["name"] = "unbreakable_map_barrier:barrier"}, {["x"] = 1, ["y"] = 80, ["param1"] = 15, ["z"] = 9, ["name"] = "unbreakable_map_barrier:barrier"}, {["x"] = 1, ["y"] = 80, ["param1"] = 15, ["z"] = 10, ["name"] = "unbreakable_map_barrier:barrier"}, {["x"] = 1, ["y"] = 80, ["param1"] = 15, ["z"] = 11, ["name"] = "unbreakable_map_barrier:barrier"}, {["x"] = 1, ["y"] = 80, ["param1"] = 15, ["z"] = 12, ["name"] = "unbreakable_map_barrier:barrier"}, {["x"] = 1, ["y"] = 80, ["param1"] = 15, ["z"] = 13, ["name"] = "unbreakable_map_barrier:barrier"}, {["x"] = 1, ["y"] = 80, ["param1"] = 15, ["z"] = 14, ["name"] = "unbreakable_map_barrier:barrier"}, {["x"] = 1, ["y"] = 80, ["param1"] = 15, ["z"] = 15, ["name"] = "unbreakable_map_barrier:barrier"}, {["x"] = 1, ["y"] = 80, ["param1"] = 15, ["z"] = 16, ["name"] = "unbreakable_map_barrier:barrier"}, {["x"] = 1, ["y"] = 80, ["param1"] = 15, ["z"] = 17, ["name"] = "unbreakable_map_barrier:barrier"}, {["x"] = 1, ["y"] = 80, ["param1"] = 15, ["z"] = 18, ["name"] = "unbreakable_map_barrier:barrier"}, {["x"] = 1, ["y"] = 80, ["param1"] = 15, ["z"] = 19, ["name"] = "unbreakable_map_barrier:barrier"}, {["x"] = 1, ["y"] = 80, ["param1"] = 15, ["z"] = 20, ["name"] = "unbreakable_map_barrier:barrier"}, {["x"] = 1, ["y"] = 80, ["param1"] = 15, ["z"] = 21, ["name"] = "unbreakable_map_barrier:barrier"}, {["x"] = 1, ["y"] = 80, ["param1"] = 15, ["z"] = 22, ["name"] = "unbreakable_map_barrier:barrier"}, {["x"] = 1, ["y"] = 80, ["param1"] = 15, ["z"] = 23, ["name"] = "unbreakable_map_barrier:barrier"}, {["x"] = 1, ["y"] = 80, ["param1"] = 15, ["z"] = 24, ["name"] = "unbreakable_map_barrier:barrier"}, {["x"] = 1, ["y"] = 80, ["param1"] = 15, ["z"] = 25, ["name"] = "unbreakable_map_barrier:barrier"}, {["x"] = 1, ["y"] = 80, ["param1"] = 15, ["z"] = 26, ["name"] = "unbreakable_map_barrier:barrier"}, {["x"] = 1, ["y"] = 80, ["param1"] = 15, ["z"] = 27, ["name"] = "unbreakable_map_barrier:barrier"}, {["x"] = 1, ["y"] = 80, ["param1"] = 15, ["z"] = 28, ["name"] = "unbreakable_map_barrier:barrier"}, {["x"] = 1, ["y"] = 80, ["param1"] = 15, ["z"] = 29, ["name"] = "unbreakable_map_barrier:barrier"}, {["x"] = 1, ["y"] = 80, ["param1"] = 15, ["z"] = 30, ["name"] = "unbreakable_map_barrier:barrier"}, {["x"] = 1, ["y"] = 80, ["param1"] = 15, ["z"] = 31, ["name"] = "unbreakable_map_barrier:barrier"}, {["x"] = 1, ["y"] = 80, ["param1"] = 15, ["z"] = 32, ["name"] = "unbreakable_map_barrier:barrier"}, {["x"] = 1, ["y"] = 80, ["param1"] = 15, ["z"] = 33, ["name"] = "unbreakable_map_barrier:barrier"}, {["x"] = 1, ["y"] = 80, ["param1"] = 15, ["z"] = 34, ["name"] = "unbreakable_map_barrier:barrier"}, {["x"] = 1, ["y"] = 80, ["param1"] = 15, ["z"] = 35, ["name"] = "unbreakable_map_barrier:barrier"}, {["x"] = 1, ["y"] = 80, ["param1"] = 15, ["z"] = 36, ["name"] = "unbreakable_map_barrier:barrier"}, {["x"] = 1, ["y"] = 80, ["param1"] = 15, ["z"] = 37, ["name"] = "unbreakable_map_barrier:barrier"}, {["x"] = 1, ["y"] = 80, ["param1"] = 15, ["z"] = 38, ["name"] = "unbreakable_map_barrier:barrier"}, {["x"] = 1, ["y"] = 80, ["param1"] = 15, ["z"] = 39, ["name"] = "unbreakable_map_barrier:barrier"}, {["x"] = 1, ["y"] = 80, ["param1"] = 15, ["z"] = 40, ["name"] = "unbreakable_map_barrier:barrier"}, {["x"] = 1, ["y"] = 80, ["param1"] = 15, ["z"] = 41, ["name"] = "unbreakable_map_barrier:barrier"}, {["x"] = 1, ["y"] = 80, ["param1"] = 15, ["z"] = 42, ["name"] = "unbreakable_map_barrier:barrier"}, {["x"] = 1, ["y"] = 80, ["param1"] = 15, ["z"] = 43, ["name"] = "unbreakable_map_barrier:barrier"}, {["x"] = 1, ["y"] = 80, ["param1"] = 15, ["z"] = 44, ["name"] = "unbreakable_map_barrier:barrier"}, {["x"] = 1, ["y"] = 80, ["param1"] = 15, ["z"] = 45, ["name"] = "unbreakable_map_barrier:barrier"}, {["x"] = 1, ["y"] = 80, ["param1"] = 15, ["z"] = 46, ["name"] = "unbreakable_map_barrier:barrier"}, {["x"] = 1, ["y"] = 80, ["param1"] = 15, ["z"] = 47, ["name"] = "unbreakable_map_barrier:barrier"}, {["x"] = 1, ["y"] = 80, ["param1"] = 15, ["z"] = 48, ["name"] = "unbreakable_map_barrier:barrier"}, {["x"] = 1, ["y"] = 80, ["param1"] = 15, ["z"] = 49, ["name"] = "unbreakable_map_barrier:barrier"}, {["x"] = 1, ["y"] = 80, ["param1"] = 15, ["z"] = 50, ["name"] = "unbreakable_map_barrier:barrier"}, {["x"] = 1, ["y"] = 80, ["param1"] = 15, ["z"] = 51, ["name"] = "unbreakable_map_barrier:barrier"}, {["x"] = 1, ["y"] = 80, ["param1"] = 15, ["z"] = 52, ["name"] = "unbreakable_map_barrier:barrier"}, {["x"] = 1, ["y"] = 80, ["param1"] = 15, ["z"] = 53, ["name"] = "unbreakable_map_barrier:barrier"}, {["x"] = 1, ["y"] = 80, ["param1"] = 15, ["z"] = 54, ["name"] = "unbreakable_map_barrier:barrier"}, {["x"] = 1, ["y"] = 80, ["param1"] = 15, ["z"] = 55, ["name"] = "unbreakable_map_barrier:barrier"}, {["x"] = 1, ["y"] = 80, ["param1"] = 15, ["z"] = 56, ["name"] = "unbreakable_map_barrier:barrier"}, {["x"] = 1, ["y"] = 80, ["param1"] = 15, ["z"] = 57, ["name"] = "unbreakable_map_barrier:barrier"}, {["x"] = 1, ["y"] = 80, ["param1"] = 15, ["z"] = 58, ["name"] = "unbreakable_map_barrier:barrier"}, {["x"] = 1, ["y"] = 80, ["param1"] = 15, ["z"] = 59, ["name"] = "unbreakable_map_barrier:barrier"}, {["x"] = 1, ["y"] = 80, ["param1"] = 15, ["z"] = 60, ["name"] = "unbreakable_map_barrier:barrier"}, {["x"] = 1, ["y"] = 80, ["param1"] = 15, ["z"] = 61, ["name"] = "unbreakable_map_barrier:barrier"}, {["x"] = 1, ["y"] = 80, ["param1"] = 15, ["z"] = 62, ["name"] = "unbreakable_map_barrier:barrier"}, {["x"] = 1, ["y"] = 80, ["param1"] = 15, ["z"] = 63, ["name"] = "unbreakable_map_barrier:barrier"}, {["x"] = 1, ["y"] = 80, ["param1"] = 15, ["z"] = 64, ["name"] = "unbreakable_map_barrier:barrier"}, {["x"] = 1, ["y"] = 80, ["param1"] = 15, ["z"] = 65, ["name"] = "unbreakable_map_barrier:barrier"}, {["x"] = 1, ["y"] = 80, ["param1"] = 15, ["z"] = 66, ["name"] = "unbreakable_map_barrier:barrier"}, {["x"] = 1, ["y"] = 80, ["param1"] = 15, ["z"] = 67, ["name"] = "unbreakable_map_barrier:barrier"}, {["x"] = 1, ["y"] = 80, ["param1"] = 15, ["z"] = 68, ["name"] = "unbreakable_map_barrier:barrier"}, {["x"] = 1, ["y"] = 80, ["param1"] = 15, ["z"] = 69, ["name"] = "unbreakable_map_barrier:barrier"}, {["x"] = 1, ["y"] = 80, ["param1"] = 15, ["z"] = 70, ["name"] = "unbreakable_map_barrier:barrier"}, {["x"] = 1, ["y"] = 80, ["param1"] = 15, ["z"] = 71, ["name"] = "unbreakable_map_barrier:barrier"}, {["x"] = 1, ["y"] = 80, ["param1"] = 15, ["z"] = 72, ["name"] = "unbreakable_map_barrier:barrier"}, {["x"] = 1, ["y"] = 80, ["param1"] = 15, ["z"] = 73, ["name"] = "unbreakable_map_barrier:barrier"}, {["x"] = 1, ["y"] = 80, ["param1"] = 15, ["z"] = 74, ["name"] = "unbreakable_map_barrier:barrier"}, {["x"] = 1, ["y"] = 80, ["param1"] = 15, ["z"] = 75, ["name"] = "unbreakable_map_barrier:barrier"}, {["x"] = 1, ["y"] = 80, ["param1"] = 15, ["z"] = 76, ["name"] = "unbreakable_map_barrier:barrier"}, {["x"] = 1, ["y"] = 80, ["param1"] = 15, ["z"] = 77, ["name"] = "unbreakable_map_barrier:barrier"}, {["x"] = 1, ["y"] = 80, ["param1"] = 15, ["z"] = 78, ["name"] = "unbreakable_map_barrier:barrier"}, {["x"] = 1, ["y"] = 80, ["param1"] = 15, ["z"] = 79, ["name"] = "unbreakable_map_barrier:barrier"}, {["x"] = 1, ["y"] = 80, ["param1"] = 15, ["z"] = 80, ["name"] = "unbreakable_map_barrier:barrier"}, {["x"] = 2, ["y"] = 0, ["param1"] = 15, ["z"] = 0, ["name"] = "unbreakable_map_barrier:barrier"}, {["x"] = 2, ["y"] = 1, ["param1"] = 15, ["z"] = 0, ["name"] = "unbreakable_map_barrier:barrier"}, {["x"] = 2, ["y"] = 2, ["param1"] = 15, ["z"] = 0, ["name"] = "unbreakable_map_barrier:barrier"}, {["x"] = 2, ["y"] = 3, ["param1"] = 15, ["z"] = 0, ["name"] = "unbreakable_map_barrier:barrier"}, {["x"] = 2, ["y"] = 4, ["param1"] = 15, ["z"] = 0, ["name"] = "unbreakable_map_barrier:barrier"}, {["x"] = 2, ["y"] = 5, ["param1"] = 15, ["z"] = 0, ["name"] = "unbreakable_map_barrier:barrier"}, {["x"] = 2, ["y"] = 6, ["param1"] = 15, ["z"] = 0, ["name"] = "unbreakable_map_barrier:barrier"}, {["x"] = 2, ["y"] = 7, ["param1"] = 15, ["z"] = 0, ["name"] = "unbreakable_map_barrier:barrier"}, {["x"] = 2, ["y"] = 8, ["param1"] = 15, ["z"] = 0, ["name"] = "unbreakable_map_barrier:barrier"}, {["x"] = 2, ["y"] = 9, ["param1"] = 15, ["z"] = 0, ["name"] = "unbreakable_map_barrier:barrier"}, {["x"] = 2, ["y"] = 10, ["param1"] = 15, ["z"] = 0, ["name"] = "unbreakable_map_barrier:barrier"}, {["x"] = 2, ["y"] = 11, ["param1"] = 15, ["z"] = 0, ["name"] = "unbreakable_map_barrier:barrier"}, {["x"] = 2, ["y"] = 12, ["param1"] = 15, ["z"] = 0, ["name"] = "unbreakable_map_barrier:barrier"}, {["x"] = 2, ["y"] = 13, ["param1"] = 15, ["z"] = 0, ["name"] = "unbreakable_map_barrier:barrier"}, {["x"] = 2, ["y"] = 14, ["param1"] = 15, ["z"] = 0, ["name"] = "unbreakable_map_barrier:barrier"}, {["x"] = 2, ["y"] = 15, ["param1"] = 15, ["z"] = 0, ["name"] = "unbreakable_map_barrier:barrier"}, {["x"] = 2, ["y"] = 16, ["param1"] = 15, ["z"] = 0, ["name"] = "unbreakable_map_barrier:barrier"}, {["x"] = 2, ["y"] = 17, ["param1"] = 15, ["z"] = 0, ["name"] = "unbreakable_map_barrier:barrier"}, {["x"] = 2, ["y"] = 18, ["param1"] = 15, ["z"] = 0, ["name"] = "unbreakable_map_barrier:barrier"}, {["x"] = 2, ["y"] = 19, ["param1"] = 15, ["z"] = 0, ["name"] = "unbreakable_map_barrier:barrier"}, {["x"] = 2, ["y"] = 20, ["param1"] = 15, ["z"] = 0, ["name"] = "unbreakable_map_barrier:barrier"}, {["x"] = 2, ["y"] = 21, ["param1"] = 15, ["z"] = 0, ["name"] = "unbreakable_map_barrier:barrier"}, {["x"] = 2, ["y"] = 22, ["param1"] = 15, ["z"] = 0, ["name"] = "unbreakable_map_barrier:barrier"}, {["x"] = 2, ["y"] = 23, ["param1"] = 15, ["z"] = 0, ["name"] = "unbreakable_map_barrier:barrier"}, {["x"] = 2, ["y"] = 24, ["param1"] = 15, ["z"] = 0, ["name"] = "unbreakable_map_barrier:barrier"}, {["x"] = 2, ["y"] = 25, ["param1"] = 15, ["z"] = 0, ["name"] = "unbreakable_map_barrier:barrier"}, {["x"] = 2, ["y"] = 26, ["param1"] = 15, ["z"] = 0, ["name"] = "unbreakable_map_barrier:barrier"}, {["x"] = 2, ["y"] = 27, ["param1"] = 15, ["z"] = 0, ["name"] = "unbreakable_map_barrier:barrier"}, {["x"] = 2, ["y"] = 28, ["param1"] = 15, ["z"] = 0, ["name"] = "unbreakable_map_barrier:barrier"}, {["x"] = 2, ["y"] = 29, ["param1"] = 15, ["z"] = 0, ["name"] = "unbreakable_map_barrier:barrier"}, {["x"] = 2, ["y"] = 30, ["param1"] = 15, ["z"] = 0, ["name"] = "unbreakable_map_barrier:barrier"}, {["x"] = 2, ["y"] = 31, ["param1"] = 15, ["z"] = 0, ["name"] = "unbreakable_map_barrier:barrier"}, {["x"] = 2, ["y"] = 32, ["param1"] = 15, ["z"] = 0, ["name"] = "unbreakable_map_barrier:barrier"}, {["x"] = 2, ["y"] = 33, ["param1"] = 15, ["z"] = 0, ["name"] = "unbreakable_map_barrier:barrier"}, {["x"] = 2, ["y"] = 34, ["param1"] = 15, ["z"] = 0, ["name"] = "unbreakable_map_barrier:barrier"}, {["x"] = 2, ["y"] = 35, ["param1"] = 15, ["z"] = 0, ["name"] = "unbreakable_map_barrier:barrier"}, {["x"] = 2, ["y"] = 36, ["param1"] = 15, ["z"] = 0, ["name"] = "unbreakable_map_barrier:barrier"}, {["x"] = 2, ["y"] = 37, ["param1"] = 15, ["z"] = 0, ["name"] = "unbreakable_map_barrier:barrier"}, {["x"] = 2, ["y"] = 38, ["param1"] = 15, ["z"] = 0, ["name"] = "unbreakable_map_barrier:barrier"}, {["x"] = 2, ["y"] = 39, ["param1"] = 15, ["z"] = 0, ["name"] = "unbreakable_map_barrier:barrier"}, {["x"] = 2, ["y"] = 40, ["param1"] = 15, ["z"] = 0, ["name"] = "unbreakable_map_barrier:barrier"}, {["x"] = 2, ["y"] = 41, ["param1"] = 15, ["z"] = 0, ["name"] = "unbreakable_map_barrier:barrier"}, {["x"] = 2, ["y"] = 42, ["param1"] = 15, ["z"] = 0, ["name"] = "unbreakable_map_barrier:barrier"}, {["x"] = 2, ["y"] = 43, ["param1"] = 15, ["z"] = 0, ["name"] = "unbreakable_map_barrier:barrier"}, {["x"] = 2, ["y"] = 44, ["param1"] = 15, ["z"] = 0, ["name"] = "unbreakable_map_barrier:barrier"}, {["x"] = 2, ["y"] = 45, ["param1"] = 15, ["z"] = 0, ["name"] = "unbreakable_map_barrier:barrier"}, {["x"] = 2, ["y"] = 46, ["param1"] = 15, ["z"] = 0, ["name"] = "unbreakable_map_barrier:barrier"}, {["x"] = 2, ["y"] = 47, ["param1"] = 15, ["z"] = 0, ["name"] = "unbreakable_map_barrier:barrier"}, {["x"] = 2, ["y"] = 48, ["param1"] = 15, ["z"] = 0, ["name"] = "unbreakable_map_barrier:barrier"}, {["x"] = 2, ["y"] = 49, ["param1"] = 15, ["z"] = 0, ["name"] = "unbreakable_map_barrier:barrier"}, {["x"] = 2, ["y"] = 50, ["param1"] = 15, ["z"] = 0, ["name"] = "unbreakable_map_barrier:barrier"}, {["x"] = 2, ["y"] = 51, ["param1"] = 15, ["z"] = 0, ["name"] = "unbreakable_map_barrier:barrier"}, {["x"] = 2, ["y"] = 52, ["param1"] = 15, ["z"] = 0, ["name"] = "unbreakable_map_barrier:barrier"}, {["x"] = 2, ["y"] = 53, ["param1"] = 15, ["z"] = 0, ["name"] = "unbreakable_map_barrier:barrier"}, {["x"] = 2, ["y"] = 54, ["param1"] = 15, ["z"] = 0, ["name"] = "unbreakable_map_barrier:barrier"}, {["x"] = 2, ["y"] = 55, ["param1"] = 15, ["z"] = 0, ["name"] = "unbreakable_map_barrier:barrier"}, {["x"] = 2, ["y"] = 56, ["param1"] = 15, ["z"] = 0, ["name"] = "unbreakable_map_barrier:barrier"}, {["x"] = 2, ["y"] = 57, ["param1"] = 15, ["z"] = 0, ["name"] = "unbreakable_map_barrier:barrier"}, {["x"] = 2, ["y"] = 58, ["param1"] = 15, ["z"] = 0, ["name"] = "unbreakable_map_barrier:barrier"}, {["x"] = 2, ["y"] = 59, ["param1"] = 15, ["z"] = 0, ["name"] = "unbreakable_map_barrier:barrier"}, {["x"] = 2, ["y"] = 60, ["param1"] = 15, ["z"] = 0, ["name"] = "unbreakable_map_barrier:barrier"}, {["x"] = 2, ["y"] = 61, ["param1"] = 15, ["z"] = 0, ["name"] = "unbreakable_map_barrier:barrier"}, {["x"] = 2, ["y"] = 62, ["param1"] = 15, ["z"] = 0, ["name"] = "unbreakable_map_barrier:barrier"}, {["x"] = 2, ["y"] = 63, ["param1"] = 15, ["z"] = 0, ["name"] = "unbreakable_map_barrier:barrier"}, {["x"] = 2, ["y"] = 64, ["param1"] = 15, ["z"] = 0, ["name"] = "unbreakable_map_barrier:barrier"}, {["x"] = 2, ["y"] = 65, ["param1"] = 15, ["z"] = 0, ["name"] = "unbreakable_map_barrier:barrier"}, {["x"] = 2, ["y"] = 66, ["param1"] = 15, ["z"] = 0, ["name"] = "unbreakable_map_barrier:barrier"}, {["x"] = 2, ["y"] = 67, ["param1"] = 15, ["z"] = 0, ["name"] = "unbreakable_map_barrier:barrier"}, {["x"] = 2, ["y"] = 68, ["param1"] = 15, ["z"] = 0, ["name"] = "unbreakable_map_barrier:barrier"}, {["x"] = 2, ["y"] = 69, ["param1"] = 15, ["z"] = 0, ["name"] = "unbreakable_map_barrier:barrier"}, {["x"] = 2, ["y"] = 70, ["param1"] = 15, ["z"] = 0, ["name"] = "unbreakable_map_barrier:barrier"}, {["x"] = 2, ["y"] = 71, ["param1"] = 15, ["z"] = 0, ["name"] = "unbreakable_map_barrier:barrier"}, {["x"] = 2, ["y"] = 72, ["param1"] = 15, ["z"] = 0, ["name"] = "unbreakable_map_barrier:barrier"}, {["x"] = 2, ["y"] = 73, ["param1"] = 15, ["z"] = 0, ["name"] = "unbreakable_map_barrier:barrier"}, {["x"] = 2, ["y"] = 74, ["param1"] = 15, ["z"] = 0, ["name"] = "unbreakable_map_barrier:barrier"}, {["x"] = 2, ["y"] = 75, ["param1"] = 15, ["z"] = 0, ["name"] = "unbreakable_map_barrier:barrier"}, {["x"] = 2, ["y"] = 76, ["param1"] = 15, ["z"] = 0, ["name"] = "unbreakable_map_barrier:barrier"}, {["x"] = 2, ["y"] = 77, ["param1"] = 15, ["z"] = 0, ["name"] = "unbreakable_map_barrier:barrier"}, {["x"] = 2, ["y"] = 78, ["param1"] = 15, ["z"] = 0, ["name"] = "unbreakable_map_barrier:barrier"}, {["x"] = 2, ["y"] = 79, ["param1"] = 15, ["z"] = 0, ["name"] = "unbreakable_map_barrier:barrier"}, {["x"] = 2, ["y"] = 80, ["param1"] = 15, ["z"] = 0, ["name"] = "unbreakable_map_barrier:barrier"}, {["x"] = 2, ["y"] = 80, ["param1"] = 15, ["z"] = 1, ["name"] = "unbreakable_map_barrier:barrier"}, {["x"] = 2, ["y"] = 80, ["param1"] = 15, ["z"] = 2, ["name"] = "unbreakable_map_barrier:barrier"}, {["x"] = 2, ["y"] = 80, ["param1"] = 15, ["z"] = 3, ["name"] = "unbreakable_map_barrier:barrier"}, {["x"] = 2, ["y"] = 80, ["param1"] = 15, ["z"] = 4, ["name"] = "unbreakable_map_barrier:barrier"}, {["x"] = 2, ["y"] = 80, ["param1"] = 15, ["z"] = 5, ["name"] = "unbreakable_map_barrier:barrier"}, {["x"] = 2, ["y"] = 80, ["param1"] = 15, ["z"] = 6, ["name"] = "unbreakable_map_barrier:barrier"}, {["x"] = 2, ["y"] = 80, ["param1"] = 15, ["z"] = 7, ["name"] = "unbreakable_map_barrier:barrier"}, {["x"] = 2, ["y"] = 80, ["param1"] = 15, ["z"] = 8, ["name"] = "unbreakable_map_barrier:barrier"}, {["x"] = 2, ["y"] = 80, ["param1"] = 15, ["z"] = 9, ["name"] = "unbreakable_map_barrier:barrier"}, {["x"] = 2, ["y"] = 80, ["param1"] = 15, ["z"] = 10, ["name"] = "unbreakable_map_barrier:barrier"}, {["x"] = 2, ["y"] = 80, ["param1"] = 15, ["z"] = 11, ["name"] = "unbreakable_map_barrier:barrier"}, {["x"] = 2, ["y"] = 80, ["param1"] = 15, ["z"] = 12, ["name"] = "unbreakable_map_barrier:barrier"}, {["x"] = 2, ["y"] = 80, ["param1"] = 15, ["z"] = 13, ["name"] = "unbreakable_map_barrier:barrier"}, {["x"] = 2, ["y"] = 80, ["param1"] = 15, ["z"] = 14, ["name"] = "unbreakable_map_barrier:barrier"}, {["x"] = 2, ["y"] = 80, ["param1"] = 15, ["z"] = 15, ["name"] = "unbreakable_map_barrier:barrier"}, {["x"] = 2, ["y"] = 80, ["param1"] = 15, ["z"] = 16, ["name"] = "unbreakable_map_barrier:barrier"}, {["x"] = 2, ["y"] = 80, ["param1"] = 15, ["z"] = 17, ["name"] = "unbreakable_map_barrier:barrier"}, {["x"] = 2, ["y"] = 80, ["param1"] = 15, ["z"] = 18, ["name"] = "unbreakable_map_barrier:barrier"}, {["x"] = 2, ["y"] = 80, ["param1"] = 15, ["z"] = 19, ["name"] = "unbreakable_map_barrier:barrier"}, {["x"] = 2, ["y"] = 80, ["param1"] = 15, ["z"] = 20, ["name"] = "unbreakable_map_barrier:barrier"}, {["x"] = 2, ["y"] = 80, ["param1"] = 15, ["z"] = 21, ["name"] = "unbreakable_map_barrier:barrier"}, {["x"] = 2, ["y"] = 80, ["param1"] = 15, ["z"] = 22, ["name"] = "unbreakable_map_barrier:barrier"}, {["x"] = 2, ["y"] = 80, ["param1"] = 15, ["z"] = 23, ["name"] = "unbreakable_map_barrier:barrier"}, {["x"] = 2, ["y"] = 80, ["param1"] = 15, ["z"] = 24, ["name"] = "unbreakable_map_barrier:barrier"}, {["x"] = 2, ["y"] = 80, ["param1"] = 15, ["z"] = 25, ["name"] = "unbreakable_map_barrier:barrier"}, {["x"] = 2, ["y"] = 80, ["param1"] = 15, ["z"] = 26, ["name"] = "unbreakable_map_barrier:barrier"}, {["x"] = 2, ["y"] = 80, ["param1"] = 15, ["z"] = 27, ["name"] = "unbreakable_map_barrier:barrier"}, {["x"] = 2, ["y"] = 80, ["param1"] = 15, ["z"] = 28, ["name"] = "unbreakable_map_barrier:barrier"}, {["x"] = 2, ["y"] = 80, ["param1"] = 15, ["z"] = 29, ["name"] = "unbreakable_map_barrier:barrier"}, {["x"] = 2, ["y"] = 80, ["param1"] = 15, ["z"] = 30, ["name"] = "unbreakable_map_barrier:barrier"}, {["x"] = 2, ["y"] = 80, ["param1"] = 15, ["z"] = 31, ["name"] = "unbreakable_map_barrier:barrier"}, {["x"] = 2, ["y"] = 80, ["param1"] = 15, ["z"] = 32, ["name"] = "unbreakable_map_barrier:barrier"}, {["x"] = 2, ["y"] = 80, ["param1"] = 15, ["z"] = 33, ["name"] = "unbreakable_map_barrier:barrier"}, {["x"] = 2, ["y"] = 80, ["param1"] = 15, ["z"] = 34, ["name"] = "unbreakable_map_barrier:barrier"}, {["x"] = 2, ["y"] = 80, ["param1"] = 15, ["z"] = 35, ["name"] = "unbreakable_map_barrier:barrier"}, {["x"] = 2, ["y"] = 80, ["param1"] = 15, ["z"] = 36, ["name"] = "unbreakable_map_barrier:barrier"}, {["x"] = 2, ["y"] = 80, ["param1"] = 15, ["z"] = 37, ["name"] = "unbreakable_map_barrier:barrier"}, {["x"] = 2, ["y"] = 80, ["param1"] = 15, ["z"] = 38, ["name"] = "unbreakable_map_barrier:barrier"}, {["x"] = 2, ["y"] = 80, ["param1"] = 15, ["z"] = 39, ["name"] = "unbreakable_map_barrier:barrier"}, {["x"] = 2, ["y"] = 80, ["param1"] = 15, ["z"] = 40, ["name"] = "unbreakable_map_barrier:barrier"}, {["x"] = 2, ["y"] = 80, ["param1"] = 15, ["z"] = 41, ["name"] = "unbreakable_map_barrier:barrier"}, {["x"] = 2, ["y"] = 80, ["param1"] = 15, ["z"] = 42, ["name"] = "unbreakable_map_barrier:barrier"}, {["x"] = 2, ["y"] = 80, ["param1"] = 15, ["z"] = 43, ["name"] = "unbreakable_map_barrier:barrier"}, {["x"] = 2, ["y"] = 80, ["param1"] = 15, ["z"] = 44, ["name"] = "unbreakable_map_barrier:barrier"}, {["x"] = 2, ["y"] = 80, ["param1"] = 15, ["z"] = 45, ["name"] = "unbreakable_map_barrier:barrier"}, {["x"] = 2, ["y"] = 80, ["param1"] = 15, ["z"] = 46, ["name"] = "unbreakable_map_barrier:barrier"}, {["x"] = 2, ["y"] = 80, ["param1"] = 15, ["z"] = 47, ["name"] = "unbreakable_map_barrier:barrier"}, {["x"] = 2, ["y"] = 80, ["param1"] = 15, ["z"] = 48, ["name"] = "unbreakable_map_barrier:barrier"}, {["x"] = 2, ["y"] = 80, ["param1"] = 15, ["z"] = 49, ["name"] = "unbreakable_map_barrier:barrier"}, {["x"] = 2, ["y"] = 80, ["param1"] = 15, ["z"] = 50, ["name"] = "unbreakable_map_barrier:barrier"}, {["x"] = 2, ["y"] = 80, ["param1"] = 15, ["z"] = 51, ["name"] = "unbreakable_map_barrier:barrier"}, {["x"] = 2, ["y"] = 80, ["param1"] = 15, ["z"] = 52, ["name"] = "unbreakable_map_barrier:barrier"}, {["x"] = 2, ["y"] = 80, ["param1"] = 15, ["z"] = 53, ["name"] = "unbreakable_map_barrier:barrier"}, {["x"] = 2, ["y"] = 80, ["param1"] = 15, ["z"] = 54, ["name"] = "unbreakable_map_barrier:barrier"}, {["x"] = 2, ["y"] = 80, ["param1"] = 15, ["z"] = 55, ["name"] = "unbreakable_map_barrier:barrier"}, {["x"] = 2, ["y"] = 80, ["param1"] = 15, ["z"] = 56, ["name"] = "unbreakable_map_barrier:barrier"}, {["x"] = 2, ["y"] = 80, ["param1"] = 15, ["z"] = 57, ["name"] = "unbreakable_map_barrier:barrier"}, {["x"] = 2, ["y"] = 80, ["param1"] = 15, ["z"] = 58, ["name"] = "unbreakable_map_barrier:barrier"}, {["x"] = 2, ["y"] = 80, ["param1"] = 15, ["z"] = 59, ["name"] = "unbreakable_map_barrier:barrier"}, {["x"] = 2, ["y"] = 80, ["param1"] = 15, ["z"] = 60, ["name"] = "unbreakable_map_barrier:barrier"}, {["x"] = 2, ["y"] = 80, ["param1"] = 15, ["z"] = 61, ["name"] = "unbreakable_map_barrier:barrier"}, {["x"] = 2, ["y"] = 80, ["param1"] = 15, ["z"] = 62, ["name"] = "unbreakable_map_barrier:barrier"}, {["x"] = 2, ["y"] = 80, ["param1"] = 15, ["z"] = 63, ["name"] = "unbreakable_map_barrier:barrier"}, {["x"] = 2, ["y"] = 80, ["param1"] = 15, ["z"] = 64, ["name"] = "unbreakable_map_barrier:barrier"}, {["x"] = 2, ["y"] = 80, ["param1"] = 15, ["z"] = 65, ["name"] = "unbreakable_map_barrier:barrier"}, {["x"] = 2, ["y"] = 80, ["param1"] = 15, ["z"] = 66, ["name"] = "unbreakable_map_barrier:barrier"}, {["x"] = 2, ["y"] = 80, ["param1"] = 15, ["z"] = 67, ["name"] = "unbreakable_map_barrier:barrier"}, {["x"] = 2, ["y"] = 80, ["param1"] = 15, ["z"] = 68, ["name"] = "unbreakable_map_barrier:barrier"}, {["x"] = 2, ["y"] = 80, ["param1"] = 15, ["z"] = 69, ["name"] = "unbreakable_map_barrier:barrier"}, {["x"] = 2, ["y"] = 80, ["param1"] = 15, ["z"] = 70, ["name"] = "unbreakable_map_barrier:barrier"}, {["x"] = 2, ["y"] = 80, ["param1"] = 15, ["z"] = 71, ["name"] = "unbreakable_map_barrier:barrier"}, {["x"] = 2, ["y"] = 80, ["param1"] = 15, ["z"] = 72, ["name"] = "unbreakable_map_barrier:barrier"}, {["x"] = 2, ["y"] = 80, ["param1"] = 15, ["z"] = 73, ["name"] = "unbreakable_map_barrier:barrier"}, {["x"] = 2, ["y"] = 80, ["param1"] = 15, ["z"] = 74, ["name"] = "unbreakable_map_barrier:barrier"}, {["x"] = 2, ["y"] = 80, ["param1"] = 15, ["z"] = 75, ["name"] = "unbreakable_map_barrier:barrier"}, {["x"] = 2, ["y"] = 80, ["param1"] = 15, ["z"] = 76, ["name"] = "unbreakable_map_barrier:barrier"}, {["x"] = 2, ["y"] = 80, ["param1"] = 15, ["z"] = 77, ["name"] = "unbreakable_map_barrier:barrier"}, {["x"] = 2, ["y"] = 80, ["param1"] = 15, ["z"] = 78, ["name"] = "unbreakable_map_barrier:barrier"}, {["x"] = 2, ["y"] = 80, ["param1"] = 15, ["z"] = 79, ["name"] = "unbreakable_map_barrier:barrier"}, {["x"] = 2, ["y"] = 80, ["param1"] = 15, ["z"] = 80, ["name"] = "unbreakable_map_barrier:barrier"}, {["x"] = 3, ["y"] = 0, ["param1"] = 15, ["z"] = 0, ["name"] = "unbreakable_map_barrier:barrier"}, {["x"] = 3, ["y"] = 1, ["param1"] = 15, ["z"] = 0, ["name"] = "unbreakable_map_barrier:barrier"}, {["x"] = 3, ["y"] = 2, ["param1"] = 15, ["z"] = 0, ["name"] = "unbreakable_map_barrier:barrier"}, {["x"] = 3, ["y"] = 3, ["param1"] = 15, ["z"] = 0, ["name"] = "unbreakable_map_barrier:barrier"}, {["x"] = 3, ["y"] = 4, ["param1"] = 15, ["z"] = 0, ["name"] = "unbreakable_map_barrier:barrier"}, {["x"] = 3, ["y"] = 5, ["param1"] = 15, ["z"] = 0, ["name"] = "unbreakable_map_barrier:barrier"}, {["x"] = 3, ["y"] = 6, ["param1"] = 15, ["z"] = 0, ["name"] = "unbreakable_map_barrier:barrier"}, {["x"] = 3, ["y"] = 7, ["param1"] = 15, ["z"] = 0, ["name"] = "unbreakable_map_barrier:barrier"}, {["x"] = 3, ["y"] = 8, ["param1"] = 15, ["z"] = 0, ["name"] = "unbreakable_map_barrier:barrier"}, {["x"] = 3, ["y"] = 9, ["param1"] = 15, ["z"] = 0, ["name"] = "unbreakable_map_barrier:barrier"}, {["x"] = 3, ["y"] = 10, ["param1"] = 15, ["z"] = 0, ["name"] = "unbreakable_map_barrier:barrier"}, {["x"] = 3, ["y"] = 11, ["param1"] = 15, ["z"] = 0, ["name"] = "unbreakable_map_barrier:barrier"}, {["x"] = 3, ["y"] = 12, ["param1"] = 15, ["z"] = 0, ["name"] = "unbreakable_map_barrier:barrier"}, {["x"] = 3, ["y"] = 13, ["param1"] = 15, ["z"] = 0, ["name"] = "unbreakable_map_barrier:barrier"}, {["x"] = 3, ["y"] = 14, ["param1"] = 15, ["z"] = 0, ["name"] = "unbreakable_map_barrier:barrier"}, {["x"] = 3, ["y"] = 15, ["param1"] = 15, ["z"] = 0, ["name"] = "unbreakable_map_barrier:barrier"}, {["x"] = 3, ["y"] = 16, ["param1"] = 15, ["z"] = 0, ["name"] = "unbreakable_map_barrier:barrier"}, {["x"] = 3, ["y"] = 17, ["param1"] = 15, ["z"] = 0, ["name"] = "unbreakable_map_barrier:barrier"}, {["x"] = 3, ["y"] = 18, ["param1"] = 15, ["z"] = 0, ["name"] = "unbreakable_map_barrier:barrier"}, {["x"] = 3, ["y"] = 19, ["param1"] = 15, ["z"] = 0, ["name"] = "unbreakable_map_barrier:barrier"}, {["x"] = 3, ["y"] = 20, ["param1"] = 15, ["z"] = 0, ["name"] = "unbreakable_map_barrier:barrier"}, {["x"] = 3, ["y"] = 21, ["param1"] = 15, ["z"] = 0, ["name"] = "unbreakable_map_barrier:barrier"}, {["x"] = 3, ["y"] = 22, ["param1"] = 15, ["z"] = 0, ["name"] = "unbreakable_map_barrier:barrier"}, {["x"] = 3, ["y"] = 23, ["param1"] = 15, ["z"] = 0, ["name"] = "unbreakable_map_barrier:barrier"}, {["x"] = 3, ["y"] = 24, ["param1"] = 15, ["z"] = 0, ["name"] = "unbreakable_map_barrier:barrier"}, {["x"] = 3, ["y"] = 25, ["param1"] = 15, ["z"] = 0, ["name"] = "unbreakable_map_barrier:barrier"}, {["x"] = 3, ["y"] = 26, ["param1"] = 15, ["z"] = 0, ["name"] = "unbreakable_map_barrier:barrier"}, {["x"] = 3, ["y"] = 27, ["param1"] = 15, ["z"] = 0, ["name"] = "unbreakable_map_barrier:barrier"}, {["x"] = 3, ["y"] = 28, ["param1"] = 15, ["z"] = 0, ["name"] = "unbreakable_map_barrier:barrier"}, {["x"] = 3, ["y"] = 29, ["param1"] = 15, ["z"] = 0, ["name"] = "unbreakable_map_barrier:barrier"}, {["x"] = 3, ["y"] = 30, ["param1"] = 15, ["z"] = 0, ["name"] = "unbreakable_map_barrier:barrier"}, {["x"] = 3, ["y"] = 31, ["param1"] = 15, ["z"] = 0, ["name"] = "unbreakable_map_barrier:barrier"}, {["x"] = 3, ["y"] = 32, ["param1"] = 15, ["z"] = 0, ["name"] = "unbreakable_map_barrier:barrier"}, {["x"] = 3, ["y"] = 33, ["param1"] = 15, ["z"] = 0, ["name"] = "unbreakable_map_barrier:barrier"}, {["x"] = 3, ["y"] = 34, ["param1"] = 15, ["z"] = 0, ["name"] = "unbreakable_map_barrier:barrier"}, {["x"] = 3, ["y"] = 35, ["param1"] = 15, ["z"] = 0, ["name"] = "unbreakable_map_barrier:barrier"}, {["x"] = 3, ["y"] = 36, ["param1"] = 15, ["z"] = 0, ["name"] = "unbreakable_map_barrier:barrier"}, {["x"] = 3, ["y"] = 37, ["param1"] = 15, ["z"] = 0, ["name"] = "unbreakable_map_barrier:barrier"}, {["x"] = 3, ["y"] = 38, ["param1"] = 15, ["z"] = 0, ["name"] = "unbreakable_map_barrier:barrier"}, {["x"] = 3, ["y"] = 39, ["param1"] = 15, ["z"] = 0, ["name"] = "unbreakable_map_barrier:barrier"}, {["x"] = 3, ["y"] = 40, ["param1"] = 15, ["z"] = 0, ["name"] = "unbreakable_map_barrier:barrier"}, {["x"] = 3, ["y"] = 41, ["param1"] = 15, ["z"] = 0, ["name"] = "unbreakable_map_barrier:barrier"}, {["x"] = 3, ["y"] = 42, ["param1"] = 15, ["z"] = 0, ["name"] = "unbreakable_map_barrier:barrier"}, {["x"] = 3, ["y"] = 43, ["param1"] = 15, ["z"] = 0, ["name"] = "unbreakable_map_barrier:barrier"}, {["x"] = 3, ["y"] = 44, ["param1"] = 15, ["z"] = 0, ["name"] = "unbreakable_map_barrier:barrier"}, {["x"] = 3, ["y"] = 45, ["param1"] = 15, ["z"] = 0, ["name"] = "unbreakable_map_barrier:barrier"}, {["x"] = 3, ["y"] = 46, ["param1"] = 15, ["z"] = 0, ["name"] = "unbreakable_map_barrier:barrier"}, {["x"] = 3, ["y"] = 47, ["param1"] = 15, ["z"] = 0, ["name"] = "unbreakable_map_barrier:barrier"}, {["x"] = 3, ["y"] = 48, ["param1"] = 15, ["z"] = 0, ["name"] = "unbreakable_map_barrier:barrier"}, {["x"] = 3, ["y"] = 49, ["param1"] = 15, ["z"] = 0, ["name"] = "unbreakable_map_barrier:barrier"}, {["x"] = 3, ["y"] = 50, ["param1"] = 15, ["z"] = 0, ["name"] = "unbreakable_map_barrier:barrier"}, {["x"] = 3, ["y"] = 51, ["param1"] = 15, ["z"] = 0, ["name"] = "unbreakable_map_barrier:barrier"}, {["x"] = 3, ["y"] = 52, ["param1"] = 15, ["z"] = 0, ["name"] = "unbreakable_map_barrier:barrier"}, {["x"] = 3, ["y"] = 53, ["param1"] = 15, ["z"] = 0, ["name"] = "unbreakable_map_barrier:barrier"}, {["x"] = 3, ["y"] = 54, ["param1"] = 15, ["z"] = 0, ["name"] = "unbreakable_map_barrier:barrier"}, {["x"] = 3, ["y"] = 55, ["param1"] = 15, ["z"] = 0, ["name"] = "unbreakable_map_barrier:barrier"}, {["x"] = 3, ["y"] = 56, ["param1"] = 15, ["z"] = 0, ["name"] = "unbreakable_map_barrier:barrier"}, {["x"] = 3, ["y"] = 57, ["param1"] = 15, ["z"] = 0, ["name"] = "unbreakable_map_barrier:barrier"}, {["x"] = 3, ["y"] = 58, ["param1"] = 15, ["z"] = 0, ["name"] = "unbreakable_map_barrier:barrier"}, {["x"] = 3, ["y"] = 59, ["param1"] = 15, ["z"] = 0, ["name"] = "unbreakable_map_barrier:barrier"}, {["x"] = 3, ["y"] = 60, ["param1"] = 15, ["z"] = 0, ["name"] = "unbreakable_map_barrier:barrier"}, {["x"] = 3, ["y"] = 61, ["param1"] = 15, ["z"] = 0, ["name"] = "unbreakable_map_barrier:barrier"}, {["x"] = 3, ["y"] = 62, ["param1"] = 15, ["z"] = 0, ["name"] = "unbreakable_map_barrier:barrier"}, {["x"] = 3, ["y"] = 63, ["param1"] = 15, ["z"] = 0, ["name"] = "unbreakable_map_barrier:barrier"}, {["x"] = 3, ["y"] = 64, ["param1"] = 15, ["z"] = 0, ["name"] = "unbreakable_map_barrier:barrier"}, {["x"] = 3, ["y"] = 65, ["param1"] = 15, ["z"] = 0, ["name"] = "unbreakable_map_barrier:barrier"}, {["x"] = 3, ["y"] = 66, ["param1"] = 15, ["z"] = 0, ["name"] = "unbreakable_map_barrier:barrier"}, {["x"] = 3, ["y"] = 67, ["param1"] = 15, ["z"] = 0, ["name"] = "unbreakable_map_barrier:barrier"}, {["x"] = 3, ["y"] = 68, ["param1"] = 15, ["z"] = 0, ["name"] = "unbreakable_map_barrier:barrier"}, {["x"] = 3, ["y"] = 69, ["param1"] = 15, ["z"] = 0, ["name"] = "unbreakable_map_barrier:barrier"}, {["x"] = 3, ["y"] = 70, ["param1"] = 15, ["z"] = 0, ["name"] = "unbreakable_map_barrier:barrier"}, {["x"] = 3, ["y"] = 71, ["param1"] = 15, ["z"] = 0, ["name"] = "unbreakable_map_barrier:barrier"}, {["x"] = 3, ["y"] = 72, ["param1"] = 15, ["z"] = 0, ["name"] = "unbreakable_map_barrier:barrier"}, {["x"] = 3, ["y"] = 73, ["param1"] = 15, ["z"] = 0, ["name"] = "unbreakable_map_barrier:barrier"}, {["x"] = 3, ["y"] = 74, ["param1"] = 15, ["z"] = 0, ["name"] = "unbreakable_map_barrier:barrier"}, {["x"] = 3, ["y"] = 75, ["param1"] = 15, ["z"] = 0, ["name"] = "unbreakable_map_barrier:barrier"}, {["x"] = 3, ["y"] = 76, ["param1"] = 15, ["z"] = 0, ["name"] = "unbreakable_map_barrier:barrier"}, {["x"] = 3, ["y"] = 77, ["param1"] = 15, ["z"] = 0, ["name"] = "unbreakable_map_barrier:barrier"}, {["x"] = 3, ["y"] = 78, ["param1"] = 15, ["z"] = 0, ["name"] = "unbreakable_map_barrier:barrier"}, {["x"] = 3, ["y"] = 79, ["param1"] = 15, ["z"] = 0, ["name"] = "unbreakable_map_barrier:barrier"}, {["x"] = 3, ["y"] = 80, ["param1"] = 15, ["z"] = 0, ["name"] = "unbreakable_map_barrier:barrier"}, {["x"] = 3, ["y"] = 80, ["param1"] = 15, ["z"] = 1, ["name"] = "unbreakable_map_barrier:barrier"}, {["x"] = 3, ["y"] = 80, ["param1"] = 15, ["z"] = 2, ["name"] = "unbreakable_map_barrier:barrier"}, {["x"] = 3, ["y"] = 80, ["param1"] = 15, ["z"] = 3, ["name"] = "unbreakable_map_barrier:barrier"}, {["x"] = 3, ["y"] = 80, ["param1"] = 15, ["z"] = 4, ["name"] = "unbreakable_map_barrier:barrier"}, {["x"] = 3, ["y"] = 80, ["param1"] = 15, ["z"] = 5, ["name"] = "unbreakable_map_barrier:barrier"}, {["x"] = 3, ["y"] = 80, ["param1"] = 15, ["z"] = 6, ["name"] = "unbreakable_map_barrier:barrier"}, {["x"] = 3, ["y"] = 80, ["param1"] = 15, ["z"] = 7, ["name"] = "unbreakable_map_barrier:barrier"}, {["x"] = 3, ["y"] = 80, ["param1"] = 15, ["z"] = 8, ["name"] = "unbreakable_map_barrier:barrier"}, {["x"] = 3, ["y"] = 80, ["param1"] = 15, ["z"] = 9, ["name"] = "unbreakable_map_barrier:barrier"}, {["x"] = 3, ["y"] = 80, ["param1"] = 15, ["z"] = 10, ["name"] = "unbreakable_map_barrier:barrier"}, {["x"] = 3, ["y"] = 80, ["param1"] = 15, ["z"] = 11, ["name"] = "unbreakable_map_barrier:barrier"}, {["x"] = 3, ["y"] = 80, ["param1"] = 15, ["z"] = 12, ["name"] = "unbreakable_map_barrier:barrier"}, {["x"] = 3, ["y"] = 80, ["param1"] = 15, ["z"] = 13, ["name"] = "unbreakable_map_barrier:barrier"}, {["x"] = 3, ["y"] = 80, ["param1"] = 15, ["z"] = 14, ["name"] = "unbreakable_map_barrier:barrier"}, {["x"] = 3, ["y"] = 80, ["param1"] = 15, ["z"] = 15, ["name"] = "unbreakable_map_barrier:barrier"}, {["x"] = 3, ["y"] = 80, ["param1"] = 15, ["z"] = 16, ["name"] = "unbreakable_map_barrier:barrier"}, {["x"] = 3, ["y"] = 80, ["param1"] = 15, ["z"] = 17, ["name"] = "unbreakable_map_barrier:barrier"}, {["x"] = 3, ["y"] = 80, ["param1"] = 15, ["z"] = 18, ["name"] = "unbreakable_map_barrier:barrier"}, {["x"] = 3, ["y"] = 80, ["param1"] = 15, ["z"] = 19, ["name"] = "unbreakable_map_barrier:barrier"}, {["x"] = 3, ["y"] = 80, ["param1"] = 15, ["z"] = 20, ["name"] = "unbreakable_map_barrier:barrier"}, {["x"] = 3, ["y"] = 80, ["param1"] = 15, ["z"] = 21, ["name"] = "unbreakable_map_barrier:barrier"}, {["x"] = 3, ["y"] = 80, ["param1"] = 15, ["z"] = 22, ["name"] = "unbreakable_map_barrier:barrier"}, {["x"] = 3, ["y"] = 80, ["param1"] = 15, ["z"] = 23, ["name"] = "unbreakable_map_barrier:barrier"}, {["x"] = 3, ["y"] = 80, ["param1"] = 15, ["z"] = 24, ["name"] = "unbreakable_map_barrier:barrier"}, {["x"] = 3, ["y"] = 80, ["param1"] = 15, ["z"] = 25, ["name"] = "unbreakable_map_barrier:barrier"}, {["x"] = 3, ["y"] = 80, ["param1"] = 15, ["z"] = 26, ["name"] = "unbreakable_map_barrier:barrier"}, {["x"] = 3, ["y"] = 80, ["param1"] = 15, ["z"] = 27, ["name"] = "unbreakable_map_barrier:barrier"}, {["x"] = 3, ["y"] = 80, ["param1"] = 15, ["z"] = 28, ["name"] = "unbreakable_map_barrier:barrier"}, {["x"] = 3, ["y"] = 80, ["param1"] = 15, ["z"] = 29, ["name"] = "unbreakable_map_barrier:barrier"}, {["x"] = 3, ["y"] = 80, ["param1"] = 15, ["z"] = 30, ["name"] = "unbreakable_map_barrier:barrier"}, {["x"] = 3, ["y"] = 80, ["param1"] = 15, ["z"] = 31, ["name"] = "unbreakable_map_barrier:barrier"}, {["x"] = 3, ["y"] = 80, ["param1"] = 15, ["z"] = 32, ["name"] = "unbreakable_map_barrier:barrier"}, {["x"] = 3, ["y"] = 80, ["param1"] = 15, ["z"] = 33, ["name"] = "unbreakable_map_barrier:barrier"}, {["x"] = 3, ["y"] = 80, ["param1"] = 15, ["z"] = 34, ["name"] = "unbreakable_map_barrier:barrier"}, {["x"] = 3, ["y"] = 80, ["param1"] = 15, ["z"] = 35, ["name"] = "unbreakable_map_barrier:barrier"}, {["x"] = 3, ["y"] = 80, ["param1"] = 15, ["z"] = 36, ["name"] = "unbreakable_map_barrier:barrier"}, {["x"] = 3, ["y"] = 80, ["param1"] = 15, ["z"] = 37, ["name"] = "unbreakable_map_barrier:barrier"}, {["x"] = 3, ["y"] = 80, ["param1"] = 15, ["z"] = 38, ["name"] = "unbreakable_map_barrier:barrier"}, {["x"] = 3, ["y"] = 80, ["param1"] = 15, ["z"] = 39, ["name"] = "unbreakable_map_barrier:barrier"}, {["x"] = 3, ["y"] = 80, ["param1"] = 15, ["z"] = 40, ["name"] = "unbreakable_map_barrier:barrier"}, {["x"] = 3, ["y"] = 80, ["param1"] = 15, ["z"] = 41, ["name"] = "unbreakable_map_barrier:barrier"}, {["x"] = 3, ["y"] = 80, ["param1"] = 15, ["z"] = 42, ["name"] = "unbreakable_map_barrier:barrier"}, {["x"] = 3, ["y"] = 80, ["param1"] = 15, ["z"] = 43, ["name"] = "unbreakable_map_barrier:barrier"}, {["x"] = 3, ["y"] = 80, ["param1"] = 15, ["z"] = 44, ["name"] = "unbreakable_map_barrier:barrier"}, {["x"] = 3, ["y"] = 80, ["param1"] = 15, ["z"] = 45, ["name"] = "unbreakable_map_barrier:barrier"}, {["x"] = 3, ["y"] = 80, ["param1"] = 15, ["z"] = 46, ["name"] = "unbreakable_map_barrier:barrier"}, {["x"] = 3, ["y"] = 80, ["param1"] = 15, ["z"] = 47, ["name"] = "unbreakable_map_barrier:barrier"}, {["x"] = 3, ["y"] = 80, ["param1"] = 15, ["z"] = 48, ["name"] = "unbreakable_map_barrier:barrier"}, {["x"] = 3, ["y"] = 80, ["param1"] = 15, ["z"] = 49, ["name"] = "unbreakable_map_barrier:barrier"}, {["x"] = 3, ["y"] = 80, ["param1"] = 15, ["z"] = 50, ["name"] = "unbreakable_map_barrier:barrier"}, {["x"] = 3, ["y"] = 80, ["param1"] = 15, ["z"] = 51, ["name"] = "unbreakable_map_barrier:barrier"}, {["x"] = 3, ["y"] = 80, ["param1"] = 15, ["z"] = 52, ["name"] = "unbreakable_map_barrier:barrier"}, {["x"] = 3, ["y"] = 80, ["param1"] = 15, ["z"] = 53, ["name"] = "unbreakable_map_barrier:barrier"}, {["x"] = 3, ["y"] = 80, ["param1"] = 15, ["z"] = 54, ["name"] = "unbreakable_map_barrier:barrier"}, {["x"] = 3, ["y"] = 80, ["param1"] = 15, ["z"] = 55, ["name"] = "unbreakable_map_barrier:barrier"}, {["x"] = 3, ["y"] = 80, ["param1"] = 15, ["z"] = 56, ["name"] = "unbreakable_map_barrier:barrier"}, {["x"] = 3, ["y"] = 80, ["param1"] = 15, ["z"] = 57, ["name"] = "unbreakable_map_barrier:barrier"}, {["x"] = 3, ["y"] = 80, ["param1"] = 15, ["z"] = 58, ["name"] = "unbreakable_map_barrier:barrier"}, {["x"] = 3, ["y"] = 80, ["param1"] = 15, ["z"] = 59, ["name"] = "unbreakable_map_barrier:barrier"}, {["x"] = 3, ["y"] = 80, ["param1"] = 15, ["z"] = 60, ["name"] = "unbreakable_map_barrier:barrier"}, {["x"] = 3, ["y"] = 80, ["param1"] = 15, ["z"] = 61, ["name"] = "unbreakable_map_barrier:barrier"}, {["x"] = 3, ["y"] = 80, ["param1"] = 15, ["z"] = 62, ["name"] = "unbreakable_map_barrier:barrier"}, {["x"] = 3, ["y"] = 80, ["param1"] = 15, ["z"] = 63, ["name"] = "unbreakable_map_barrier:barrier"}, {["x"] = 3, ["y"] = 80, ["param1"] = 15, ["z"] = 64, ["name"] = "unbreakable_map_barrier:barrier"}, {["x"] = 3, ["y"] = 80, ["param1"] = 15, ["z"] = 65, ["name"] = "unbreakable_map_barrier:barrier"}, {["x"] = 3, ["y"] = 80, ["param1"] = 15, ["z"] = 66, ["name"] = "unbreakable_map_barrier:barrier"}, {["x"] = 3, ["y"] = 80, ["param1"] = 15, ["z"] = 67, ["name"] = "unbreakable_map_barrier:barrier"}, {["x"] = 3, ["y"] = 80, ["param1"] = 15, ["z"] = 68, ["name"] = "unbreakable_map_barrier:barrier"}, {["x"] = 3, ["y"] = 80, ["param1"] = 15, ["z"] = 69, ["name"] = "unbreakable_map_barrier:barrier"}, {["x"] = 3, ["y"] = 80, ["param1"] = 15, ["z"] = 70, ["name"] = "unbreakable_map_barrier:barrier"}, {["x"] = 3, ["y"] = 80, ["param1"] = 15, ["z"] = 71, ["name"] = "unbreakable_map_barrier:barrier"}, {["x"] = 3, ["y"] = 80, ["param1"] = 15, ["z"] = 72, ["name"] = "unbreakable_map_barrier:barrier"}, {["x"] = 3, ["y"] = 80, ["param1"] = 15, ["z"] = 73, ["name"] = "unbreakable_map_barrier:barrier"}, {["x"] = 3, ["y"] = 80, ["param1"] = 15, ["z"] = 74, ["name"] = "unbreakable_map_barrier:barrier"}, {["x"] = 3, ["y"] = 80, ["param1"] = 15, ["z"] = 75, ["name"] = "unbreakable_map_barrier:barrier"}, {["x"] = 3, ["y"] = 80, ["param1"] = 15, ["z"] = 76, ["name"] = "unbreakable_map_barrier:barrier"}, {["x"] = 3, ["y"] = 80, ["param1"] = 15, ["z"] = 77, ["name"] = "unbreakable_map_barrier:barrier"}, {["x"] = 3, ["y"] = 80, ["param1"] = 15, ["z"] = 78, ["name"] = "unbreakable_map_barrier:barrier"}, {["x"] = 3, ["y"] = 80, ["param1"] = 15, ["z"] = 79, ["name"] = "unbreakable_map_barrier:barrier"}, {["x"] = 3, ["y"] = 80, ["param1"] = 15, ["z"] = 80, ["name"] = "unbreakable_map_barrier:barrier"}, {["x"] = 4, ["y"] = 0, ["param1"] = 15, ["z"] = 0, ["name"] = "unbreakable_map_barrier:barrier"}, {["x"] = 4, ["y"] = 1, ["param1"] = 15, ["z"] = 0, ["name"] = "unbreakable_map_barrier:barrier"}, {["x"] = 4, ["y"] = 2, ["param1"] = 15, ["z"] = 0, ["name"] = "unbreakable_map_barrier:barrier"}, {["x"] = 4, ["y"] = 3, ["param1"] = 15, ["z"] = 0, ["name"] = "unbreakable_map_barrier:barrier"}, {["x"] = 4, ["y"] = 4, ["param1"] = 15, ["z"] = 0, ["name"] = "unbreakable_map_barrier:barrier"}, {["x"] = 4, ["y"] = 5, ["param1"] = 15, ["z"] = 0, ["name"] = "unbreakable_map_barrier:barrier"}, {["x"] = 4, ["y"] = 6, ["param1"] = 15, ["z"] = 0, ["name"] = "unbreakable_map_barrier:barrier"}, {["x"] = 4, ["y"] = 7, ["param1"] = 15, ["z"] = 0, ["name"] = "unbreakable_map_barrier:barrier"}, {["x"] = 4, ["y"] = 8, ["param1"] = 15, ["z"] = 0, ["name"] = "unbreakable_map_barrier:barrier"}, {["x"] = 4, ["y"] = 9, ["param1"] = 15, ["z"] = 0, ["name"] = "unbreakable_map_barrier:barrier"}, {["x"] = 4, ["y"] = 10, ["param1"] = 15, ["z"] = 0, ["name"] = "unbreakable_map_barrier:barrier"}, {["x"] = 4, ["y"] = 11, ["param1"] = 15, ["z"] = 0, ["name"] = "unbreakable_map_barrier:barrier"}, {["x"] = 4, ["y"] = 12, ["param1"] = 15, ["z"] = 0, ["name"] = "unbreakable_map_barrier:barrier"}, {["x"] = 4, ["y"] = 13, ["param1"] = 15, ["z"] = 0, ["name"] = "unbreakable_map_barrier:barrier"}, {["x"] = 4, ["y"] = 14, ["param1"] = 15, ["z"] = 0, ["name"] = "unbreakable_map_barrier:barrier"}, {["x"] = 4, ["y"] = 15, ["param1"] = 15, ["z"] = 0, ["name"] = "unbreakable_map_barrier:barrier"}, {["x"] = 4, ["y"] = 16, ["param1"] = 15, ["z"] = 0, ["name"] = "unbreakable_map_barrier:barrier"}, {["x"] = 4, ["y"] = 17, ["param1"] = 15, ["z"] = 0, ["name"] = "unbreakable_map_barrier:barrier"}, {["x"] = 4, ["y"] = 18, ["param1"] = 15, ["z"] = 0, ["name"] = "unbreakable_map_barrier:barrier"}, {["x"] = 4, ["y"] = 19, ["param1"] = 15, ["z"] = 0, ["name"] = "unbreakable_map_barrier:barrier"}, {["x"] = 4, ["y"] = 20, ["param1"] = 15, ["z"] = 0, ["name"] = "unbreakable_map_barrier:barrier"}, {["x"] = 4, ["y"] = 21, ["param1"] = 15, ["z"] = 0, ["name"] = "unbreakable_map_barrier:barrier"}, {["x"] = 4, ["y"] = 22, ["param1"] = 15, ["z"] = 0, ["name"] = "unbreakable_map_barrier:barrier"}, {["x"] = 4, ["y"] = 23, ["param1"] = 15, ["z"] = 0, ["name"] = "unbreakable_map_barrier:barrier"}, {["x"] = 4, ["y"] = 24, ["param1"] = 15, ["z"] = 0, ["name"] = "unbreakable_map_barrier:barrier"}, {["x"] = 4, ["y"] = 25, ["param1"] = 15, ["z"] = 0, ["name"] = "unbreakable_map_barrier:barrier"}, {["x"] = 4, ["y"] = 26, ["param1"] = 15, ["z"] = 0, ["name"] = "unbreakable_map_barrier:barrier"}, {["x"] = 4, ["y"] = 27, ["param1"] = 15, ["z"] = 0, ["name"] = "unbreakable_map_barrier:barrier"}, {["x"] = 4, ["y"] = 28, ["param1"] = 15, ["z"] = 0, ["name"] = "unbreakable_map_barrier:barrier"}, {["x"] = 4, ["y"] = 29, ["param1"] = 15, ["z"] = 0, ["name"] = "unbreakable_map_barrier:barrier"}, {["x"] = 4, ["y"] = 30, ["param1"] = 15, ["z"] = 0, ["name"] = "unbreakable_map_barrier:barrier"}, {["x"] = 4, ["y"] = 31, ["param1"] = 15, ["z"] = 0, ["name"] = "unbreakable_map_barrier:barrier"}, {["x"] = 4, ["y"] = 32, ["param1"] = 15, ["z"] = 0, ["name"] = "unbreakable_map_barrier:barrier"}, {["x"] = 4, ["y"] = 33, ["param1"] = 15, ["z"] = 0, ["name"] = "unbreakable_map_barrier:barrier"}, {["x"] = 4, ["y"] = 34, ["param1"] = 15, ["z"] = 0, ["name"] = "unbreakable_map_barrier:barrier"}, {["x"] = 4, ["y"] = 35, ["param1"] = 15, ["z"] = 0, ["name"] = "unbreakable_map_barrier:barrier"}, {["x"] = 4, ["y"] = 36, ["param1"] = 15, ["z"] = 0, ["name"] = "unbreakable_map_barrier:barrier"}, {["x"] = 4, ["y"] = 37, ["param1"] = 15, ["z"] = 0, ["name"] = "unbreakable_map_barrier:barrier"}, {["x"] = 4, ["y"] = 38, ["param1"] = 15, ["z"] = 0, ["name"] = "unbreakable_map_barrier:barrier"}, {["x"] = 4, ["y"] = 39, ["param1"] = 15, ["z"] = 0, ["name"] = "unbreakable_map_barrier:barrier"}, {["x"] = 4, ["y"] = 40, ["param1"] = 15, ["z"] = 0, ["name"] = "unbreakable_map_barrier:barrier"}, {["x"] = 4, ["y"] = 41, ["param1"] = 15, ["z"] = 0, ["name"] = "unbreakable_map_barrier:barrier"}, {["x"] = 4, ["y"] = 42, ["param1"] = 15, ["z"] = 0, ["name"] = "unbreakable_map_barrier:barrier"}, {["x"] = 4, ["y"] = 43, ["param1"] = 15, ["z"] = 0, ["name"] = "unbreakable_map_barrier:barrier"}, {["x"] = 4, ["y"] = 44, ["param1"] = 15, ["z"] = 0, ["name"] = "unbreakable_map_barrier:barrier"}, {["x"] = 4, ["y"] = 45, ["param1"] = 15, ["z"] = 0, ["name"] = "unbreakable_map_barrier:barrier"}, {["x"] = 4, ["y"] = 46, ["param1"] = 15, ["z"] = 0, ["name"] = "unbreakable_map_barrier:barrier"}, {["x"] = 4, ["y"] = 47, ["param1"] = 15, ["z"] = 0, ["name"] = "unbreakable_map_barrier:barrier"}, {["x"] = 4, ["y"] = 48, ["param1"] = 15, ["z"] = 0, ["name"] = "unbreakable_map_barrier:barrier"}, {["x"] = 4, ["y"] = 49, ["param1"] = 15, ["z"] = 0, ["name"] = "unbreakable_map_barrier:barrier"}, {["x"] = 4, ["y"] = 50, ["param1"] = 15, ["z"] = 0, ["name"] = "unbreakable_map_barrier:barrier"}, {["x"] = 4, ["y"] = 51, ["param1"] = 15, ["z"] = 0, ["name"] = "unbreakable_map_barrier:barrier"}, {["x"] = 4, ["y"] = 52, ["param1"] = 15, ["z"] = 0, ["name"] = "unbreakable_map_barrier:barrier"}, {["x"] = 4, ["y"] = 53, ["param1"] = 15, ["z"] = 0, ["name"] = "unbreakable_map_barrier:barrier"}, {["x"] = 4, ["y"] = 54, ["param1"] = 15, ["z"] = 0, ["name"] = "unbreakable_map_barrier:barrier"}, {["x"] = 4, ["y"] = 55, ["param1"] = 15, ["z"] = 0, ["name"] = "unbreakable_map_barrier:barrier"}, {["x"] = 4, ["y"] = 56, ["param1"] = 15, ["z"] = 0, ["name"] = "unbreakable_map_barrier:barrier"}, {["x"] = 4, ["y"] = 57, ["param1"] = 15, ["z"] = 0, ["name"] = "unbreakable_map_barrier:barrier"}, {["x"] = 4, ["y"] = 58, ["param1"] = 15, ["z"] = 0, ["name"] = "unbreakable_map_barrier:barrier"}, {["x"] = 4, ["y"] = 59, ["param1"] = 15, ["z"] = 0, ["name"] = "unbreakable_map_barrier:barrier"}, {["x"] = 4, ["y"] = 60, ["param1"] = 15, ["z"] = 0, ["name"] = "unbreakable_map_barrier:barrier"}, {["x"] = 4, ["y"] = 61, ["param1"] = 15, ["z"] = 0, ["name"] = "unbreakable_map_barrier:barrier"}, {["x"] = 4, ["y"] = 62, ["param1"] = 15, ["z"] = 0, ["name"] = "unbreakable_map_barrier:barrier"}, {["x"] = 4, ["y"] = 63, ["param1"] = 15, ["z"] = 0, ["name"] = "unbreakable_map_barrier:barrier"}, {["x"] = 4, ["y"] = 64, ["param1"] = 15, ["z"] = 0, ["name"] = "unbreakable_map_barrier:barrier"}, {["x"] = 4, ["y"] = 65, ["param1"] = 15, ["z"] = 0, ["name"] = "unbreakable_map_barrier:barrier"}, {["x"] = 4, ["y"] = 66, ["param1"] = 15, ["z"] = 0, ["name"] = "unbreakable_map_barrier:barrier"}, {["x"] = 4, ["y"] = 67, ["param1"] = 15, ["z"] = 0, ["name"] = "unbreakable_map_barrier:barrier"}, {["x"] = 4, ["y"] = 68, ["param1"] = 15, ["z"] = 0, ["name"] = "unbreakable_map_barrier:barrier"}, {["x"] = 4, ["y"] = 69, ["param1"] = 15, ["z"] = 0, ["name"] = "unbreakable_map_barrier:barrier"}, {["x"] = 4, ["y"] = 70, ["param1"] = 15, ["z"] = 0, ["name"] = "unbreakable_map_barrier:barrier"}, {["x"] = 4, ["y"] = 71, ["param1"] = 15, ["z"] = 0, ["name"] = "unbreakable_map_barrier:barrier"}, {["x"] = 4, ["y"] = 72, ["param1"] = 15, ["z"] = 0, ["name"] = "unbreakable_map_barrier:barrier"}, {["x"] = 4, ["y"] = 73, ["param1"] = 15, ["z"] = 0, ["name"] = "unbreakable_map_barrier:barrier"}, {["x"] = 4, ["y"] = 74, ["param1"] = 15, ["z"] = 0, ["name"] = "unbreakable_map_barrier:barrier"}, {["x"] = 4, ["y"] = 75, ["param1"] = 15, ["z"] = 0, ["name"] = "unbreakable_map_barrier:barrier"}, {["x"] = 4, ["y"] = 76, ["param1"] = 15, ["z"] = 0, ["name"] = "unbreakable_map_barrier:barrier"}, {["x"] = 4, ["y"] = 77, ["param1"] = 15, ["z"] = 0, ["name"] = "unbreakable_map_barrier:barrier"}, {["x"] = 4, ["y"] = 78, ["param1"] = 15, ["z"] = 0, ["name"] = "unbreakable_map_barrier:barrier"}, {["x"] = 4, ["y"] = 79, ["param1"] = 15, ["z"] = 0, ["name"] = "unbreakable_map_barrier:barrier"}, {["x"] = 4, ["y"] = 80, ["param1"] = 15, ["z"] = 0, ["name"] = "unbreakable_map_barrier:barrier"}, {["x"] = 4, ["y"] = 80, ["param1"] = 15, ["z"] = 1, ["name"] = "unbreakable_map_barrier:barrier"}, {["x"] = 4, ["y"] = 80, ["param1"] = 15, ["z"] = 2, ["name"] = "unbreakable_map_barrier:barrier"}, {["x"] = 4, ["y"] = 80, ["param1"] = 15, ["z"] = 3, ["name"] = "unbreakable_map_barrier:barrier"}, {["x"] = 4, ["y"] = 80, ["param1"] = 15, ["z"] = 4, ["name"] = "unbreakable_map_barrier:barrier"}, {["x"] = 4, ["y"] = 80, ["param1"] = 15, ["z"] = 5, ["name"] = "unbreakable_map_barrier:barrier"}, {["x"] = 4, ["y"] = 80, ["param1"] = 15, ["z"] = 6, ["name"] = "unbreakable_map_barrier:barrier"}, {["x"] = 4, ["y"] = 80, ["param1"] = 15, ["z"] = 7, ["name"] = "unbreakable_map_barrier:barrier"}, {["x"] = 4, ["y"] = 80, ["param1"] = 15, ["z"] = 8, ["name"] = "unbreakable_map_barrier:barrier"}, {["x"] = 4, ["y"] = 80, ["param1"] = 15, ["z"] = 9, ["name"] = "unbreakable_map_barrier:barrier"}, {["x"] = 4, ["y"] = 80, ["param1"] = 15, ["z"] = 10, ["name"] = "unbreakable_map_barrier:barrier"}, {["x"] = 4, ["y"] = 80, ["param1"] = 15, ["z"] = 11, ["name"] = "unbreakable_map_barrier:barrier"}, {["x"] = 4, ["y"] = 80, ["param1"] = 15, ["z"] = 12, ["name"] = "unbreakable_map_barrier:barrier"}, {["x"] = 4, ["y"] = 80, ["param1"] = 15, ["z"] = 13, ["name"] = "unbreakable_map_barrier:barrier"}, {["x"] = 4, ["y"] = 80, ["param1"] = 15, ["z"] = 14, ["name"] = "unbreakable_map_barrier:barrier"}, {["x"] = 4, ["y"] = 80, ["param1"] = 15, ["z"] = 15, ["name"] = "unbreakable_map_barrier:barrier"}, {["x"] = 4, ["y"] = 80, ["param1"] = 15, ["z"] = 16, ["name"] = "unbreakable_map_barrier:barrier"}, {["x"] = 4, ["y"] = 80, ["param1"] = 15, ["z"] = 17, ["name"] = "unbreakable_map_barrier:barrier"}, {["x"] = 4, ["y"] = 80, ["param1"] = 15, ["z"] = 18, ["name"] = "unbreakable_map_barrier:barrier"}, {["x"] = 4, ["y"] = 80, ["param1"] = 15, ["z"] = 19, ["name"] = "unbreakable_map_barrier:barrier"}, {["x"] = 4, ["y"] = 80, ["param1"] = 15, ["z"] = 20, ["name"] = "unbreakable_map_barrier:barrier"}, {["x"] = 4, ["y"] = 80, ["param1"] = 15, ["z"] = 21, ["name"] = "unbreakable_map_barrier:barrier"}, {["x"] = 4, ["y"] = 80, ["param1"] = 15, ["z"] = 22, ["name"] = "unbreakable_map_barrier:barrier"}, {["x"] = 4, ["y"] = 80, ["param1"] = 15, ["z"] = 23, ["name"] = "unbreakable_map_barrier:barrier"}, {["x"] = 4, ["y"] = 80, ["param1"] = 15, ["z"] = 24, ["name"] = "unbreakable_map_barrier:barrier"}, {["x"] = 4, ["y"] = 80, ["param1"] = 15, ["z"] = 25, ["name"] = "unbreakable_map_barrier:barrier"}, {["x"] = 4, ["y"] = 80, ["param1"] = 15, ["z"] = 26, ["name"] = "unbreakable_map_barrier:barrier"}, {["x"] = 4, ["y"] = 80, ["param1"] = 15, ["z"] = 27, ["name"] = "unbreakable_map_barrier:barrier"}, {["x"] = 4, ["y"] = 80, ["param1"] = 15, ["z"] = 28, ["name"] = "unbreakable_map_barrier:barrier"}, {["x"] = 4, ["y"] = 80, ["param1"] = 15, ["z"] = 29, ["name"] = "unbreakable_map_barrier:barrier"}, {["x"] = 4, ["y"] = 80, ["param1"] = 15, ["z"] = 30, ["name"] = "unbreakable_map_barrier:barrier"}, {["x"] = 4, ["y"] = 80, ["param1"] = 15, ["z"] = 31, ["name"] = "unbreakable_map_barrier:barrier"}, {["x"] = 4, ["y"] = 80, ["param1"] = 15, ["z"] = 32, ["name"] = "unbreakable_map_barrier:barrier"}, {["x"] = 4, ["y"] = 80, ["param1"] = 15, ["z"] = 33, ["name"] = "unbreakable_map_barrier:barrier"}, {["x"] = 4, ["y"] = 80, ["param1"] = 15, ["z"] = 34, ["name"] = "unbreakable_map_barrier:barrier"}, {["x"] = 4, ["y"] = 80, ["param1"] = 15, ["z"] = 35, ["name"] = "unbreakable_map_barrier:barrier"}, {["x"] = 4, ["y"] = 80, ["param1"] = 15, ["z"] = 36, ["name"] = "unbreakable_map_barrier:barrier"}, {["x"] = 4, ["y"] = 80, ["param1"] = 15, ["z"] = 37, ["name"] = "unbreakable_map_barrier:barrier"}, {["x"] = 4, ["y"] = 80, ["param1"] = 15, ["z"] = 38, ["name"] = "unbreakable_map_barrier:barrier"}, {["x"] = 4, ["y"] = 80, ["param1"] = 15, ["z"] = 39, ["name"] = "unbreakable_map_barrier:barrier"}, {["x"] = 4, ["y"] = 80, ["param1"] = 15, ["z"] = 40, ["name"] = "unbreakable_map_barrier:barrier"}, {["x"] = 4, ["y"] = 80, ["param1"] = 15, ["z"] = 41, ["name"] = "unbreakable_map_barrier:barrier"}, {["x"] = 4, ["y"] = 80, ["param1"] = 15, ["z"] = 42, ["name"] = "unbreakable_map_barrier:barrier"}, {["x"] = 4, ["y"] = 80, ["param1"] = 15, ["z"] = 43, ["name"] = "unbreakable_map_barrier:barrier"}, {["x"] = 4, ["y"] = 80, ["param1"] = 15, ["z"] = 44, ["name"] = "unbreakable_map_barrier:barrier"}, {["x"] = 4, ["y"] = 80, ["param1"] = 15, ["z"] = 45, ["name"] = "unbreakable_map_barrier:barrier"}, {["x"] = 4, ["y"] = 80, ["param1"] = 15, ["z"] = 46, ["name"] = "unbreakable_map_barrier:barrier"}, {["x"] = 4, ["y"] = 80, ["param1"] = 15, ["z"] = 47, ["name"] = "unbreakable_map_barrier:barrier"}, {["x"] = 4, ["y"] = 80, ["param1"] = 15, ["z"] = 48, ["name"] = "unbreakable_map_barrier:barrier"}, {["x"] = 4, ["y"] = 80, ["param1"] = 15, ["z"] = 49, ["name"] = "unbreakable_map_barrier:barrier"}, {["x"] = 4, ["y"] = 80, ["param1"] = 15, ["z"] = 50, ["name"] = "unbreakable_map_barrier:barrier"}, {["x"] = 4, ["y"] = 80, ["param1"] = 15, ["z"] = 51, ["name"] = "unbreakable_map_barrier:barrier"}, {["x"] = 4, ["y"] = 80, ["param1"] = 15, ["z"] = 52, ["name"] = "unbreakable_map_barrier:barrier"}, {["x"] = 4, ["y"] = 80, ["param1"] = 15, ["z"] = 53, ["name"] = "unbreakable_map_barrier:barrier"}, {["x"] = 4, ["y"] = 80, ["param1"] = 15, ["z"] = 54, ["name"] = "unbreakable_map_barrier:barrier"}, {["x"] = 4, ["y"] = 80, ["param1"] = 15, ["z"] = 55, ["name"] = "unbreakable_map_barrier:barrier"}, {["x"] = 4, ["y"] = 80, ["param1"] = 15, ["z"] = 56, ["name"] = "unbreakable_map_barrier:barrier"}, {["x"] = 4, ["y"] = 80, ["param1"] = 15, ["z"] = 57, ["name"] = "unbreakable_map_barrier:barrier"}, {["x"] = 4, ["y"] = 80, ["param1"] = 15, ["z"] = 58, ["name"] = "unbreakable_map_barrier:barrier"}, {["x"] = 4, ["y"] = 80, ["param1"] = 15, ["z"] = 59, ["name"] = "unbreakable_map_barrier:barrier"}, {["x"] = 4, ["y"] = 80, ["param1"] = 15, ["z"] = 60, ["name"] = "unbreakable_map_barrier:barrier"}, {["x"] = 4, ["y"] = 80, ["param1"] = 15, ["z"] = 61, ["name"] = "unbreakable_map_barrier:barrier"}, {["x"] = 4, ["y"] = 80, ["param1"] = 15, ["z"] = 62, ["name"] = "unbreakable_map_barrier:barrier"}, {["x"] = 4, ["y"] = 80, ["param1"] = 15, ["z"] = 63, ["name"] = "unbreakable_map_barrier:barrier"}, {["x"] = 4, ["y"] = 80, ["param1"] = 15, ["z"] = 64, ["name"] = "unbreakable_map_barrier:barrier"}, {["x"] = 4, ["y"] = 80, ["param1"] = 15, ["z"] = 65, ["name"] = "unbreakable_map_barrier:barrier"}, {["x"] = 4, ["y"] = 80, ["param1"] = 15, ["z"] = 66, ["name"] = "unbreakable_map_barrier:barrier"}, {["x"] = 4, ["y"] = 80, ["param1"] = 15, ["z"] = 67, ["name"] = "unbreakable_map_barrier:barrier"}, {["x"] = 4, ["y"] = 80, ["param1"] = 15, ["z"] = 68, ["name"] = "unbreakable_map_barrier:barrier"}, {["x"] = 4, ["y"] = 80, ["param1"] = 15, ["z"] = 69, ["name"] = "unbreakable_map_barrier:barrier"}, {["x"] = 4, ["y"] = 80, ["param1"] = 15, ["z"] = 70, ["name"] = "unbreakable_map_barrier:barrier"}, {["x"] = 4, ["y"] = 80, ["param1"] = 15, ["z"] = 71, ["name"] = "unbreakable_map_barrier:barrier"}, {["x"] = 4, ["y"] = 80, ["param1"] = 15, ["z"] = 72, ["name"] = "unbreakable_map_barrier:barrier"}, {["x"] = 4, ["y"] = 80, ["param1"] = 15, ["z"] = 73, ["name"] = "unbreakable_map_barrier:barrier"}, {["x"] = 4, ["y"] = 80, ["param1"] = 15, ["z"] = 74, ["name"] = "unbreakable_map_barrier:barrier"}, {["x"] = 4, ["y"] = 80, ["param1"] = 15, ["z"] = 75, ["name"] = "unbreakable_map_barrier:barrier"}, {["x"] = 4, ["y"] = 80, ["param1"] = 15, ["z"] = 76, ["name"] = "unbreakable_map_barrier:barrier"}, {["x"] = 4, ["y"] = 80, ["param1"] = 15, ["z"] = 77, ["name"] = "unbreakable_map_barrier:barrier"}, {["x"] = 4, ["y"] = 80, ["param1"] = 15, ["z"] = 78, ["name"] = "unbreakable_map_barrier:barrier"}, {["x"] = 4, ["y"] = 80, ["param1"] = 15, ["z"] = 79, ["name"] = "unbreakable_map_barrier:barrier"}, {["x"] = 4, ["y"] = 80, ["param1"] = 15, ["z"] = 80, ["name"] = "unbreakable_map_barrier:barrier"}, {["x"] = 5, ["y"] = 0, ["param1"] = 15, ["z"] = 0, ["name"] = "unbreakable_map_barrier:barrier"}, {["x"] = 5, ["y"] = 1, ["param1"] = 15, ["z"] = 0, ["name"] = "unbreakable_map_barrier:barrier"}, {["x"] = 5, ["y"] = 2, ["param1"] = 15, ["z"] = 0, ["name"] = "unbreakable_map_barrier:barrier"}, {["x"] = 5, ["y"] = 3, ["param1"] = 15, ["z"] = 0, ["name"] = "unbreakable_map_barrier:barrier"}, {["x"] = 5, ["y"] = 4, ["param1"] = 15, ["z"] = 0, ["name"] = "unbreakable_map_barrier:barrier"}, {["x"] = 5, ["y"] = 5, ["param1"] = 15, ["z"] = 0, ["name"] = "unbreakable_map_barrier:barrier"}, {["x"] = 5, ["y"] = 6, ["param1"] = 15, ["z"] = 0, ["name"] = "unbreakable_map_barrier:barrier"}, {["x"] = 5, ["y"] = 7, ["param1"] = 15, ["z"] = 0, ["name"] = "unbreakable_map_barrier:barrier"}, {["x"] = 5, ["y"] = 8, ["param1"] = 15, ["z"] = 0, ["name"] = "unbreakable_map_barrier:barrier"}, {["x"] = 5, ["y"] = 9, ["param1"] = 15, ["z"] = 0, ["name"] = "unbreakable_map_barrier:barrier"}, {["x"] = 5, ["y"] = 10, ["param1"] = 15, ["z"] = 0, ["name"] = "unbreakable_map_barrier:barrier"}, {["x"] = 5, ["y"] = 11, ["param1"] = 15, ["z"] = 0, ["name"] = "unbreakable_map_barrier:barrier"}, {["x"] = 5, ["y"] = 12, ["param1"] = 15, ["z"] = 0, ["name"] = "unbreakable_map_barrier:barrier"}, {["x"] = 5, ["y"] = 13, ["param1"] = 15, ["z"] = 0, ["name"] = "unbreakable_map_barrier:barrier"}, {["x"] = 5, ["y"] = 14, ["param1"] = 15, ["z"] = 0, ["name"] = "unbreakable_map_barrier:barrier"}, {["x"] = 5, ["y"] = 15, ["param1"] = 15, ["z"] = 0, ["name"] = "unbreakable_map_barrier:barrier"}, {["x"] = 5, ["y"] = 16, ["param1"] = 15, ["z"] = 0, ["name"] = "unbreakable_map_barrier:barrier"}, {["x"] = 5, ["y"] = 17, ["param1"] = 15, ["z"] = 0, ["name"] = "unbreakable_map_barrier:barrier"}, {["x"] = 5, ["y"] = 18, ["param1"] = 15, ["z"] = 0, ["name"] = "unbreakable_map_barrier:barrier"}, {["x"] = 5, ["y"] = 19, ["param1"] = 15, ["z"] = 0, ["name"] = "unbreakable_map_barrier:barrier"}, {["x"] = 5, ["y"] = 20, ["param1"] = 15, ["z"] = 0, ["name"] = "unbreakable_map_barrier:barrier"}, {["x"] = 5, ["y"] = 21, ["param1"] = 15, ["z"] = 0, ["name"] = "unbreakable_map_barrier:barrier"}, {["x"] = 5, ["y"] = 22, ["param1"] = 15, ["z"] = 0, ["name"] = "unbreakable_map_barrier:barrier"}, {["x"] = 5, ["y"] = 23, ["param1"] = 15, ["z"] = 0, ["name"] = "unbreakable_map_barrier:barrier"}, {["x"] = 5, ["y"] = 24, ["param1"] = 15, ["z"] = 0, ["name"] = "unbreakable_map_barrier:barrier"}, {["x"] = 5, ["y"] = 25, ["param1"] = 15, ["z"] = 0, ["name"] = "unbreakable_map_barrier:barrier"}, {["x"] = 5, ["y"] = 26, ["param1"] = 15, ["z"] = 0, ["name"] = "unbreakable_map_barrier:barrier"}, {["x"] = 5, ["y"] = 27, ["param1"] = 15, ["z"] = 0, ["name"] = "unbreakable_map_barrier:barrier"}, {["x"] = 5, ["y"] = 28, ["param1"] = 15, ["z"] = 0, ["name"] = "unbreakable_map_barrier:barrier"}, {["x"] = 5, ["y"] = 29, ["param1"] = 15, ["z"] = 0, ["name"] = "unbreakable_map_barrier:barrier"}, {["x"] = 5, ["y"] = 30, ["param1"] = 15, ["z"] = 0, ["name"] = "unbreakable_map_barrier:barrier"}, {["x"] = 5, ["y"] = 31, ["param1"] = 15, ["z"] = 0, ["name"] = "unbreakable_map_barrier:barrier"}, {["x"] = 5, ["y"] = 32, ["param1"] = 15, ["z"] = 0, ["name"] = "unbreakable_map_barrier:barrier"}, {["x"] = 5, ["y"] = 33, ["param1"] = 15, ["z"] = 0, ["name"] = "unbreakable_map_barrier:barrier"}, {["x"] = 5, ["y"] = 34, ["param1"] = 15, ["z"] = 0, ["name"] = "unbreakable_map_barrier:barrier"}, {["x"] = 5, ["y"] = 35, ["param1"] = 15, ["z"] = 0, ["name"] = "unbreakable_map_barrier:barrier"}, {["x"] = 5, ["y"] = 36, ["param1"] = 15, ["z"] = 0, ["name"] = "unbreakable_map_barrier:barrier"}, {["x"] = 5, ["y"] = 37, ["param1"] = 15, ["z"] = 0, ["name"] = "unbreakable_map_barrier:barrier"}, {["x"] = 5, ["y"] = 38, ["param1"] = 15, ["z"] = 0, ["name"] = "unbreakable_map_barrier:barrier"}, {["x"] = 5, ["y"] = 39, ["param1"] = 15, ["z"] = 0, ["name"] = "unbreakable_map_barrier:barrier"}, {["x"] = 5, ["y"] = 40, ["param1"] = 15, ["z"] = 0, ["name"] = "unbreakable_map_barrier:barrier"}, {["x"] = 5, ["y"] = 41, ["param1"] = 15, ["z"] = 0, ["name"] = "unbreakable_map_barrier:barrier"}, {["x"] = 5, ["y"] = 42, ["param1"] = 15, ["z"] = 0, ["name"] = "unbreakable_map_barrier:barrier"}, {["x"] = 5, ["y"] = 43, ["param1"] = 15, ["z"] = 0, ["name"] = "unbreakable_map_barrier:barrier"}, {["x"] = 5, ["y"] = 44, ["param1"] = 15, ["z"] = 0, ["name"] = "unbreakable_map_barrier:barrier"}, {["x"] = 5, ["y"] = 45, ["param1"] = 15, ["z"] = 0, ["name"] = "unbreakable_map_barrier:barrier"}, {["x"] = 5, ["y"] = 46, ["param1"] = 15, ["z"] = 0, ["name"] = "unbreakable_map_barrier:barrier"}, {["x"] = 5, ["y"] = 47, ["param1"] = 15, ["z"] = 0, ["name"] = "unbreakable_map_barrier:barrier"}, {["x"] = 5, ["y"] = 48, ["param1"] = 15, ["z"] = 0, ["name"] = "unbreakable_map_barrier:barrier"}, {["x"] = 5, ["y"] = 49, ["param1"] = 15, ["z"] = 0, ["name"] = "unbreakable_map_barrier:barrier"}, {["x"] = 5, ["y"] = 50, ["param1"] = 15, ["z"] = 0, ["name"] = "unbreakable_map_barrier:barrier"}, {["x"] = 5, ["y"] = 51, ["param1"] = 15, ["z"] = 0, ["name"] = "unbreakable_map_barrier:barrier"}, {["x"] = 5, ["y"] = 52, ["param1"] = 15, ["z"] = 0, ["name"] = "unbreakable_map_barrier:barrier"}, {["x"] = 5, ["y"] = 53, ["param1"] = 15, ["z"] = 0, ["name"] = "unbreakable_map_barrier:barrier"}, {["x"] = 5, ["y"] = 54, ["param1"] = 15, ["z"] = 0, ["name"] = "unbreakable_map_barrier:barrier"}, {["x"] = 5, ["y"] = 55, ["param1"] = 15, ["z"] = 0, ["name"] = "unbreakable_map_barrier:barrier"}, {["x"] = 5, ["y"] = 56, ["param1"] = 15, ["z"] = 0, ["name"] = "unbreakable_map_barrier:barrier"}, {["x"] = 5, ["y"] = 57, ["param1"] = 15, ["z"] = 0, ["name"] = "unbreakable_map_barrier:barrier"}, {["x"] = 5, ["y"] = 58, ["param1"] = 15, ["z"] = 0, ["name"] = "unbreakable_map_barrier:barrier"}, {["x"] = 5, ["y"] = 59, ["param1"] = 15, ["z"] = 0, ["name"] = "unbreakable_map_barrier:barrier"}, {["x"] = 5, ["y"] = 60, ["param1"] = 15, ["z"] = 0, ["name"] = "unbreakable_map_barrier:barrier"}, {["x"] = 5, ["y"] = 61, ["param1"] = 15, ["z"] = 0, ["name"] = "unbreakable_map_barrier:barrier"}, {["x"] = 5, ["y"] = 62, ["param1"] = 15, ["z"] = 0, ["name"] = "unbreakable_map_barrier:barrier"}, {["x"] = 5, ["y"] = 63, ["param1"] = 15, ["z"] = 0, ["name"] = "unbreakable_map_barrier:barrier"}, {["x"] = 5, ["y"] = 64, ["param1"] = 15, ["z"] = 0, ["name"] = "unbreakable_map_barrier:barrier"}, {["x"] = 5, ["y"] = 65, ["param1"] = 15, ["z"] = 0, ["name"] = "unbreakable_map_barrier:barrier"}, {["x"] = 5, ["y"] = 66, ["param1"] = 15, ["z"] = 0, ["name"] = "unbreakable_map_barrier:barrier"}, {["x"] = 5, ["y"] = 67, ["param1"] = 15, ["z"] = 0, ["name"] = "unbreakable_map_barrier:barrier"}, {["x"] = 5, ["y"] = 68, ["param1"] = 15, ["z"] = 0, ["name"] = "unbreakable_map_barrier:barrier"}, {["x"] = 5, ["y"] = 69, ["param1"] = 15, ["z"] = 0, ["name"] = "unbreakable_map_barrier:barrier"}, {["x"] = 5, ["y"] = 70, ["param1"] = 15, ["z"] = 0, ["name"] = "unbreakable_map_barrier:barrier"}, {["x"] = 5, ["y"] = 71, ["param1"] = 15, ["z"] = 0, ["name"] = "unbreakable_map_barrier:barrier"}, {["x"] = 5, ["y"] = 72, ["param1"] = 15, ["z"] = 0, ["name"] = "unbreakable_map_barrier:barrier"}, {["x"] = 5, ["y"] = 73, ["param1"] = 15, ["z"] = 0, ["name"] = "unbreakable_map_barrier:barrier"}, {["x"] = 5, ["y"] = 74, ["param1"] = 15, ["z"] = 0, ["name"] = "unbreakable_map_barrier:barrier"}, {["x"] = 5, ["y"] = 75, ["param1"] = 15, ["z"] = 0, ["name"] = "unbreakable_map_barrier:barrier"}, {["x"] = 5, ["y"] = 76, ["param1"] = 15, ["z"] = 0, ["name"] = "unbreakable_map_barrier:barrier"}, {["x"] = 5, ["y"] = 77, ["param1"] = 15, ["z"] = 0, ["name"] = "unbreakable_map_barrier:barrier"}, {["x"] = 5, ["y"] = 78, ["param1"] = 15, ["z"] = 0, ["name"] = "unbreakable_map_barrier:barrier"}, {["x"] = 5, ["y"] = 79, ["param1"] = 15, ["z"] = 0, ["name"] = "unbreakable_map_barrier:barrier"}, {["x"] = 5, ["y"] = 80, ["param1"] = 15, ["z"] = 0, ["name"] = "unbreakable_map_barrier:barrier"}, {["x"] = 5, ["y"] = 80, ["param1"] = 15, ["z"] = 1, ["name"] = "unbreakable_map_barrier:barrier"}, {["x"] = 5, ["y"] = 80, ["param1"] = 15, ["z"] = 2, ["name"] = "unbreakable_map_barrier:barrier"}, {["x"] = 5, ["y"] = 80, ["param1"] = 15, ["z"] = 3, ["name"] = "unbreakable_map_barrier:barrier"}, {["x"] = 5, ["y"] = 80, ["param1"] = 15, ["z"] = 4, ["name"] = "unbreakable_map_barrier:barrier"}, {["x"] = 5, ["y"] = 80, ["param1"] = 15, ["z"] = 5, ["name"] = "unbreakable_map_barrier:barrier"}, {["x"] = 5, ["y"] = 80, ["param1"] = 15, ["z"] = 6, ["name"] = "unbreakable_map_barrier:barrier"}, {["x"] = 5, ["y"] = 80, ["param1"] = 15, ["z"] = 7, ["name"] = "unbreakable_map_barrier:barrier"}, {["x"] = 5, ["y"] = 80, ["param1"] = 15, ["z"] = 8, ["name"] = "unbreakable_map_barrier:barrier"}, {["x"] = 5, ["y"] = 80, ["param1"] = 15, ["z"] = 9, ["name"] = "unbreakable_map_barrier:barrier"}, {["x"] = 5, ["y"] = 80, ["param1"] = 15, ["z"] = 10, ["name"] = "unbreakable_map_barrier:barrier"}, {["x"] = 5, ["y"] = 80, ["param1"] = 15, ["z"] = 11, ["name"] = "unbreakable_map_barrier:barrier"}, {["x"] = 5, ["y"] = 80, ["param1"] = 15, ["z"] = 12, ["name"] = "unbreakable_map_barrier:barrier"}, {["x"] = 5, ["y"] = 80, ["param1"] = 15, ["z"] = 13, ["name"] = "unbreakable_map_barrier:barrier"}, {["x"] = 5, ["y"] = 80, ["param1"] = 15, ["z"] = 14, ["name"] = "unbreakable_map_barrier:barrier"}, {["x"] = 5, ["y"] = 80, ["param1"] = 15, ["z"] = 15, ["name"] = "unbreakable_map_barrier:barrier"}, {["x"] = 5, ["y"] = 80, ["param1"] = 15, ["z"] = 16, ["name"] = "unbreakable_map_barrier:barrier"}, {["x"] = 5, ["y"] = 80, ["param1"] = 15, ["z"] = 17, ["name"] = "unbreakable_map_barrier:barrier"}, {["x"] = 5, ["y"] = 80, ["param1"] = 15, ["z"] = 18, ["name"] = "unbreakable_map_barrier:barrier"}, {["x"] = 5, ["y"] = 80, ["param1"] = 15, ["z"] = 19, ["name"] = "unbreakable_map_barrier:barrier"}, {["x"] = 5, ["y"] = 80, ["param1"] = 15, ["z"] = 20, ["name"] = "unbreakable_map_barrier:barrier"}, {["x"] = 5, ["y"] = 80, ["param1"] = 15, ["z"] = 21, ["name"] = "unbreakable_map_barrier:barrier"}, {["x"] = 5, ["y"] = 80, ["param1"] = 15, ["z"] = 22, ["name"] = "unbreakable_map_barrier:barrier"}, {["x"] = 5, ["y"] = 80, ["param1"] = 15, ["z"] = 23, ["name"] = "unbreakable_map_barrier:barrier"}, {["x"] = 5, ["y"] = 80, ["param1"] = 15, ["z"] = 24, ["name"] = "unbreakable_map_barrier:barrier"}, {["x"] = 5, ["y"] = 80, ["param1"] = 15, ["z"] = 25, ["name"] = "unbreakable_map_barrier:barrier"}, {["x"] = 5, ["y"] = 80, ["param1"] = 15, ["z"] = 26, ["name"] = "unbreakable_map_barrier:barrier"}, {["x"] = 5, ["y"] = 80, ["param1"] = 15, ["z"] = 27, ["name"] = "unbreakable_map_barrier:barrier"}, {["x"] = 5, ["y"] = 80, ["param1"] = 15, ["z"] = 28, ["name"] = "unbreakable_map_barrier:barrier"}, {["x"] = 5, ["y"] = 80, ["param1"] = 15, ["z"] = 29, ["name"] = "unbreakable_map_barrier:barrier"}, {["x"] = 5, ["y"] = 80, ["param1"] = 15, ["z"] = 30, ["name"] = "unbreakable_map_barrier:barrier"}, {["x"] = 5, ["y"] = 80, ["param1"] = 15, ["z"] = 31, ["name"] = "unbreakable_map_barrier:barrier"}, {["x"] = 5, ["y"] = 80, ["param1"] = 15, ["z"] = 32, ["name"] = "unbreakable_map_barrier:barrier"}, {["x"] = 5, ["y"] = 80, ["param1"] = 15, ["z"] = 33, ["name"] = "unbreakable_map_barrier:barrier"}, {["x"] = 5, ["y"] = 80, ["param1"] = 15, ["z"] = 34, ["name"] = "unbreakable_map_barrier:barrier"}, {["x"] = 5, ["y"] = 80, ["param1"] = 15, ["z"] = 35, ["name"] = "unbreakable_map_barrier:barrier"}, {["x"] = 5, ["y"] = 80, ["param1"] = 15, ["z"] = 36, ["name"] = "unbreakable_map_barrier:barrier"}, {["x"] = 5, ["y"] = 80, ["param1"] = 15, ["z"] = 37, ["name"] = "unbreakable_map_barrier:barrier"}, {["x"] = 5, ["y"] = 80, ["param1"] = 15, ["z"] = 38, ["name"] = "unbreakable_map_barrier:barrier"}, {["x"] = 5, ["y"] = 80, ["param1"] = 15, ["z"] = 39, ["name"] = "unbreakable_map_barrier:barrier"}, {["x"] = 5, ["y"] = 80, ["param1"] = 15, ["z"] = 40, ["name"] = "unbreakable_map_barrier:barrier"}, {["x"] = 5, ["y"] = 80, ["param1"] = 15, ["z"] = 41, ["name"] = "unbreakable_map_barrier:barrier"}, {["x"] = 5, ["y"] = 80, ["param1"] = 15, ["z"] = 42, ["name"] = "unbreakable_map_barrier:barrier"}, {["x"] = 5, ["y"] = 80, ["param1"] = 15, ["z"] = 43, ["name"] = "unbreakable_map_barrier:barrier"}, {["x"] = 5, ["y"] = 80, ["param1"] = 15, ["z"] = 44, ["name"] = "unbreakable_map_barrier:barrier"}, {["x"] = 5, ["y"] = 80, ["param1"] = 15, ["z"] = 45, ["name"] = "unbreakable_map_barrier:barrier"}, {["x"] = 5, ["y"] = 80, ["param1"] = 15, ["z"] = 46, ["name"] = "unbreakable_map_barrier:barrier"}, {["x"] = 5, ["y"] = 80, ["param1"] = 15, ["z"] = 47, ["name"] = "unbreakable_map_barrier:barrier"}, {["x"] = 5, ["y"] = 80, ["param1"] = 15, ["z"] = 48, ["name"] = "unbreakable_map_barrier:barrier"}, {["x"] = 5, ["y"] = 80, ["param1"] = 15, ["z"] = 49, ["name"] = "unbreakable_map_barrier:barrier"}, {["x"] = 5, ["y"] = 80, ["param1"] = 15, ["z"] = 50, ["name"] = "unbreakable_map_barrier:barrier"}, {["x"] = 5, ["y"] = 80, ["param1"] = 15, ["z"] = 51, ["name"] = "unbreakable_map_barrier:barrier"}, {["x"] = 5, ["y"] = 80, ["param1"] = 15, ["z"] = 52, ["name"] = "unbreakable_map_barrier:barrier"}, {["x"] = 5, ["y"] = 80, ["param1"] = 15, ["z"] = 53, ["name"] = "unbreakable_map_barrier:barrier"}, {["x"] = 5, ["y"] = 80, ["param1"] = 15, ["z"] = 54, ["name"] = "unbreakable_map_barrier:barrier"}, {["x"] = 5, ["y"] = 80, ["param1"] = 15, ["z"] = 55, ["name"] = "unbreakable_map_barrier:barrier"}, {["x"] = 5, ["y"] = 80, ["param1"] = 15, ["z"] = 56, ["name"] = "unbreakable_map_barrier:barrier"}, {["x"] = 5, ["y"] = 80, ["param1"] = 15, ["z"] = 57, ["name"] = "unbreakable_map_barrier:barrier"}, {["x"] = 5, ["y"] = 80, ["param1"] = 15, ["z"] = 58, ["name"] = "unbreakable_map_barrier:barrier"}, {["x"] = 5, ["y"] = 80, ["param1"] = 15, ["z"] = 59, ["name"] = "unbreakable_map_barrier:barrier"}, {["x"] = 5, ["y"] = 80, ["param1"] = 15, ["z"] = 60, ["name"] = "unbreakable_map_barrier:barrier"}, {["x"] = 5, ["y"] = 80, ["param1"] = 15, ["z"] = 61, ["name"] = "unbreakable_map_barrier:barrier"}, {["x"] = 5, ["y"] = 80, ["param1"] = 15, ["z"] = 62, ["name"] = "unbreakable_map_barrier:barrier"}, {["x"] = 5, ["y"] = 80, ["param1"] = 15, ["z"] = 63, ["name"] = "unbreakable_map_barrier:barrier"}, {["x"] = 5, ["y"] = 80, ["param1"] = 15, ["z"] = 64, ["name"] = "unbreakable_map_barrier:barrier"}, {["x"] = 5, ["y"] = 80, ["param1"] = 15, ["z"] = 65, ["name"] = "unbreakable_map_barrier:barrier"}, {["x"] = 5, ["y"] = 80, ["param1"] = 15, ["z"] = 66, ["name"] = "unbreakable_map_barrier:barrier"}, {["x"] = 5, ["y"] = 80, ["param1"] = 15, ["z"] = 67, ["name"] = "unbreakable_map_barrier:barrier"}, {["x"] = 5, ["y"] = 80, ["param1"] = 15, ["z"] = 68, ["name"] = "unbreakable_map_barrier:barrier"}, {["x"] = 5, ["y"] = 80, ["param1"] = 15, ["z"] = 69, ["name"] = "unbreakable_map_barrier:barrier"}, {["x"] = 5, ["y"] = 80, ["param1"] = 15, ["z"] = 70, ["name"] = "unbreakable_map_barrier:barrier"}, {["x"] = 5, ["y"] = 80, ["param1"] = 15, ["z"] = 71, ["name"] = "unbreakable_map_barrier:barrier"}, {["x"] = 5, ["y"] = 80, ["param1"] = 15, ["z"] = 72, ["name"] = "unbreakable_map_barrier:barrier"}, {["x"] = 5, ["y"] = 80, ["param1"] = 15, ["z"] = 73, ["name"] = "unbreakable_map_barrier:barrier"}, {["x"] = 5, ["y"] = 80, ["param1"] = 15, ["z"] = 74, ["name"] = "unbreakable_map_barrier:barrier"}, {["x"] = 5, ["y"] = 80, ["param1"] = 15, ["z"] = 75, ["name"] = "unbreakable_map_barrier:barrier"}, {["x"] = 5, ["y"] = 80, ["param1"] = 15, ["z"] = 76, ["name"] = "unbreakable_map_barrier:barrier"}, {["x"] = 5, ["y"] = 80, ["param1"] = 15, ["z"] = 77, ["name"] = "unbreakable_map_barrier:barrier"}, {["x"] = 5, ["y"] = 80, ["param1"] = 15, ["z"] = 78, ["name"] = "unbreakable_map_barrier:barrier"}, {["x"] = 5, ["y"] = 80, ["param1"] = 15, ["z"] = 79, ["name"] = "unbreakable_map_barrier:barrier"}, {["x"] = 5, ["y"] = 80, ["param1"] = 15, ["z"] = 80, ["name"] = "unbreakable_map_barrier:barrier"}, {["x"] = 6, ["y"] = 0, ["param1"] = 15, ["z"] = 0, ["name"] = "unbreakable_map_barrier:barrier"}, {["x"] = 6, ["y"] = 1, ["param1"] = 15, ["z"] = 0, ["name"] = "unbreakable_map_barrier:barrier"}, {["x"] = 6, ["y"] = 2, ["param1"] = 15, ["z"] = 0, ["name"] = "unbreakable_map_barrier:barrier"}, {["x"] = 6, ["y"] = 3, ["param1"] = 15, ["z"] = 0, ["name"] = "unbreakable_map_barrier:barrier"}, {["x"] = 6, ["y"] = 4, ["param1"] = 15, ["z"] = 0, ["name"] = "unbreakable_map_barrier:barrier"}, {["x"] = 6, ["y"] = 5, ["param1"] = 15, ["z"] = 0, ["name"] = "unbreakable_map_barrier:barrier"}, {["x"] = 6, ["y"] = 6, ["param1"] = 15, ["z"] = 0, ["name"] = "unbreakable_map_barrier:barrier"}, {["x"] = 6, ["y"] = 7, ["param1"] = 15, ["z"] = 0, ["name"] = "unbreakable_map_barrier:barrier"}, {["x"] = 6, ["y"] = 8, ["param1"] = 15, ["z"] = 0, ["name"] = "unbreakable_map_barrier:barrier"}, {["x"] = 6, ["y"] = 9, ["param1"] = 15, ["z"] = 0, ["name"] = "unbreakable_map_barrier:barrier"}, {["x"] = 6, ["y"] = 10, ["param1"] = 15, ["z"] = 0, ["name"] = "unbreakable_map_barrier:barrier"}, {["x"] = 6, ["y"] = 11, ["param1"] = 15, ["z"] = 0, ["name"] = "unbreakable_map_barrier:barrier"}, {["x"] = 6, ["y"] = 12, ["param1"] = 15, ["z"] = 0, ["name"] = "unbreakable_map_barrier:barrier"}, {["x"] = 6, ["y"] = 13, ["param1"] = 15, ["z"] = 0, ["name"] = "unbreakable_map_barrier:barrier"}, {["x"] = 6, ["y"] = 14, ["param1"] = 15, ["z"] = 0, ["name"] = "unbreakable_map_barrier:barrier"}, {["x"] = 6, ["y"] = 15, ["param1"] = 15, ["z"] = 0, ["name"] = "unbreakable_map_barrier:barrier"}, {["x"] = 6, ["y"] = 16, ["param1"] = 15, ["z"] = 0, ["name"] = "unbreakable_map_barrier:barrier"}, {["x"] = 6, ["y"] = 17, ["param1"] = 15, ["z"] = 0, ["name"] = "unbreakable_map_barrier:barrier"}, {["x"] = 6, ["y"] = 18, ["param1"] = 15, ["z"] = 0, ["name"] = "unbreakable_map_barrier:barrier"}, {["x"] = 6, ["y"] = 19, ["param1"] = 15, ["z"] = 0, ["name"] = "unbreakable_map_barrier:barrier"}, {["x"] = 6, ["y"] = 20, ["param1"] = 15, ["z"] = 0, ["name"] = "unbreakable_map_barrier:barrier"}, {["x"] = 6, ["y"] = 21, ["param1"] = 15, ["z"] = 0, ["name"] = "unbreakable_map_barrier:barrier"}, {["x"] = 6, ["y"] = 22, ["param1"] = 15, ["z"] = 0, ["name"] = "unbreakable_map_barrier:barrier"}, {["x"] = 6, ["y"] = 23, ["param1"] = 15, ["z"] = 0, ["name"] = "unbreakable_map_barrier:barrier"}, {["x"] = 6, ["y"] = 24, ["param1"] = 15, ["z"] = 0, ["name"] = "unbreakable_map_barrier:barrier"}, {["x"] = 6, ["y"] = 25, ["param1"] = 15, ["z"] = 0, ["name"] = "unbreakable_map_barrier:barrier"}, {["x"] = 6, ["y"] = 26, ["param1"] = 15, ["z"] = 0, ["name"] = "unbreakable_map_barrier:barrier"}, {["x"] = 6, ["y"] = 27, ["param1"] = 15, ["z"] = 0, ["name"] = "unbreakable_map_barrier:barrier"}, {["x"] = 6, ["y"] = 28, ["param1"] = 15, ["z"] = 0, ["name"] = "unbreakable_map_barrier:barrier"}, {["x"] = 6, ["y"] = 29, ["param1"] = 15, ["z"] = 0, ["name"] = "unbreakable_map_barrier:barrier"}, {["x"] = 6, ["y"] = 30, ["param1"] = 15, ["z"] = 0, ["name"] = "unbreakable_map_barrier:barrier"}, {["x"] = 6, ["y"] = 31, ["param1"] = 15, ["z"] = 0, ["name"] = "unbreakable_map_barrier:barrier"}, {["x"] = 6, ["y"] = 32, ["param1"] = 15, ["z"] = 0, ["name"] = "unbreakable_map_barrier:barrier"}, {["x"] = 6, ["y"] = 33, ["param1"] = 15, ["z"] = 0, ["name"] = "unbreakable_map_barrier:barrier"}, {["x"] = 6, ["y"] = 34, ["param1"] = 15, ["z"] = 0, ["name"] = "unbreakable_map_barrier:barrier"}, {["x"] = 6, ["y"] = 35, ["param1"] = 15, ["z"] = 0, ["name"] = "unbreakable_map_barrier:barrier"}, {["x"] = 6, ["y"] = 36, ["param1"] = 15, ["z"] = 0, ["name"] = "unbreakable_map_barrier:barrier"}, {["x"] = 6, ["y"] = 37, ["param1"] = 15, ["z"] = 0, ["name"] = "unbreakable_map_barrier:barrier"}, {["x"] = 6, ["y"] = 38, ["param1"] = 15, ["z"] = 0, ["name"] = "unbreakable_map_barrier:barrier"}, {["x"] = 6, ["y"] = 39, ["param1"] = 15, ["z"] = 0, ["name"] = "unbreakable_map_barrier:barrier"},